Workbook

Sheet Stabilization - Items
A1: Area | B1: Feature | C1: Functionality | D1: Module | E1: Phase | F1: Status | G1: Remarks | H1: Requested Date | I1: ETA | J1: Priority | K1: Start Date | L1: End Date | M1: Resource | N1: Jira ID
A2: Stablization | B2: Business Critical | C2: PROD Bug: Dashboard vs RO page - When login user applied the same filters in Dashboard and the same in RO then counts are NO matching - Example Milind in email | D2: iWork | E2: Milestone 6 | F2: DEV - WIP | H2: 46240 | I2: 46240 | J2: High | M2: Karan
A3: Stablization | B3: Orphan Records | C3: Orphan - Companies - Identifying the records, Validate & Delete | D3: iWork | E3: Milestone 6 | F3: Yet to start | H3: 46240 | I3: 46245 | J3: High | K3: 46241 | L3: 46245 | M3: Gopal / Rama
A4: Stablization | B4: Orphan Records | C4: Orphan - Oppotunities - Identifying the records, Validate & Delete | D4: iWork | E4: Milestone 6 | F4: Yet to start | H4: 46240 | I4: 46245 | J4: High | K4: 46241 | L4: 46245 | M4: Gopal / Rama
A5: Stablization | B5: Orphan Records | C5: Orphan - Policies - Identifying the records, Validate & Delete | D5: iWork | E5: Milestone 6 | F5: Yet to start | H5: 46240 | I5: 46245 | J5: High | K5: 46241 | L5: 46245 | M5: Gopal / Rama
A6: Stablization | B6: Business Critical | C6: Migration Data load should be always complete only after manual Performances Job Execution - Continous acitivity | D6: iWork | E6: Milestone 6 | F6: DEV - WIP | G6: Anytime, manual load or adjustments are done, performance job needs to be executed for entire period | H6: 46235 | I6: 46237 | J6: High | K6: 46237 | L6: 46237 | M6: Rama
A7: Stablization | B7: Business Critical | C7: Dashboard: Having individual component loaders on the landing page for each component and web-socket framework to avoid long-loading blank page issue. | D7: iWork | E7: Milestone 6 | F7: Dev - Done | H7: 46235 | I7: 46238 | J7: High | K7: 46237 | L7: 46238 | M7: Manjusha
A8: Stablization | B8: Business Critical | C8: BizDone & Dashboard: Filters Persistance | D8: iWork | E8: Milestone 6 | F8: Delivered | H8: 46235 | I8: 46238 | J8: High | K8: 46238 | L8: 46238 | M8: Sunil
A9: Stablization | B9: Business Critical | C9: BizDone - Download - User select the desired sheet | D9: iWork - CR | E9: Milestone 6 | F9: Delivered | H9: 46235 | I9: 46238 | J9: High | K9: 46238 | L9: 46238 | M9: Karan
A10: Stablization | B10: Business Critical | C10: BizDone - Download - Indian template along with Localization fields | D10: iWork | E10: Milestone 6 | F10: UAT - WIP | H10: 46235 | I10: 46238 | J10: High | K10: 46238 | L10: 46238 | M10: Leela
A11: Stablization | B11: Business Critical | C11: BizDone - Download - Performance (Offload Excel Generation) - API, Queue, Store in S3 & Download | D11: iWork | E11: Milestone 6 | F11: Delivered | H11: 46235 | I11: 46239 | J11: High | K11: 46237 | L11: 46239 | M11: Karan
A12: Stablization | B12: Business Critical | C12: BizDone - Applied filters in the Downloaded file in Sheet-1 | D12: iWork | E12: Milestone 6 | F12: Delivered | H12: 46235 | I12: 46239 | J12: High | K12: 46238 | L12: 46239 | M12: Sunil
A13: Stablization | B13: Business Critical | C13: IBP - Risk Watch - Report Issues - Enrolment Drive - Validate, enhance, and document | D13: IBP | E13: Milestone 6 | F13: Dev - Done | H13: 46235 | I13: 46239 | J13: High | K13: 46238 | L13: 46239 | M13: Ravikiran | O13: PR is ready, Waiting for nithin to verify
A14: Stablization | B14: Business Critical | C14: The owner selection process remains highly user-unfriendly, with a very small expand ('>') button, incomplete visibility of names, and insufficient hierarchy indentation. | D14: iWork | E14: Milestone 6 | F14: DEV - WIP | H14: 46221 | I14: 46240 | J14: High | K14: 46238 | L14: 46240 | M14: Raju
A15: Stablization | B15: Business Critical | C15: BizDone - Old & Enhance Screens - For now both will be live(Metrics) | D15: iWork | E15: Milestone 6 | F15: Dev - WIP | H15: 46235 | I15: 46240 | J15: High | K15: 46239 | L15: 46240 | M15: Karan | N15: Leela
A16: Stablization | B16: Business Critical | C16: Dashboard & BizDone: Centralised code or utility to fetch the KPIs data for re-usability | D16: iWork | E16: Milestone 6 | F16: Dev - WIP | H16: 46235 | I16: 46240 | J16: High | K16: 46239 | L16: 46240 | M16: Sunil
A17: Stablization | B17: Business Critical | C17: Dashboard: Implementation of the dynamic fetching of widgets data without depending on performance output cron job | D17: iWork | E17: Milestone 6 | F17: UAT - WIP | H17: 46235 | I17: 46237 | J17: High | K17: 46240 | L17: 46240 | M17: Jagadeesh
A18: Stablization | B18: Business Critical | C18: BizDone & Dashboard - Consider Fee & Rewards as "Brokerage" | D18: iWork | E18: Milestone 6 | F18: Yet to start | H18: 46235 | I18: 46241 | J18: High | K18: 46240 | L18: 46241 | M18: Sunil
A19: Stablization | B19: Business Critical | C19: BizDone - Screen & Download data is not consistent | D19: iWork | E19: Milestone 6 | F19: Dev - WIP | H19: 46221 | I19: 46241 | J19: High | K19: 46240 | L19: 46241 | M19: Karan | N19: leela
A20: Stablization | B20: Business Critical | C20: IBP - Risk Watch - Company & Policy Levels are not matching (CD, Endorsement, Claims) | D20: IBP | E20: Milestone 6 | F20: Dev - Done | H20: 46235 | I20: 46241 | J20: High | K20: 46240 | L20: 46241 | M20: Ravikiran
A21: Stablization | B21: Business Critical | C21: BizDone - Performance - Query Fine Tuning | D21: iWork | E21: Milestone 6 | F21: Dev - WIP | H21: 46235 | I21: 46244 | J21: High | K21: 46244 | L21: 46244 | M21: Karan
A22: Stablization | B22: Business Critical | C22: BizDone & other filters - Multi-select for Vertical & Branch | D22: iWork | E22: Milestone 6 | F22: Dev - WIP | H22: 46221 | I22: 46245 | J22: High | K22: 46244 | L22: 46245 | M22: Sunil
A23: Stablization | B23: Business Critical | C23: Dashboard - Performance - Query Fine Tuning | D23: iWork | E23: Milestone 6 | F23: Yet to start | H23: 46235 | I23: 46246 | J23: High | K23: 46246 | L23: 46246 | M23: Sunil
A24: Stablization | B24: Business Critical | C24: BizDone - Download - Reduce the file size (Ex. Excel binary or others) | D24: iWork - CR | E24: Milestone 6 | F24: Yet to start | H24: 46235 | I24: 46246 | J24: High | K24: 46246 | L24: 46246 | M24: Karan
A25: Stablization | B25: Business Critical | C25: IBP - Email Notification - Company specific email templates for all types (Welcome, Confirmation, Reminder, Raise Ticket, & Others) | D25: iWork/IBP | E25: Milestone 6 | F25: Yet to start | H25: 46235 | J25: Medium
A26: Stablization | B26: Business Critical | C26: Computed value & Reported values * Computed values - It’s the real-time values base on Policy inception/endorsement * Reported values - It’s validated by the mgmt. and share this number to update in the column. * Reported value MUST be used for the Dashboard & BizDone, which was declared by the company to public. * In the admin a feature to update the Reported values from the computed values * Legacy data - Premiums, Brokerage, CD Balance | D26: iWork - CR | E26: Milestone 6 | F26: Yet to start | H26: 46198 | I26: 46241 | J26: Medium
A27: Stablization | B27: Maintenance | C27: Convert Policy from Active to Generated | D27: iWork | E27: Milestone 6 | F27: Yet to start | H27: 46235 | J27: Medium
A28: Stablization | B28: Maintenance | C28: Delete - Policy Configuration | D28: iWork | E28: Milestone 6 | F28: Yet to start | H28: 46235 | J28: Medium
A29: Stablization | B29: Maintenance | C29: iWork - Reports - View Dump for each download for comparision | D29: iWork | E29: Milestone 6 | F29: Yet to start | H29: 46132 | J29: Medium | M29: Gopal
A30: Stablization | B30: Maintenance | C30: PROD: Health Check of the Application, Alert notification & Triage the situation | D30: iWork | E30: Milestone 6 | F30: Yet to start | H30: 46235 | J30: Low
A31: Stablization | B31: Maintenance | C31: Delete - Inception/Endorsement Data | D31: iWork | E31: Milestone 6 | F31: Yet to start | H31: 46235 | J31: Low
A32: Stablization | B32: Maintenance | C32: Employee Mgmt - Create, Update, Delete - Validate and document | D32: iWork | E32: Milestone 6 | F32: Yet to start | H32: 46235 | J32: Low
A33: Stablization | B33: Maintenance | C33: Hierarchy Mgmt - View & Update - Report & Visual Chart | D33: iWork | E33: Milestone 6 | F33: Yet to start | H33: 46235 | J33: Low
A34: Stablization | B34: Maintenance | C34: In any of the screen, we have to provide an info icon where it will help the users how critical fields in that screen are derieved or got populated | D34: iWork | E34: Milestone 6 | F34: Yet to start | H34: 46220 | J34: Low
A35: Stablization | B35: Maintenance | C35: IBP - Go-Live: Check-list document & SOP | D35: iWork/IBP | E35: Milestone 6 | F35: Yet to start | H35: 46132 | J35: Low | M35: Nithin
A36: Stablization | B36: Maintenance | C36: iWork - Reports - Use BizDone framework | D36: iWork | E36: Milestone 6 | F36: Yet to start | H36: 46235 | J36: Low
A37: Stablization | B37: Operational | C37: Job - Dashboard - Review, Enhance and document | D37: iWork | E37: Milestone 6 | F37: Delivered | G37: Flag based development / remove job post approval | H37: 46235 | I37: 46240 | J37: High | K37: 46238 | L37: 46239 | M37: Sunil
A38: Stablization | B38: Operational | C38: Personal Lines Data Integration (DSR and iWork) | D38: iWork | E38: Milestone 6 | F38: Dev - Done | H38: 46228 | I38: 46239 | J38: High | K38: 46238 | L38: 46239 | M38: Junaid
A39: Stablization | B39: Operational | C39: Demo Env. - Stop all the Job; Make sure emails & SMS are working as expected | D39: iWork | E39: Milestone 6 | F39: Yet to start | H39: 46235 | I39: 46240 | J39: High | K39: 46239 | L39: 46240 | M39: Tharun
A40: Stablization | B40: Operational | C40: PROD & Other env.: Database Vaccum - Schedule a periodic acitvity in all the env. | D40: iWork | E40: Milestone 6 | F40: Yet to start | H40: 46235 | I40: 46241 | J40: High | K40: 46240 | L40: 46241 | M40: Abhilash
...

Sheet Stabilization - Summary
A1: STABILIZATION — STATUS OVERVIEW
A4: Stabilization Area | Break-up by Feature · As of 07-Aug-2026
A6: OVERALL COMPLETION | H6: REMAINING WORK
A7: =ROUND(COUNTIFS('Stabilization - Items'!$A:$A,"Stablization",Helper!$E:$E,"Delivered")/(COUNTIFS('Stabilization - Items'!$A:$A,"Stablization",Helper!$E:$E,"Delivered")+COUNTIFS('Stabilization - Items'!$A:$A,"Stablization",Helper!$E:$E,"Pending")),3) -> 0.15 | D7: =COUNTIFS('Stabilization - Items'!$A:$A,"Stablization",Helper!$E:$E,"Delivered")&" of "&(COUNTIFS('Stabilization - Items'!$A:$A,"Stablization",Helper!$E:$E,"Delivered")+COUNTIFS('Stabilization - Items'!$A:$A,"Stablization",Helper!$E:$E,"Pending"))&" Stabilization items delivered" -> 9 of 60 Stabilization items delivered | H7: =COUNTIFS('Stabilization - Items'!$A:$A,"Stablization",Helper!$E:$E,"Pending") -> 51 | J7: Stabilization items still to deliver, broken up by Feature below
A11: STATUS BREAKDOWN (Stabilization items)
A12: =COUNTIFS('Stabilization - Items'!$A:$A,"Stablization",Helper!$D:$D,"Delivered") -> 5 | D12: =COUNTIFS('Stabilization - Items'!$A:$A,"Stablization",Helper!$D:$D,"Dev Complete") -> 4 | G12: =COUNTIFS('Stabilization - Items'!$A:$A,"Stablization",Helper!$D:$D,"In Development") -> 8 | J12: =COUNTIFS('Stabilization - Items'!$A:$A,"Stablization",Helper!$D:$D,"In QA") -> 0
A13: Delivered | D13: Dev Complete | G13: In Development | J13: In QA
A14: =COUNTIFS('Stabilization - Items'!$A:$A,"Stablization",Helper!$D:$D,"Pre-PROD / UAT") -> 2 | D14: =COUNTIFS('Stabilization - Items'!$A:$A,"Stablization",Helper!$D:$D,"Not Started") -> 41 | G14: =COUNTIFS('Stabilization - Items'!$A:$A,"Stablization",Helper!$D:$D,"Partial Delivery") -> 0 | J14: =COUNTIFS('Stabilization - Items'!$A:$A,"Stablization",Helper!$D:$D,"N/A") -> 0
A15: Pre-PROD / UAT | D15: Not Started | G15: Partial Delivery | J15: N/A
A17: BREAKDOWN BY FEATURE
A18: Feature | B18: Total | C18: Delivered | D18: Pending | E18: N/A | F18: % Complete | G18: Progress
A19: Business Critical | B19: =COUNTIFS('Stabilization - Items'!$A:$A,"Stablization",'Stabilization - Items'!$B:$B,"Business Critical") -> 22 | C19: =COUNTIFS('Stabilization - Items'!$A:$A,"Stablization",'Stabilization - Items'!$B:$B,"Business Critical",Helper!$E:$E,"Delivered") -> 7 | D19: =COUNTIFS('Stabilization - Items'!$A:$A,"Stablization",'Stabilization - Items'!$B:$B,"Business Critical",Helper!$E:$E,"Pending") -> 15 | E19: =COUNTIFS('Stabilization - Items'!$A:$A,"Stablization",'Stabilization - Items'!$B:$B,"Business Critical",Helper!$E:$E,"N/A") -> 0 | F19: =IFERROR(C19/(C19+D19),0) -> 0.31818182 | G19: =F19 -> 0.31818182
A20: Maintenance | B20: =COUNTIFS('Stabilization - Items'!$A:$A,"Stablization",'Stabilization - Items'!$B:$B,"Maintenance") -> 10 | C20: =COUNTIFS('Stabilization - Items'!$A:$A,"Stablization",'Stabilization - Items'!$B:$B,"Maintenance",Helper!$E:$E,"Delivered") -> 0 | D20: =COUNTIFS('Stabilization - Items'!$A:$A,"Stablization",'Stabilization - Items'!$B:$B,"Maintenance",Helper!$E:$E,"Pending") -> 10 | E20: =COUNTIFS('Stabilization - Items'!$A:$A,"Stablization",'Stabilization - Items'!$B:$B,"Maintenance",Helper!$E:$E,"N/A") -> 0 | F20: =IFERROR(C20/(C20+D20),0) -> 0 | G20: =F20 -> 0
A21: Operational | B21: =COUNTIFS('Stabilization - Items'!$A:$A,"Stablization",'Stabilization - Items'!$B:$B,"Operational") -> 25 | C21: =COUNTIFS('Stabilization - Items'!$A:$A,"Stablization",'Stabilization - Items'!$B:$B,"Operational",Helper!$E:$E,"Delivered") -> 2 | D21: =COUNTIFS('Stabilization - Items'!$A:$A,"Stablization",'Stabilization - Items'!$B:$B,"Operational",Helper!$E:$E,"Pending") -> 23 | E21: =COUNTIFS('Stabilization - Items'!$A:$A,"Stablization",'Stabilization - Items'!$B:$B,"Operational",Helper!$E:$E,"N/A") -> 0 | F21: =IFERROR(C21/(C21+D21),0) -> 0.08 | G21: =F21 -> 0.08
A22: Orphan Records | B22: =COUNTIFS('Stabilization - Items'!$A:$A,"Stablization",'Stabilization - Items'!$B:$B,"Orphan Records") -> 3 | C22: =COUNTIFS('Stabilization - Items'!$A:$A,"Stablization",'Stabilization - Items'!$B:$B,"Orphan Records",Helper!$E:$E,"Delivered") -> 0 | D22: =COUNTIFS('Stabilization - Items'!$A:$A,"Stablization",'Stabilization - Items'!$B:$B,"Orphan Records",Helper!$E:$E,"Pending") -> 3 | E22: =COUNTIFS('Stabilization - Items'!$A:$A,"Stablization",'Stabilization - Items'!$B:$B,"Orphan Records",Helper!$E:$E,"N/A") -> 0 | F22: =IFERROR(C22/(C22+D22),0) -> 0 | G22: =F22 -> 0
A23: TOTAL | B23: =COUNTIFS('Stabilization - Items'!$A:$A,"Stablization") -> 60 | C23: =COUNTIFS('Stabilization - Items'!$A:$A,"Stablization",Helper!$E:$E,"Delivered") -> 9 | D23: =COUNTIFS('Stabilization - Items'!$A:$A,"Stablization",Helper!$E:$E,"Pending") -> 51 | E23: =COUNTIFS('Stabilization - Items'!$A:$A,"Stablization",Helper!$E:$E,"N/A") -> 0 | F23: =IFERROR(C23/(C23+D23),0) -> 0.15 | G23: =F23 -> 0.15
A25: Scope: rows where Area = 'Stablization' in the source sheet. % Complete = Delivered ÷ (Delivered + Pending). N/A items excluded. Counts update live from the source sheet; re-run the script only if a new Feature value is added under this Area (to add its row here).
A27: PRIORITY vs STATUS
A28: Priority | B28: Delivered | C28: Dev Complete | D28: In Development | E28: In QA | F28: Pre-PROD / UAT | G28: Not Started | H28: Partial Delivery | I28: N/A | J28: Unknown | K28: TOTAL
A29: High | B29: =COUNTIFS('Stabilization - Items'!$A:$A,"Stablization",'Stabilization - Items'!$J:$J,"High",Helper!$D:$D,"Delivered") -> 5 | C29: =COUNTIFS('Stabilization - Items'!$A:$A,"Stablization",'Stabilization - Items'!$J:$J,"High",Helper!$D:$D,"Dev Complete") -> 4 | D29: =COUNTIFS('Stabilization - Items'!$A:$A,"Stablization",'Stabilization - Items'!$J:$J,"High",Helper!$D:$D,"In Development") -> 8 | E29: =COUNTIFS('Stabilization - Items'!$A:$A,"Stablization",'Stabilization - Items'!$J:$J,"High",Helper!$D:$D,"In QA") -> 0 | F29: =COUNTIFS('Stabilization - Items'!$A:$A,"Stablization",'Stabilization - Items'!$J:$J,"High",Helper!$D:$D,"Pre-PROD / UAT") -> 2 | G29: =COUNTIFS('Stabilization - Items'!$A:$A,"Stablization",'Stabilization - Items'!$J:$J,"High",Helper!$D:$D,"Not Started") -> 17 | H29: =COUNTIFS('Stabilization - Items'!$A:$A,"Stablization",'Stabilization - Items'!$J:$J,"High",Helper!$D:$D,"Partial Delivery") -> 0 | I29: =COUNTIFS('Stabilization - Items'!$A:$A,"Stablization",'Stabilization - Items'!$J:$J,"High",Helper!$D:$D,"N/A") -> 0 | J29: =COUNTIFS('Stabilization - Items'!$A:$A,"Stablization",'Stabilization - Items'!$J:$J,"High",Helper!$D:$D,"Unknown") -> 0 | K29: =SUM(B29:J29) -> 36
A30: Medium | B30: =COUNTIFS('Stabilization - Items'!$A:$A,"Stablization",'Stabilization - Items'!$J:$J,"Medium",Helper!$D:$D,"Delivered") -> 0 | C30: =COUNTIFS('Stabilization - Items'!$A:$A,"Stablization",'Stabilization - Items'!$J:$J,"Medium",Helper!$D:$D,"Dev Complete") -> 0 | D30: =COUNTIFS('Stabilization - Items'!$A:$A,"Stablization",'Stabilization - Items'!$J:$J,"Medium",Helper!$D:$D,"In Development") -> 0 | E30: =COUNTIFS('Stabilization - Items'!$A:$A,"Stablization",'Stabilization - Items'!$J:$J,"Medium",Helper!$D:$D,"In QA") -> 0 | F30: =COUNTIFS('Stabilization - Items'!$A:$A,"Stablization",'Stabilization - Items'!$J:$J,"Medium",Helper!$D:$D,"Pre-PROD / UAT") -> 0 | G30: =COUNTIFS('Stabilization - Items'!$A:$A,"Stablization",'Stabilization - Items'!$J:$J,"Medium",Helper!$D:$D,"Not Started") -> 6 | H30: =COUNTIFS('Stabilization - Items'!$A:$A,"Stablization",'Stabilization - Items'!$J:$J,"Medium",Helper!$D:$D,"Partial Delivery") -> 0 | I30: =COUNTIFS('Stabilization - Items'!$A:$A,"Stablization",'Stabilization - Items'!$J:$J,"Medium",Helper!$D:$D,"N/A") -> 0 | J30: =COUNTIFS('Stabilization - Items'!$A:$A,"Stablization",'Stabilization - Items'!$J:$J,"Medium",Helper!$D:$D,"Unknown") -> 0 | K30: =SUM(B30:J30) -> 6
A31: Low | B31: =COUNTIFS('Stabilization - Items'!$A:$A,"Stablization",'Stabilization - Items'!$J:$J,"Low",Helper!$D:$D,"Delivered") -> 0 | C31: =COUNTIFS('Stabilization - Items'!$A:$A,"Stablization",'Stabilization - Items'!$J:$J,"Low",Helper!$D:$D,"Dev Complete") -> 0 | D31: =COUNTIFS('Stabilization - Items'!$A:$A,"Stablization",'Stabilization - Items'!$J:$J,"Low",Helper!$D:$D,"In Development") -> 0 | E31: =COUNTIFS('Stabilization - Items'!$A:$A,"Stablization",'Stabilization - Items'!$J:$J,"Low",Helper!$D:$D,"In QA") -> 0 | F31: =COUNTIFS('Stabilization - Items'!$A:$A,"Stablization",'Stabilization - Items'!$J:$J,"Low",Helper!$D:$D,"Pre-PROD / UAT") -> 0 | G31: =COUNTIFS('Stabilization - Items'!$A:$A,"Stablization",'Stabilization - Items'!$J:$J,"Low",Helper!$D:$D,"Not Started") -> 18 | H31: =COUNTIFS('Stabilization - Items'!$A:$A,"Stablization",'Stabilization - Items'!$J:$J,"Low",Helper!$D:$D,"Partial Delivery") -> 0 | I31: =COUNTIFS('Stabilization - Items'!$A:$A,"Stablization",'Stabilization - Items'!$J:$J,"Low",Helper!$D:$D,"N/A") -> 0 | J31: =COUNTIFS('Stabilization - Items'!$A:$A,"Stablization",'Stabilization - Items'!$J:$J,"Low",Helper!$D:$D,"Unknown") -> 0 | K31: =SUM(B31:J31) -> 18
A32: TOTAL | B32: =SUM(B29:B31) -> 5 | C32: =SUM(C29:C31) -> 4 | D32: =SUM(D29:D31) -> 8 | E32: =SUM(E29:E31) -> 0 | F32: =SUM(F29:F31) -> 2 | G32: =SUM(G29:G31) -> 41 | H32: =SUM(H29:H31) -> 0 | I32: =SUM(I29:I31) -> 0 | ... K32: =SUM(K29:K31) -> 60
A34: Scope: rows where Area = 'Stablization', grouped by the 'Priority' column. Counts update live from the source sheet; re-run the script only if a new Priority value is used (to add its row here).
A36: DAILY PROGRESS — toward the 14-Aug-2026 deadline
A37: Date | B37: Total | C37: Planned Delivered | D37: Delivered | E37: Planned Pending | F37: Pending | G37: Delivered Today | H37: % Complete | I37: Ahead/Behind Plan | J37: Days Left | K37: Req. Pace/day
A38: 46241 | B38: 35 | C38: 21 | D38: 9 | E38: 14 | F38: 26 | G38: — | H38: 0.2571 | I38: -12 | J38: 7 | K38: 3.7
A39: 46242 | B39: — | C39: 21 | D39: — | E39: 14 | F39: — | G39: — | H39: — | I39: — | J39: 6 | K39: —
A40: 46243 | B40: — | C40: 21 | D40: — | E40: 14 | F40: — | G40: — | H40: — | I40: — | J40: 5 | K40: —
A41: 46244 | B41: — | C41: 22 | D41: — | E41: 13 | F41: — | G41: — | H41: — | I41: — | J41: 4 | K41: —
A42: 46245 | B42: — | C42: 29 | D42: — | E42: 6 | F42: — | G42: — | H42: — | I42: — | J42: 3 | K42: —
A43: 46246 | B43: — | C43: 32 | D43: — | E43: 3 | F43: — | G43: — | H43: — | I43: — | J43: 2 | K43: —
A44: 46247 | B44: — | C44: 34 | D44: — | E44: 1 | F44: — | G44: — | H44: — | I44: — | J44: 1 | K44: —
A45: 46248 | B45: — | C45: 35 | D45: — | E45: 0 | F45: — | G45: — | H45: — | I45: — | J45: 0 | K45: —
A46: Unplanned (no ETA / ETA beyond 14-Aug) | C46: 25
A48: Scope: only the 35 Stablization items with an ETA on or before 14-Aug-2026 — that's the actual plan for this deadline. Planned Delivered/Pending = cumulative count of those items due on or before that day, from their real ETA dates (not a smoothed ramp); recomputed every run, so it shifts if ETAs or the item set change. Ahead/Behind Plan = Delivered − Planned Delivered for that day. The 25 item(s) with no ETA (or an ETA after 14-Aug) are listed above, not counted toward this deadline.

Sheet Helper
A1: Module | B1: Phase | C1: Status | D1: Category | E1: Bucket | F1: ReqDate
A2: ='Stabilization - Items'!D2 -> iWork | B2: ='Stabilization - Items'!E2 -> Milestone 6 | C2: =TRIM('Stabilization - Items'!F2) -> DEV - WIP | D2: =IFERROR(VLOOKUP(C2,Config!$A:$B,2,0),"Unknown") -> In Development | E2: =IFERROR(VLOOKUP(C2,Config!$A:$C,3,0),"N/A") -> Pending | F2: =IF('Stabilization - Items'!H2="","",'Stabilization - Items'!H2) -> 46240
A3: ='Stabilization - Items'!D3 -> iWork | B3: ='Stabilization - Items'!E3 -> Milestone 6 | C3: =TRIM('Stabilization - Items'!F3) -> Yet to start | D3: =IFERROR(VLOOKUP(C3,Config!$A:$B,2,0),"Unknown") -> Not Started | E3: =IFERROR(VLOOKUP(C3,Config!$A:$C,3,0),"N/A") -> Pending | F3: =IF('Stabilization - Items'!H3="","",'Stabilization - Items'!H3) -> 46240
A4: ='Stabilization - Items'!D4 -> iWork | B4: ='Stabilization - Items'!E4 -> Milestone 6 | C4: =TRIM('Stabilization - Items'!F4) -> Yet to start | D4: =IFERROR(VLOOKUP(C4,Config!$A:$B,2,0),"Unknown") -> Not Started | E4: =IFERROR(VLOOKUP(C4,Config!$A:$C,3,0),"N/A") -> Pending | F4: =IF('Stabilization - Items'!H4="","",'Stabilization - Items'!H4) -> 46240
A5: ='Stabilization - Items'!D5 -> iWork | B5: ='Stabilization - Items'!E5 -> Milestone 6 | C5: =TRIM('Stabilization - Items'!F5) -> Yet to start | D5: =IFERROR(VLOOKUP(C5,Config!$A:$B,2,0),"Unknown") -> Not Started | E5: =IFERROR(VLOOKUP(C5,Config!$A:$C,3,0),"N/A") -> Pending | F5: =IF('Stabilization - Items'!H5="","",'Stabilization - Items'!H5) -> 46240
A6: ='Stabilization - Items'!D6 -> iWork | B6: ='Stabilization - Items'!E6 -> Milestone 6 | C6: =TRIM('Stabilization - Items'!F6) -> DEV - WIP | D6: =IFERROR(VLOOKUP(C6,Config!$A:$B,2,0),"Unknown") -> In Development | E6: =IFERROR(VLOOKUP(C6,Config!$A:$C,3,0),"N/A") -> Pending | F6: =IF('Stabilization - Items'!H6="","",'Stabilization - Items'!H6) -> 46235
A7: ='Stabilization - Items'!D7 -> iWork | B7: ='Stabilization - Items'!E7 -> Milestone 6 | C7: =TRIM('Stabilization - Items'!F7) -> Dev - Done | D7: =IFERROR(VLOOKUP(C7,Config!$A:$B,2,0),"Unknown") -> Dev Complete | E7: =IFERROR(VLOOKUP(C7,Config!$A:$C,3,0),"N/A") -> Delivered | F7: =IF('Stabilization - Items'!H7="","",'Stabilization - Items'!H7) -> 46235
A8: ='Stabilization - Items'!D8 -> iWork | B8: ='Stabilization - Items'!E8 -> Milestone 6 | C8: =TRIM('Stabilization - Items'!F8) -> Delivered | D8: =IFERROR(VLOOKUP(C8,Config!$A:$B,2,0),"Unknown") -> Delivered | E8: =IFERROR(VLOOKUP(C8,Config!$A:$C,3,0),"N/A") -> Delivered | F8: =IF('Stabilization - Items'!H8="","",'Stabilization - Items'!H8) -> 46235
A9: ='Stabilization - Items'!D9 -> iWork - CR | B9: ='Stabilization - Items'!E9 -> Milestone 6 | C9: =TRIM('Stabilization - Items'!F9) -> Delivered | D9: =IFERROR(VLOOKUP(C9,Config!$A:$B,2,0),"Unknown") -> Delivered | E9: =IFERROR(VLOOKUP(C9,Config!$A:$C,3,0),"N/A") -> Delivered | F9: =IF('Stabilization - Items'!H9="","",'Stabilization - Items'!H9) -> 46235
A10: ='Stabilization - Items'!D10 -> iWork | B10: ='Stabilization - Items'!E10 -> Milestone 6 | C10: =TRIM('Stabilization - Items'!F10) -> UAT - WIP | D10: =IFERROR(VLOOKUP(C10,Config!$A:$B,2,0),"Unknown") -> Pre-PROD / UAT | E10: =IFERROR(VLOOKUP(C10,Config!$A:$C,3,0),"N/A") -> Pending | F10: =IF('Stabilization - Items'!H10="","",'Stabilization - Items'!H10) -> 46235
A11: ='Stabilization - Items'!D11 -> iWork | B11: ='Stabilization - Items'!E11 -> Milestone 6 | C11: =TRIM('Stabilization - Items'!F11) -> Delivered | D11: =IFERROR(VLOOKUP(C11,Config!$A:$B,2,0),"Unknown") -> Delivered | E11: =IFERROR(VLOOKUP(C11,Config!$A:$C,3,0),"N/A") -> Delivered | F11: =IF('Stabilization - Items'!H11="","",'Stabilization - Items'!H11) -> 46235
A12: ='Stabilization - Items'!D12 -> iWork | B12: ='Stabilization - Items'!E12 -> Milestone 6 | C12: =TRIM('Stabilization - Items'!F12) -> Delivered | D12: =IFERROR(VLOOKUP(C12,Config!$A:$B,2,0),"Unknown") -> Delivered | E12: =IFERROR(VLOOKUP(C12,Config!$A:$C,3,0),"N/A") -> Delivered | F12: =IF('Stabilization - Items'!H12="","",'Stabilization - Items'!H12) -> 46235
A13: ='Stabilization - Items'!D13 -> IBP | B13: ='Stabilization - Items'!E13 -> Milestone 6 | C13: =TRIM('Stabilization - Items'!F13) -> Dev - Done | D13: =IFERROR(VLOOKUP(C13,Config!$A:$B,2,0),"Unknown") -> Dev Complete | E13: =IFERROR(VLOOKUP(C13,Config!$A:$C,3,0),"N/A") -> Delivered | F13: =IF('Stabilization - Items'!H13="","",'Stabilization - Items'!H13) -> 46235
... A61: ='Stabilization - Items'!D61 -> iWork | B61: ='Stabilization - Items'!E61 -> Milestone 6 | C61: =TRIM('Stabilization - Items'!F61) -> Yet to start | D61: =IFERROR(VLOOKUP(C61,Config!$A:$B,2,0),"Unknown") -> Not Started | E61: =IFERROR(VLOOKUP(C61,Config!$A:$C,3,0),"N/A") -> Pending | F61: =IF('Stabilization - Items'!H61="","",'Stabilization - Items'!H61) -> 46235

Sheet Config
A1: Status_Raw | B1: Category | C1: Bucket
A2: Delivered | B2: Delivered | C2: Delivered
A3: Dev - Done | B3: Dev Complete | C3: Delivered
A4: DEV - Done | B4: Dev Complete | C4: Delivered
A5: Dev - WIP | B5: In Development | C5: Pending
A6: DEV - WIP | B6: In Development | C6: Pending
A7: QA - WIP | B7: In QA | C7: Pending
A8: Pre-PROD | B8: Pre-PROD / UAT | C8: Pending
A9: UAT - WIP | B9: Pre-PROD / UAT | C9: Pending
A10: Yet to start | B10: Not Started | C10: Pending
A11: Delivered - Deficit | B11: Partial Delivery | C11: Pending
A12: Duplicate | B12: N/A | C12: N/A
... A14: Not in scope | B14: Delivered | C14: Delivered
