Workbook

Sheet SOW, Feedbacks-Bug & CR_Items
A1: Area | B1: Feature | C1: Functionality | D1: Module | E1: Phase | F1: Status | G1: Remarks | H1: Requested Date | I1: ETA | J1: Priority | K1: Start Date | L1: End Date | M1: Resource | N1: Jira ID
A2: Framework: DPDP | B2: Enable SAST | D2: DPDP | E2: Milestone 5 | F2: Delivered | H2: 45869 | I2: 46188
A3: Framework: DPDP | B3: Integrate SSO / MFA | D3: DPDP | E3: Milestone 5 | F3: Delivered | H3: 45869 | I3: 46142
A4: Framework: DPDP | B4: Capture consent within app | D4: DPDP | E4: Milestone 5 | F4: Delivered | H4: 45869 | I4: 46172 | N4: IIRM-8015
A5: Framework: DPDP | B5: Allow easy consent withdrawal | D5: DPDP | E5: Milestone 5 | F5: Delivered | H5: 45869 | I5: 46172 | N5: IIRM-8015
A6: Framework: DPDP | B6: Approval workflow | D6: DPDP | E6: Milestone 5 | F6: Delivered | H6: 45869 | I6: 46172
A7: Framework: DPDP | B7: Show privacy notice with purpose, retention, rights | D7: DPDP | E7: Milestone 5 | F7: Delivered | H7: 45869 | I7: 46172
A8: Framework: DPDP | B8: App vulnerability scans | D8: DPDP | E8: Milestone 5 | F8: DEV - WIP | H8: 45869 | I8: 46241
A9: Framework: DPDP | B9: Document Flows | D9: DPDP | E9: Milestone 5 | F9: DEV - WIP | H9: 45869 | I9: 46241
A10: Framework: DPDP | B10: Perform security UAT | D10: DPDP | E10: Milestone 5 | F10: DEV - WIP | H10: 45869 | I10: 46241
A11: Framework: DPDP | B11: Remove unnecessary fields | D11: DPDP | E11: Milestone 5 | F11: DEV - Done | H11: 45869 | I11: 46241
A12: Framework: DPDP | B12: Enforce business logic to restrict purpose | D12: DPDP | E12: Milestone 5 | F12: DEV - WIP | H12: 45869 | I12: 46241
A13: Framework: DPDP | B13: Allow user corrections | D13: DPDP | E13: Milestone 5 | F13: DEV - WIP | H13: 45869 | I13: 46241 | N13: IIRM-8015
A14: Framework: DPDP | B14: Delete expired data | D14: DPDP | E14: Milestone 5 | F14: DEV - WIP | H14: 45869 | I14: 46241 | N14: IIRM-8015
A15: Framework: DPDP | B15: Map PII tables | D15: DPDP | E15: Milestone 5 | F15: QA - WIP | H15: 45869 | I15: 46241 | M15: Rama
A16: Framework: DPDP | B16: Enable delete pipeline | D16: DPDP | E16: Milestone 5 | F16: Yet to start | H16: 45869 | I16: 46241 | N16: IIRM-8015
A17: Framework: DPDP | B17: Sign DPDP clauses | D17: DPDP | E17: Milestone 5 | F17: DEV - WIP | H17: 45869 | I17: 46241 | N17: IIRM-8015
A18: Framework: DPDP | B18: Quarterly restore tests | D18: DPDP | E18: Milestone 5 | F18: Pre-PROD | H18: 45869 | I18: 46241 | M18: Rama
A19: FRAMEWORK: Frontend | B19: Project setup | C19: Basic project / Development environment setup | D19: Framework | E19: Milestone 1 | F19: Delivered | H19: 45717 | N19: IIRM-17
A20: FRAMEWORK: Frontend | B20: UI Approach Design System | C20: Building Design System | D20: Framework | E20: Milestone 1 | F20: Delivered | H20: 45717 | N20: IIRM-734
A21: FRAMEWORK: Frontend | B21: Core Infrastructure | C21: Core Infra | D21: Framework | E21: Milestone 1 | F21: Delivered | H21: 45717
A22: FRAMEWORK: Frontend | B22: Build UI components | C22: This includes all the UI componnets to compose the application and module definitions: Form, Toast, Filter, Cards, Visualisation, Grid, Menu, Header, Footer, Maps Integration | D22: Framework | E22: Milestone 1 | F22: Delivered | H22: 45717 | N22: IIRM-836
A23: FRAMEWORK: Frontend | B23: UI Approach Style Establishment | C23: UI Style Establishment | D23: Framework | E23: Milestone 1 | F23: Delivered | H23: 45717 | N23: IIRM-838
A24: FRAMEWORK: Frontend | B24: Service Workers Implementation | D24: Framework | E24: Milestone 1 | F24: Delivered | H24: 45717 | N24: IIRM-19
A25: FRAMEWORK: Frontend | B25: Core System | D25: Framework | E25: Milestone 1 | F25: Delivered | H25: 45717 | N25: IIRM-80
A26: FRAMEWORK: Frontend | B26: ACL & RBAC Control Framework | D26: Framework | E26: Milestone 1 | F26: Delivered | H26: 45717 | N26: IIRM-18
A27: FRAMEWORK: Frontend | B27: Micro Frontend Setup | D27: Framework | E27: Milestone 1 | F27: Delivered | H27: 45717 | N27: IIRM-15
A28: FRAMEWORK: Frontend | B28: Landing Page | D28: Framework | E28: Milestone 1 | F28: Delivered | H28: 45717
A29: FRAMEWORK: Frontend | B29: Master Data Management | D29: Framework | E29: Milestone 2 | F29: Delivered | H29: 45763 | I29: 46169 | N29: IIRM-745
A30: FRAMEWORK: Frontend | B30: User Management | C30: 22-May: Other than iWork employee | D30: Framework | E30: Milestone 2 | F30: Delivered | G30: Pending: User deletion | H30: 45763 | I30: 46185 | N30: IIRM-744
A31: FRAMEWORK: Frontend | B31: Visualization framework | C31: Charts and KPIs | D31: Framework | E31: Milestone 2 | F31: Delivered | H31: 45763 | N31: IIRM-743
A32: FRAMEWORK: Frontend | B32: Document Management | C32: Create, Upload, Seach, Download | D32: Framework | E32: Milestone 2 | F32: Delivered | H32: 45763 | N32: IIRM-750
A33: FRAMEWORK: Frontend | B33: Caching of API Data | D33: Framework | E33: Milestone 2 | F33: Delivered | H33: 45763
A34: FRAMEWORK: Frontend | B34: Notifications Management | C34: Different email notification - Madhav excel. 1. Renewal Reminders - ASAP 2. Instalment Reminders 3. Others | D34: Framework | E34: Milestone 4 | F34: Pre-PROD | H34: 45818 | I34: 46237 | M34: Pushyami | N34: IIRM-761, IIRM-4740
A35: FRAMEWORK: Frontend | B35: Accessibility | C35: 20-Jul: Jagadees --> Need More details | D35: Framework | E35: Milestone 4 | F35: Yet to start | H35: 45818 | I35: 46241 | N35: IIRM-763
A36: FRAMEWORK: Frontend | B36: Localisation | D36: Framework | E36: Milestone 4 | F36: Delivered - Deficit | G36: Pending: Service Flow | H36: 45818 | I36: 46241 | M36: Tharun | N36: IIRM-764
A37: Framework: NFR | B37: NFR_Usability | C37: NFR-USA-018: The session management should be configurable from UI 23-May: Configure from UI & store in DB; When changed then restart server | D37: IBP | E37: Milestone 4 | F37: Delivered | H37: 45818 | I37: 46188 | M37: Manjusha | N37: IIRM-9912
A38: Framework: NFR | B38: NFR_Usability | C38: NFR-USA-015: The system must show personalized welcome messages and profile information based on locale. | D38: IBP | E38: Milestone 4 | F38: Delivered | H38: 45818 | N38: IIRM-4477
A39: Framework: NFR | B39: NFR_Usability | C39: NFR-USA-016: Notification banners must be dismissible and configurable based on role. | D39: IBP | E39: Milestone 4 | F39: Delivered | G39: No notifications in IBP | H39: 45818 | N39: IIRM-4478
A40: Framework: NFR | B40: NFR_Usability | C40: NFR-USA-021: Guidelines for document management should be provided | D40: NFR | E40: Milestone 4 | F40: Delivered - Deficit | G40: Pending: Provide the document on how do we store and view it | H40: 45818 | I40: 46241 | M40: Rama | N40: IIRM-4482
...

Sheet ① Executive Summary
A1: PROJECT DELIVERY PLAN
A4: iWork · IBP · Framework (IIRM SOW) | Status Overview & Forward Roadmap · As of 07-Aug-2026
A6: OVERALL COMPLETION | H6: REMAINING WORK
A7: =ROUND(COUNTIF(Helper!$E:$E,"Delivered")/(COUNTIF(Helper!$E:$E,"Delivered")+COUNTIF(Helper!$E:$E,"Pending")),3) -> 0.674 | D7: =COUNTIF(Helper!$E:$E,"Delivered")&" of "&(COUNTIF(Helper!$E:$E,"Delivered")+COUNTIF(Helper!$E:$E,"Pending"))&" scope items delivered" -> 287 of 426 scope items delivered | H7: =COUNTIF(Helper!$E:$E,"Pending") -> 139 | J7: items still to deliver across all modules — planned week by week in the weekly sheets
A11: SOW SCOPE — ORIGINAL vs CURRENT ITEMS
A12: Static comparison vs the 'SOW - Actual Items' reference sheet (original contracted scope). Matched by Module + Feature name. Recomputed on each re-run of the script.
A14: Original SOW items | G14: 158
A15: Currently tracked (all items) | G15: 426
A16: — new: DPDP / NFR / Change Requests | G16: 77
A17: — new: organic growth (existing modules) | G17: 199
A18: Net growth vs original SOW (158 → 426) | G18: +268
A19: ⚠ 2 original SOW item(s) still need review — no matching row in the tracker and no mapping note yet.
A20: 🔗 15 item(s) already mapped by hand to a renamed/restructured tracker row — see notes in 'SOW - Actual Items'.
A23: WEEKLY INTAKE — items requested (by Requested Date)
A24: Period | B24: Added | C24: Delivered | D24: Pending | E24: % Closed
A25: Before 01-Jun-2026 | B25: =COUNTIFS(Helper!$F:$F,"<"&DATE(2026,6,1)) -> 210 | C25: =COUNTIFS(Helper!$F:$F,"<"&DATE(2026,6,1),Helper!$E:$E,"Delivered") -> 156 | D25: =COUNTIFS(Helper!$F:$F,"<"&DATE(2026,6,1),Helper!$E:$E,"Pending") -> 54 | E25: =IFERROR(C25/B25,0) -> 0.74285714
A26: Week of 01 Jun 2026 | B26: =COUNTIFS(Helper!$F:$F,">="&DATE(2026,6,1),Helper!$F:$F,"<="&DATE(2026,6,7)) -> 5 | C26: =COUNTIFS(Helper!$F:$F,">="&DATE(2026,6,1),Helper!$F:$F,"<="&DATE(2026,6,7),Helper!$E:$E,"Delivered") -> 5 | D26: =COUNTIFS(Helper!$F:$F,">="&DATE(2026,6,1),Helper!$F:$F,"<="&DATE(2026,6,7),Helper!$E:$E,"Pending") -> 0 | E26: =IFERROR(C26/B26,0) -> 1
A27: Week of 08 Jun 2026 | B27: =COUNTIFS(Helper!$F:$F,">="&DATE(2026,6,8),Helper!$F:$F,"<="&DATE(2026,6,14)) -> 43 | C27: =COUNTIFS(Helper!$F:$F,">="&DATE(2026,6,8),Helper!$F:$F,"<="&DATE(2026,6,14),Helper!$E:$E,"Delivered") -> 42 | D27: =COUNTIFS(Helper!$F:$F,">="&DATE(2026,6,8),Helper!$F:$F,"<="&DATE(2026,6,14),Helper!$E:$E,"Pending") -> 1 | E27: =IFERROR(C27/B27,0) -> 0.97674419
A28: Week of 15 Jun 2026 | B28: =COUNTIFS(Helper!$F:$F,">="&DATE(2026,6,15),Helper!$F:$F,"<="&DATE(2026,6,21)) -> 11 | C28: =COUNTIFS(Helper!$F:$F,">="&DATE(2026,6,15),Helper!$F:$F,"<="&DATE(2026,6,21),Helper!$E:$E,"Delivered") -> 5 | D28: =COUNTIFS(Helper!$F:$F,">="&DATE(2026,6,15),Helper!$F:$F,"<="&DATE(2026,6,21),Helper!$E:$E,"Pending") -> 6 | E28: =IFERROR(C28/B28,0) -> 0.45454545
A29: Week of 22 Jun 2026 | B29: =COUNTIFS(Helper!$F:$F,">="&DATE(2026,6,22),Helper!$F:$F,"<="&DATE(2026,6,28)) -> 21 | C29: =COUNTIFS(Helper!$F:$F,">="&DATE(2026,6,22),Helper!$F:$F,"<="&DATE(2026,6,28),Helper!$E:$E,"Delivered") -> 15 | D29: =COUNTIFS(Helper!$F:$F,">="&DATE(2026,6,22),Helper!$F:$F,"<="&DATE(2026,6,28),Helper!$E:$E,"Pending") -> 6 | E29: =IFERROR(C29/B29,0) -> 0.71428571
A30: Week of 29 Jun 2026 | B30: =COUNTIFS(Helper!$F:$F,">="&DATE(2026,6,29),Helper!$F:$F,"<="&DATE(2026,7,5)) -> 5 | C30: =COUNTIFS(Helper!$F:$F,">="&DATE(2026,6,29),Helper!$F:$F,"<="&DATE(2026,7,5),Helper!$E:$E,"Delivered") -> 3 | D30: =COUNTIFS(Helper!$F:$F,">="&DATE(2026,6,29),Helper!$F:$F,"<="&DATE(2026,7,5),Helper!$E:$E,"Pending") -> 2 | E30: =IFERROR(C30/B30,0) -> 0.6
A31: Week of 06 Jul 2026 | B31: =COUNTIFS(Helper!$F:$F,">="&DATE(2026,7,6),Helper!$F:$F,"<="&DATE(2026,7,12)) -> 8 | C31: =COUNTIFS(Helper!$F:$F,">="&DATE(2026,7,6),Helper!$F:$F,"<="&DATE(2026,7,12),Helper!$E:$E,"Delivered") -> 7 | D31: =COUNTIFS(Helper!$F:$F,">="&DATE(2026,7,6),Helper!$F:$F,"<="&DATE(2026,7,12),Helper!$E:$E,"Pending") -> 1 | E31: =IFERROR(C31/B31,0) -> 0.875
A32: Week of 13 Jul 2026 | B32: =COUNTIFS(Helper!$F:$F,">="&DATE(2026,7,13),Helper!$F:$F,"<="&DATE(2026,7,19)) -> 24 | C32: =COUNTIFS(Helper!$F:$F,">="&DATE(2026,7,13),Helper!$F:$F,"<="&DATE(2026,7,19),Helper!$E:$E,"Delivered") -> 19 | D32: =COUNTIFS(Helper!$F:$F,">="&DATE(2026,7,13),Helper!$F:$F,"<="&DATE(2026,7,19),Helper!$E:$E,"Pending") -> 5 | E32: =IFERROR(C32/B32,0) -> 0.79166667
A33: Week of 20 Jul 2026 | B33: =COUNTIFS(Helper!$F:$F,">="&DATE(2026,7,20),Helper!$F:$F,"<="&DATE(2026,7,26)) -> 22 | C33: =COUNTIFS(Helper!$F:$F,">="&DATE(2026,7,20),Helper!$F:$F,"<="&DATE(2026,7,26),Helper!$E:$E,"Delivered") -> 18 | D33: =COUNTIFS(Helper!$F:$F,">="&DATE(2026,7,20),Helper!$F:$F,"<="&DATE(2026,7,26),Helper!$E:$E,"Pending") -> 4 | E33: =IFERROR(C33/B33,0) -> 0.81818182
A34: Week of 27 Jul 2026 — last week | B34: =COUNTIFS(Helper!$F:$F,">="&DATE(2026,7,27),Helper!$F:$F,"<="&DATE(2026,8,2)) -> 58 | C34: =COUNTIFS(Helper!$F:$F,">="&DATE(2026,7,27),Helper!$F:$F,"<="&DATE(2026,8,2),Helper!$E:$E,"Delivered") -> 16 | D34: =COUNTIFS(Helper!$F:$F,">="&DATE(2026,7,27),Helper!$F:$F,"<="&DATE(2026,8,2),Helper!$E:$E,"Pending") -> 42 | E34: =IFERROR(C34/B34,0) -> 0.27586207
A35: Week of 03 Aug 2026 — this week | B35: =COUNTIFS(Helper!$F:$F,">="&DATE(2026,8,3),Helper!$F:$F,"<="&DATE(2026,8,9)) -> 19 | C35: =COUNTIFS(Helper!$F:$F,">="&DATE(2026,8,3),Helper!$F:$F,"<="&DATE(2026,8,9),Helper!$E:$E,"Delivered") -> 1 | D35: =COUNTIFS(Helper!$F:$F,">="&DATE(2026,8,3),Helper!$F:$F,"<="&DATE(2026,8,9),Helper!$E:$E,"Pending") -> 18 | E35: =IFERROR(C35/B35,0) -> 0.052631579
A36: Requested ahead (after 09 Aug) | B36: =COUNTIFS(Helper!$F:$F,">"&DATE(2026,8,9)) -> 0 | C36: =COUNTIFS(Helper!$F:$F,">"&DATE(2026,8,9),Helper!$E:$E,"Delivered") -> 0 | D36: =COUNTIFS(Helper!$F:$F,">"&DATE(2026,8,9),Helper!$E:$E,"Pending") -> 0 | E36: =IFERROR(C36/B36,0) -> 0
A37: No Requested Date | B37: =COUNTA(Helper!$C$2:$C$5000)-COUNT(Helper!$F$2:$F$5000) -> 0 | C37: =COUNTIFS(Helper!$F:$F,"",Helper!$E:$E,"Delivered") -> 0 | D37: =COUNTIFS(Helper!$F:$F,"",Helper!$E:$E,"Pending") -> 0 | E37: =IFERROR(C37/B37,0) -> 0
A38: TOTAL | B38: =SUM(B25:B37) -> 426 | C38: =SUM(C25:C37) -> 287 | D38: =SUM(D25:D37) -> 139 | E38: =IFERROR(C38/B38,0) -> 0.67370892
A40: STATUS BREAKDOWN (all items)
A41: =COUNTIF(Helper!$D:$D,"Delivered") -> 281 | D41: =COUNTIF(Helper!$D:$D,"Dev Complete") -> 6 | G41: =COUNTIF(Helper!$D:$D,"In Development") -> 22 | J41: =COUNTIF(Helper!$D:$D,"In QA") -> 4
A42: Delivered | D42: Dev Complete | G42: In Development | J42: In QA
A43: =COUNTIF(Helper!$D:$D,"Pre-PROD / UAT") -> 20 | D43: =COUNTIF(Helper!$D:$D,"Not Started") -> 90 | G43: =COUNTIF(Helper!$D:$D,"Partial Delivery") -> 3 | J43: =COUNTIF(Helper!$D:$D,"N/A") -> 0
A44: Pre-PROD / UAT | D44: Not Started | G44: Partial Delivery | J44: N/A
A46: PROGRESS BY MODULE
A47: Module | B47: Type | C47: Total | D47: Delivered | E47: Pending | F47: N/A | G47: % Complete | H47: Progress
A48: iWork (Backlog) | B48: Backlog | C48: =COUNTIF(Helper!$A:$A,"iWork") -> 212 | D48: =COUNTIFS(Helper!$A:$A,"iWork",Helper!$E:$E,"Delivered") -> 139 | E48: =COUNTIFS(Helper!$A:$A,"iWork",Helper!$E:$E,"Pending") -> 73 | F48: =COUNTIFS(Helper!$A:$A,"iWork",Helper!$E:$E,"N/A") -> 0 | G48: =IFERROR(D48/(D48+E48),0) -> 0.65566038 | H48: =G48 -> 0.65566038
A49: iWork (Change Requests) | B49: Change Request | C49: =COUNTIF(Helper!$A:$A,"iWork - CR") -> 43 | D49: =COUNTIFS(Helper!$A:$A,"iWork - CR",Helper!$E:$E,"Delivered") -> 37 | E49: =COUNTIFS(Helper!$A:$A,"iWork - CR",Helper!$E:$E,"Pending") -> 6 | F49: =COUNTIFS(Helper!$A:$A,"iWork - CR",Helper!$E:$E,"N/A") -> 0 | G49: =IFERROR(D49/(D49+E49),0) -> 0.86046512 | H49: =G49 -> 0.86046512
A50: IBP (Backlog) | B50: Backlog | C50: =COUNTIF(Helper!$A:$A,"IBP") -> 71 | D50: =COUNTIFS(Helper!$A:$A,"IBP",Helper!$E:$E,"Delivered") -> 51 | E50: =COUNTIFS(Helper!$A:$A,"IBP",Helper!$E:$E,"Pending") -> 20 | F50: =COUNTIFS(Helper!$A:$A,"IBP",Helper!$E:$E,"N/A") -> 0 | G50: =IFERROR(D50/(D50+E50),0) -> 0.71830986 | H50: =G50 -> 0.71830986
A51: IBP (Change Requests) | B51: Change Request | C51: =COUNTIF(Helper!$A:$A,"IBP - CR") -> 3 | D51: =COUNTIFS(Helper!$A:$A,"IBP - CR",Helper!$E:$E,"Delivered") -> 2 | E51: =COUNTIFS(Helper!$A:$A,"IBP - CR",Helper!$E:$E,"Pending") -> 1 | F51: =COUNTIFS(Helper!$A:$A,"IBP - CR",Helper!$E:$E,"N/A") -> 0 | G51: =IFERROR(D51/(D51+E51),0) -> 0.66666667 | H51: =G51 -> 0.66666667
...

Sheet ② Stablization Summary
A1: STABILIZATION — STATUS OVERVIEW
A4: Stabilization Area | Break-up by Feature · As of 07-Aug-2026
A6: OVERALL COMPLETION | H6: REMAINING WORK
A7: =ROUND(COUNTIFS('SOW, Feedbacks-Bug & CR_Items'!$A:$A,"Stablization",Helper!$E:$E,"Delivered")/(COUNTIFS('SOW, Feedbacks-Bug & CR_Items'!$A:$A,"Stablization",Helper!$E:$E,"Delivered")+COUNTIFS('SOW, Feedbacks-Bug & CR_Items'!$A:$A,"Stablization",Helper!$E:$E,"Pending")),3) -> 0.15 | D7: =COUNTIFS('SOW, Feedbacks-Bug & CR_Items'!$A:$A,"Stablization",Helper!$E:$E,"Delivered")&" of "&(COUNTIFS('SOW, Feedbacks-Bug & CR_Items'!$A:$A,"Stablization",Helper!$E:$E,"Delivered")+COUNTIFS('SOW, Feedbacks-Bug & CR_Items'!$A:$A,"Stablization",Helper!$E:$E,"Pending"))&" Stabilization items delivered" -> 9 of 60 Stabilization items delivered | H7: =COUNTIFS('SOW, Feedbacks-Bug & CR_Items'!$A:$A,"Stablization",Helper!$E:$E,"Pending") -> 51 | J7: Stabilization items still to deliver, broken up by Feature below
A11: STATUS BREAKDOWN (Stabilization items)
A12: =COUNTIFS('SOW, Feedbacks-Bug & CR_Items'!$A:$A,"Stablization",Helper!$D:$D,"Delivered") -> 5 | D12: =COUNTIFS('SOW, Feedbacks-Bug & CR_Items'!$A:$A,"Stablization",Helper!$D:$D,"Dev Complete") -> 4 | G12: =COUNTIFS('SOW, Feedbacks-Bug & CR_Items'!$A:$A,"Stablization",Helper!$D:$D,"In Development") -> 8 | J12: =COUNTIFS('SOW, Feedbacks-Bug & CR_Items'!$A:$A,"Stablization",Helper!$D:$D,"In QA") -> 0
A13: Delivered | D13: Dev Complete | G13: In Development | J13: In QA
A14: =COUNTIFS('SOW, Feedbacks-Bug & CR_Items'!$A:$A,"Stablization",Helper!$D:$D,"Pre-PROD / UAT") -> 2 | D14: =COUNTIFS('SOW, Feedbacks-Bug & CR_Items'!$A:$A,"Stablization",Helper!$D:$D,"Not Started") -> 41 | G14: =COUNTIFS('SOW, Feedbacks-Bug & CR_Items'!$A:$A,"Stablization",Helper!$D:$D,"Partial Delivery") -> 0 | J14: =COUNTIFS('SOW, Feedbacks-Bug & CR_Items'!$A:$A,"Stablization",Helper!$D:$D,"N/A") -> 0
A15: Pre-PROD / UAT | D15: Not Started | G15: Partial Delivery | J15: N/A
A17: BREAKDOWN BY FEATURE
A18: Feature | B18: Total | C18: Delivered | D18: Pending | E18: N/A | F18: % Complete | G18: Progress
A19: Business Critical | B19: =COUNTIFS('SOW, Feedbacks-Bug & CR_Items'!$A:$A,"Stablization",'SOW, Feedbacks-Bug & CR_Items'!$B:$B,"Business Critical") -> 22 | C19: =COUNTIFS('SOW, Feedbacks-Bug & CR_Items'!$A:$A,"Stablization",'SOW, Feedbacks-Bug & CR_Items'!$B:$B,"Business Critical",Helper!$E:$E,"Delivered") -> 7 | D19: =COUNTIFS('SOW, Feedbacks-Bug & CR_Items'!$A:$A,"Stablization",'SOW, Feedbacks-Bug & CR_Items'!$B:$B,"Business Critical",Helper!$E:$E,"Pending") -> 15 | E19: =COUNTIFS('SOW, Feedbacks-Bug & CR_Items'!$A:$A,"Stablization",'SOW, Feedbacks-Bug & CR_Items'!$B:$B,"Business Critical",Helper!$E:$E,"N/A") -> 0 | F19: =IFERROR(C19/(C19+D19),0) -> 0.31818182 | G19: =F19 -> 0.31818182
A20: Maintenance | B20: =COUNTIFS('SOW, Feedbacks-Bug & CR_Items'!$A:$A,"Stablization",'SOW, Feedbacks-Bug & CR_Items'!$B:$B,"Maintenance") -> 10 | C20: =COUNTIFS('SOW, Feedbacks-Bug & CR_Items'!$A:$A,"Stablization",'SOW, Feedbacks-Bug & CR_Items'!$B:$B,"Maintenance",Helper!$E:$E,"Delivered") -> 0 | D20: =COUNTIFS('SOW, Feedbacks-Bug & CR_Items'!$A:$A,"Stablization",'SOW, Feedbacks-Bug & CR_Items'!$B:$B,"Maintenance",Helper!$E:$E,"Pending") -> 10 | E20: =COUNTIFS('SOW, Feedbacks-Bug & CR_Items'!$A:$A,"Stablization",'SOW, Feedbacks-Bug & CR_Items'!$B:$B,"Maintenance",Helper!$E:$E,"N/A") -> 0 | F20: =IFERROR(C20/(C20+D20),0) -> 0 | G20: =F20 -> 0
A21: Operational | B21: =COUNTIFS('SOW, Feedbacks-Bug & CR_Items'!$A:$A,"Stablization",'SOW, Feedbacks-Bug & CR_Items'!$B:$B,"Operational") -> 25 | C21: =COUNTIFS('SOW, Feedbacks-Bug & CR_Items'!$A:$A,"Stablization",'SOW, Feedbacks-Bug & CR_Items'!$B:$B,"Operational",Helper!$E:$E,"Delivered") -> 2 | D21: =COUNTIFS('SOW, Feedbacks-Bug & CR_Items'!$A:$A,"Stablization",'SOW, Feedbacks-Bug & CR_Items'!$B:$B,"Operational",Helper!$E:$E,"Pending") -> 23 | E21: =COUNTIFS('SOW, Feedbacks-Bug & CR_Items'!$A:$A,"Stablization",'SOW, Feedbacks-Bug & CR_Items'!$B:$B,"Operational",Helper!$E:$E,"N/A") -> 0 | F21: =IFERROR(C21/(C21+D21),0) -> 0.08 | G21: =F21 -> 0.08
A22: Orphan Records | B22: =COUNTIFS('SOW, Feedbacks-Bug & CR_Items'!$A:$A,"Stablization",'SOW, Feedbacks-Bug & CR_Items'!$B:$B,"Orphan Records") -> 3 | C22: =COUNTIFS('SOW, Feedbacks-Bug & CR_Items'!$A:$A,"Stablization",'SOW, Feedbacks-Bug & CR_Items'!$B:$B,"Orphan Records",Helper!$E:$E,"Delivered") -> 0 | D22: =COUNTIFS('SOW, Feedbacks-Bug & CR_Items'!$A:$A,"Stablization",'SOW, Feedbacks-Bug & CR_Items'!$B:$B,"Orphan Records",Helper!$E:$E,"Pending") -> 3 | E22: =COUNTIFS('SOW, Feedbacks-Bug & CR_Items'!$A:$A,"Stablization",'SOW, Feedbacks-Bug & CR_Items'!$B:$B,"Orphan Records",Helper!$E:$E,"N/A") -> 0 | F22: =IFERROR(C22/(C22+D22),0) -> 0 | G22: =F22 -> 0
A23: TOTAL | B23: =COUNTIFS('SOW, Feedbacks-Bug & CR_Items'!$A:$A,"Stablization") -> 60 | C23: =COUNTIFS('SOW, Feedbacks-Bug & CR_Items'!$A:$A,"Stablization",Helper!$E:$E,"Delivered") -> 9 | D23: =COUNTIFS('SOW, Feedbacks-Bug & CR_Items'!$A:$A,"Stablization",Helper!$E:$E,"Pending") -> 51 | E23: =COUNTIFS('SOW, Feedbacks-Bug & CR_Items'!$A:$A,"Stablization",Helper!$E:$E,"N/A") -> 0 | F23: =IFERROR(C23/(C23+D23),0) -> 0.15 | G23: =F23 -> 0.15
A25: Scope: rows where Area = 'Stablization' in the source sheet. % Complete = Delivered ÷ (Delivered + Pending). N/A items excluded. Counts update live from the source sheet; re-run the script only if a new Feature value is added under this Area (to add its row here).
A27: PRIORITY vs STATUS
A28: Priority | B28: Delivered | C28: Dev Complete | D28: In Development | E28: In QA | F28: Pre-PROD / UAT | G28: Not Started | H28: Partial Delivery | I28: N/A | J28: Unknown | K28: TOTAL
A29: High | B29: =COUNTIFS('SOW, Feedbacks-Bug & CR_Items'!$A:$A,"Stablization",'SOW, Feedbacks-Bug & CR_Items'!$J:$J,"High",Helper!$D:$D,"Delivered") -> 5 | C29: =COUNTIFS('SOW, Feedbacks-Bug & CR_Items'!$A:$A,"Stablization",'SOW, Feedbacks-Bug & CR_Items'!$J:$J,"High",Helper!$D:$D,"Dev Complete") -> 4 | D29: =COUNTIFS('SOW, Feedbacks-Bug & CR_Items'!$A:$A,"Stablization",'SOW, Feedbacks-Bug & CR_Items'!$J:$J,"High",Helper!$D:$D,"In Development") -> 8 | E29: =COUNTIFS('SOW, Feedbacks-Bug & CR_Items'!$A:$A,"Stablization",'SOW, Feedbacks-Bug & CR_Items'!$J:$J,"High",Helper!$D:$D,"In QA") -> 0 | F29: =COUNTIFS('SOW, Feedbacks-Bug & CR_Items'!$A:$A,"Stablization",'SOW, Feedbacks-Bug & CR_Items'!$J:$J,"High",Helper!$D:$D,"Pre-PROD / UAT") -> 2 | G29: =COUNTIFS('SOW, Feedbacks-Bug & CR_Items'!$A:$A,"Stablization",'SOW, Feedbacks-Bug & CR_Items'!$J:$J,"High",Helper!$D:$D,"Not Started") -> 17 | H29: =COUNTIFS('SOW, Feedbacks-Bug & CR_Items'!$A:$A,"Stablization",'SOW, Feedbacks-Bug & CR_Items'!$J:$J,"High",Helper!$D:$D,"Partial Delivery") -> 0 | I29: =COUNTIFS('SOW, Feedbacks-Bug & CR_Items'!$A:$A,"Stablization",'SOW, Feedbacks-Bug & CR_Items'!$J:$J,"High",Helper!$D:$D,"N/A") -> 0 | J29: =COUNTIFS('SOW, Feedbacks-Bug & CR_Items'!$A:$A,"Stablization",'SOW, Feedbacks-Bug & CR_Items'!$J:$J,"High",Helper!$D:$D,"Unknown") -> 0 | K29: =SUM(B29:J29) -> 36
A30: Medium | B30: =COUNTIFS('SOW, Feedbacks-Bug & CR_Items'!$A:$A,"Stablization",'SOW, Feedbacks-Bug & CR_Items'!$J:$J,"Medium",Helper!$D:$D,"Delivered") -> 0 | C30: =COUNTIFS('SOW, Feedbacks-Bug & CR_Items'!$A:$A,"Stablization",'SOW, Feedbacks-Bug & CR_Items'!$J:$J,"Medium",Helper!$D:$D,"Dev Complete") -> 0 | D30: =COUNTIFS('SOW, Feedbacks-Bug & CR_Items'!$A:$A,"Stablization",'SOW, Feedbacks-Bug & CR_Items'!$J:$J,"Medium",Helper!$D:$D,"In Development") -> 0 | E30: =COUNTIFS('SOW, Feedbacks-Bug & CR_Items'!$A:$A,"Stablization",'SOW, Feedbacks-Bug & CR_Items'!$J:$J,"Medium",Helper!$D:$D,"In QA") -> 0 | F30: =COUNTIFS('SOW, Feedbacks-Bug & CR_Items'!$A:$A,"Stablization",'SOW, Feedbacks-Bug & CR_Items'!$J:$J,"Medium",Helper!$D:$D,"Pre-PROD / UAT") -> 0 | G30: =COUNTIFS('SOW, Feedbacks-Bug & CR_Items'!$A:$A,"Stablization",'SOW, Feedbacks-Bug & CR_Items'!$J:$J,"Medium",Helper!$D:$D,"Not Started") -> 6 | H30: =COUNTIFS('SOW, Feedbacks-Bug & CR_Items'!$A:$A,"Stablization",'SOW, Feedbacks-Bug & CR_Items'!$J:$J,"Medium",Helper!$D:$D,"Partial Delivery") -> 0 | I30: =COUNTIFS('SOW, Feedbacks-Bug & CR_Items'!$A:$A,"Stablization",'SOW, Feedbacks-Bug & CR_Items'!$J:$J,"Medium",Helper!$D:$D,"N/A") -> 0 | J30: =COUNTIFS('SOW, Feedbacks-Bug & CR_Items'!$A:$A,"Stablization",'SOW, Feedbacks-Bug & CR_Items'!$J:$J,"Medium",Helper!$D:$D,"Unknown") -> 0 | K30: =SUM(B30:J30) -> 6
A31: Low | B31: =COUNTIFS('SOW, Feedbacks-Bug & CR_Items'!$A:$A,"Stablization",'SOW, Feedbacks-Bug & CR_Items'!$J:$J,"Low",Helper!$D:$D,"Delivered") -> 0 | C31: =COUNTIFS('SOW, Feedbacks-Bug & CR_Items'!$A:$A,"Stablization",'SOW, Feedbacks-Bug & CR_Items'!$J:$J,"Low",Helper!$D:$D,"Dev Complete") -> 0 | D31: =COUNTIFS('SOW, Feedbacks-Bug & CR_Items'!$A:$A,"Stablization",'SOW, Feedbacks-Bug & CR_Items'!$J:$J,"Low",Helper!$D:$D,"In Development") -> 0 | E31: =COUNTIFS('SOW, Feedbacks-Bug & CR_Items'!$A:$A,"Stablization",'SOW, Feedbacks-Bug & CR_Items'!$J:$J,"Low",Helper!$D:$D,"In QA") -> 0 | F31: =COUNTIFS('SOW, Feedbacks-Bug & CR_Items'!$A:$A,"Stablization",'SOW, Feedbacks-Bug & CR_Items'!$J:$J,"Low",Helper!$D:$D,"Pre-PROD / UAT") -> 0 | G31: =COUNTIFS('SOW, Feedbacks-Bug & CR_Items'!$A:$A,"Stablization",'SOW, Feedbacks-Bug & CR_Items'!$J:$J,"Low",Helper!$D:$D,"Not Started") -> 18 | H31: =COUNTIFS('SOW, Feedbacks-Bug & CR_Items'!$A:$A,"Stablization",'SOW, Feedbacks-Bug & CR_Items'!$J:$J,"Low",Helper!$D:$D,"Partial Delivery") -> 0 | I31: =COUNTIFS('SOW, Feedbacks-Bug & CR_Items'!$A:$A,"Stablization",'SOW, Feedbacks-Bug & CR_Items'!$J:$J,"Low",Helper!$D:$D,"N/A") -> 0 | J31: =COUNTIFS('SOW, Feedbacks-Bug & CR_Items'!$A:$A,"Stablization",'SOW, Feedbacks-Bug & CR_Items'!$J:$J,"Low",Helper!$D:$D,"Unknown") -> 0 | K31: =SUM(B31:J31) -> 18
A32: TOTAL | B32: =SUM(B29:B31) -> 5 | C32: =SUM(C29:C31) -> 4 | D32: =SUM(D29:D31) -> 8 | E32: =SUM(E29:E31) -> 0 | F32: =SUM(F29:F31) -> 2 | G32: =SUM(G29:G31) -> 41 | H32: =SUM(H29:H31) -> 0 | I32: =SUM(I29:I31) -> 0 | ... K32: =SUM(K29:K31) -> 60
A34: Scope: rows where Area = 'Stablization', grouped by the 'Priority' column. Counts update live from the source sheet; re-run the script only if a new Priority value is used (to add its row here).
A36: DAILY PROGRESS — toward the 14-Aug-2026 deadline
A37: Date | B37: Total | C37: Planned Delivered | D37: Delivered | E37: Planned Pending | F37: Pending | G37: Delivered Today | H37: % Complete | I37: Ahead/Behind Plan | J37: Days Left | K37: Req. Pace/day
A38: 46237 | B38: 31 | C38: 2 | D38: 0 | E38: 33 | F38: 31 | G38: — | H38: 0 | I38: -2 | J38: 11 | K38: 2.8
A39: 46238 | B39: 31 | C39: 6 | D39: 0 | E39: 29 | F39: 31 | G39: 0 | H39: 0 | I39: -6 | J39: 10 | K39: 3.1
A40: 46239 | B40: — | C40: 10 | D40: — | E40: 25 | F40: — | G40: — | H40: — | I40: — | J40: 9 | K40: —
A41: 46240 | B41: 35 | C41: 16 | D41: 9 | E41: 19 | F41: 26 | G41: 9 | H41: 0.2571 | I41: -7 | J41: 8 | K41: 3.2
A42: 46241 | B42: 35 | C42: 21 | D42: 9 | E42: 14 | F42: 26 | G42: 0 | H42: 0.2571 | I42: -12 | J42: 7 | K42: 3.7
A43: 46242 | B43: — | C43: 21 | D43: — | E43: 14 | F43: — | G43: — | H43: — | I43: — | J43: 6 | K43: —
A44: 46243 | B44: — | C44: 21 | D44: — | E44: 14 | F44: — | G44: — | H44: — | I44: — | J44: 5 | K44: —
A45: 46244 | B45: — | C45: 22 | D45: — | E45: 13 | F45: — | G45: — | H45: — | I45: — | J45: 4 | K45: —
A46: 46245 | B46: — | C46: 29 | D46: — | E46: 6 | F46: — | G46: — | H46: — | I46: — | J46: 3 | K46: —
A47: 46246 | B47: — | C47: 32 | D47: — | E47: 3 | F47: — | G47: — | H47: — | I47: — | J47: 2 | K47: —
A48: 46247 | B48: — | C48: 34 | D48: — | E48: 1 | F48: — | G48: — | H48: — | I48: — | J48: 1 | K48: —
A49: 46248 | B49: — | C49: 35 | D49: — | E49: 0 | F49: — | G49: — | H49: — | I49: — | J49: 0 | K49: —
A50: Unplanned (no ETA / ETA beyond 14-Aug) | C50: 25
A52: Scope: only the 35 Stablization items with an ETA on or before 14-Aug-2026 — that's the actual plan for this deadline. Planned Delivered/Pending = cumulative count of those items due on or before that day, from their real ETA dates (not a smoothed ramp); recomputed every run, so it shifts if ETAs or the item set change. Ahead/Behind Plan = Delivered − Planned Delivered for that day. The 25 item(s) with no ETA (or an ETA after 14-Aug) are listed above, not counted toward this deadline.

Sheet 📅 27-Jul
A1: WEEK OF 27 Jul 2026 → 02 Aug 2026 — 11 items · 10 delivered · 1 pending · LAST WEEK
A3: ⚠️ Static snapshot. To update: edit STATUS/ETA in the source sheet, then re-run build_iirm_summary.py
A5: # | B5: Module | C5: Feature | D5: Functionality | E5: Status | F5: Milestone | G5: Requested | H5: ETA | I5: Resource | J5: Remarks
A6: iWork (Backlog & CRs) · 9 items · 8 delivered · 1 pending
A7: 1 | B7: iWork | C7: My Client Portfolio | D7: My Client Portfolio: issues - company search and brokerage | E7: Delivered | F7: Milestone 6 | G7: 27-Jul-2026 | H7: 27-Jul-2026 | I7: Pushyami
A8: 2 | B8: iWork | C8: Dashboard | D8: Dashboard issue - ISG planning count mismatch | E8: Delivered | F8: Milestone 6 | G8: 28-Jul-2026 | H8: 28-Jul-2026 | I8: Pushyami
A9: 3 | B9: iWork | C9: Dashboard | D9: Business Performance-breakup - count mismatch | E9: Delivered | F9: Milestone 6 | G9: 28-Jul-2026 | H9: 28-Jul-2026 | I9: Pushyami
A10: 4 | B10: iWork | C10: View Service Score | D10: My Client Portfolio: Service Score - Single Table (drillable) to calculate an overall score Dashboard - Service Score - Widget | E10: Delivered | F10: Milestone 4 | G10: 10-Jun-2025 | H10: 29-Jul-2026 | I10: Sunil
A11: 5 | B11: iWork | C11: Manage Insurer | D11: Insurer-branch-edit | E11: Delivered | F11: Milestone 6 | G11: 29-Jul-2026 | H11: 29-Jul-2026
A12: 6 | B12: IBP/iWork | C12: Core Infrastructure | D12: Core Infra | E12: Delivered | F12: Milestone 5 | G12: 31-Jul-2025 | H12: 31-Jul-2026 | I12: Velangini Raju | J12: Pending: Mobile responsive
A13: 7 | B13: iWork | C13: HRMS Integration Mgmt Framework provided to link the HRMS portal in Risk Watch | D13: Base framework needs to be built and actual integration should be on need - Need to create the API's for each service flow process (Endorsement - Add/Delete) - Endorsement process - What is the process for this? HRMS - integrations with enrolment portal (POC - with Zoho People), client mentioned that they have already integrated MB360 for HCL IBP & HRMS Integration - HCL | E13: Pre-PROD | F13: Milestone 5 | G13: 31-Jul-2025 | H13: 31-Jul-2026 | J13: As per us Framework is Ready. Validate integrate HCL API's and test it.
A14: 8 | B14: IBP/iWork | C14: Enrolment Journey - EMI's | D14: Based on Employee's enrolment period, the EMI months should be pro-ration month. Ex: Day-1 should show the all months EMI. If someone enrol after 2-months then EMI should be based on that. | E14: Delivered | F14: Milestone 6 | G14: 29-Jul-2026 | H14: 31-Jul-2026 | J14: Kriti raised
A15: 9 | B15: iWork | C15: BizDone - Data Updates | D15: Bizdone 2025-26 - Ass. CRM & Lead CRM Corrections | E15: Delivered | F15: Milestone 6 | G15: 30-Jul-2026 | H15: 31-Jul-2026 | J15: Madhav sent in IIRM email
A16: IBP (Backlog & CRs) · 2 items · 2 delivered · 0 pending
A17: 10 | B17: IBP | C17: Chat Interface | D17: Floater on the screen - Integrate with AI Component and IWork support channel | E17: Delivered | F17: Milestone 5 | G17: 31-Jul-2025 | H17: 31-Jul-2026
A18: 11 | B18: IBP | C18: Chat for End Users | D18: Chat Module to interact with Chat Bot and Customer Support Representative | E18: Delivered | F18: Milestone 5 | G18: 31-Jul-2025 | H18: 31-Jul-2026 | I18: Abhilash | J18: External chatbot integration?

Sheet 📍 03-Aug
A1: WEEK OF 03 Aug 2026 → 09 Aug 2026 — 86 items · 11 delivered · 75 pending · CURRENT WEEK
A3: ⚠️ Static snapshot. To update: edit STATUS/ETA in the source sheet, then re-run build_iirm_summary.py
A5: # | B5: Module | C5: Feature | D5: Functionality | E5: Status | F5: Milestone | G5: Requested | H5: ETA | I5: Resource | J5: Remarks
A6: iWork (Backlog & CRs) · 49 items · 8 delivered · 41 pending
A7: 1 | B7: iWork | C7: Cut Off Mgmt | E7: Pre-PROD | F7: Milestone 2 | G7: 16-Apr-2025 | H7: 03-Aug-2026 | I7: Karan
A8: 2 | B8: IBP/iWork | C8: Wellness Discount List Management | D8: Add/Remove/update Discount program benefits | E8: Pre-PROD | F8: Milestone 4 | G8: 10-Jun-2025 | H8: 03-Aug-2026
A9: 3 | B9: IBP/iWork | C9: Upload from Partner of services bought on Partner site | D9: Upload, listing, confirm & load into DB by an Iwork user. These are services purchased / discounts availed on partner sites by IBP corporate users | E9: Pre-PROD | F9: Milestone 4 | G9: 10-Jun-2025 | H9: 03-Aug-2026
A10: 4 | B10: IBP/iWork | C10: Wellness Admin Configurator | D10: Admin side of IBP (in iWork) needs to customize/configure the offerings/page per Corporate. | E10: Pre-PROD | F10: Milestone 5 | G10: 31-Jul-2025 | H10: 03-Aug-2026 | I10: Ravi
A11: 5 | B11: IBP/iWork | C11: End User Portal Configurator | D11: What set of features to be enabled or disabled, Offers, Benefits etc. More or less how portal should contain and visible to end user needs to be configured (per Corporate Configuration) | E11: Pre-PROD | F11: Milestone 5 | G11: 31-Jul-2025 | H11: 03-Aug-2026 | I11: Manjusha | J11: Pending: Offer, Feature flagging (UI)
A12: 6 | B12: iWork | C12: ISG Flow Changes | D12: Placement Slip flow - Terrorism premium in Insurer Sharing | E12: Pre-PROD | F12: Milestone 6 | G12: 27-Jul-2026 | H12: 03-Aug-2026 | I12: Karan | J12: Madhav sent in IIRM email
A13: 7 | B13: iWork | C13: Business Critical | D13: Migration Data load should be always complete only after manual Performances Job Execution - Continous acitivity | E13: DEV - WIP | F13: Milestone 6 | G13: 01-Aug-2026 | H13: 03-Aug-2026 | I13: Rama | J13: Anytime, manual load or adjustments are done, performance job needs to be executed for entire period
A14: 8 | B14: iWork | C14: Business Critical | D14: Dashboard: Implementation of the dynamic fetching of widgets data without depending on performance output cron job | E14: UAT - WIP | F14: Milestone 6 | G14: 01-Aug-2026 | H14: 03-Aug-2026 | I14: Jagadeesh
A15: 9 | B15: IBP/iWork - CR | C15: Service Flow - Upload Employee Details | D15: Upsert logic - Tough there is an employee data historically, when user upload latest file we have to update the "Empolyee" or "Dependent" details with the latest information | E15: DEV - WIP | F15: Milestone 6 | G15: 01-Jul-2026 | H15: 04-Aug-2026 | I15: Jagadeesh
A16: 10 | B16: IBP/iWork | C16: IBP - Email Communication | D16: For an enrolled employee with Dependents using Service, instead of Welcome Email they should get Confirmation email | E16: Pre-PROD | F16: Milestone 6 | G16: 25-Jul-2026 | H16: 04-Aug-2026 | I16: Abhilash | J16: API is ready. Need to add into Notification framework
A17: 11 | B17: iWork | C17: IBP - Enrolment Details | D17: DVN Group - Dependent based on SI & Premium changes | E17: DEV - WIP | F17: Milestone 6 | G17: 01-Aug-2026 | H17: 04-Aug-2026 | I17: Abhilash
A18: 12 | B18: iWork | C18: Business Critical | D18: Dashboard: Having individual component loaders on the landing page for each component and web-socket framework to avoid long-loading blank page issue. | E18: Dev - Done | F18: Milestone 6 | G18: 01-Aug-2026 | H18: 04-Aug-2026 | I18: Manjusha
A19: 13 | B19: iWork | C19: Business Critical | D19: BizDone & Dashboard: Filters Persistance | E19: Delivered | F19: Milestone 6 | G19: 01-Aug-2026 | H19: 04-Aug-2026 | I19: Sunil
A20: 14 | B20: iWork - CR | C20: Business Critical | D20: BizDone - Download - User select the desired sheet | E20: Delivered | F20: Milestone 6 | G20: 01-Aug-2026 | H20: 04-Aug-2026 | I20: Karan
A21: 15 | B21: iWork | C21: Business Critical | D21: BizDone - Download - Indian template along with Localization fields | E21: UAT - WIP | F21: Milestone 6 | G21: 01-Aug-2026 | H21: 04-Aug-2026 | I21: Leela
A22: 16 | B22: iWork | C22: Reports | D22: Generic template for all the reports, Bizdone Report, Missing entries from commission statement against policies | E22: Delivered - Deficit | F22: Milestone 5 | G22: 31-Jul-2025 | H22: 05-Aug-2026 | J22: Linked with Reconciliation Management & Commission
A23: 17 | B23: iWork | C23: Operational | D23: Personal Lines Data Integration (DSR and iWork) | E23: Dev - Done | F23: Milestone 6 | G23: 25-Jul-2026 | H23: 05-Aug-2026 | I23: Junaid
A24: 18 | B24: iWork | C24: Business Critical | D24: BizDone - Download - Performance (Offload Excel Generation) - API, Queue, Store in S3 & Download | E24: Delivered | F24: Milestone 6 | G24: 01-Aug-2026 | H24: 05-Aug-2026 | I24: Karan
A25: 19 | B25: iWork | C25: Business Critical | D25: BizDone - Applied filters in the Downloaded file in Sheet-1 | E25: Delivered | F25: Milestone 6 | G25: 01-Aug-2026 | H25: 05-Aug-2026 | I25: Sunil
A26: 20 | B26: IBP/iWork - CR | C26: IBP - Enrolment Journey | D26: Using Policy Config, add only dependent & complete the enrolment. - Hide SI, Premiums, Rate Calculator - Endorsement - Employee only should support SI & Parameter | E26: Yet to start | F26: Milestone 6 | G26: 03-Aug-2026 | H26: 05-Aug-2026 | I26: Jagadeesh
A27: 21 | B27: iWork | C27: Business Critical | D27: The owner selection process remains highly user-unfriendly, with a very small expand ('>') button, incomplete visibility of names, and insufficient hierarchy indentation. | E27: DEV - WIP | F27: Milestone 6 | G27: 18-Jul-2026 | H27: 06-Aug-2026 | I27: Raju
A28: 22 | B28: iWork | C28: Business Critical | D28: BizDone - Old & Enhance Screens - For now both will be live(Metrics) | E28: Dev - WIP | F28: Milestone 6 | G28: 01-Aug-2026 | H28: 06-Aug-2026 | I28: Karan
A29: 23 | B29: iWork | C29: Business Critical | D29: Dashboard & BizDone: Centralised code or utility to fetch the KPIs data for re-usability | E29: Dev - WIP | F29: Milestone 6 | G29: 01-Aug-2026 | H29: 06-Aug-2026 | I29: Sunil
A30: 24 | B30: iWork | C30: Operational | D30: Job - Dashboard - Review, Enhance and document | E30: Delivered | F30: Milestone 6 | G30: 01-Aug-2026 | H30: 06-Aug-2026 | I30: Sunil | J30: Flag based development / remove job post approval
A31: 25 | B31: iWork | C31: Operational | D31: Demo Env. - Stop all the Job; Make sure emails & SMS are working as expected | E31: Yet to start | F31: Milestone 6 | G31: 01-Aug-2026 | H31: 06-Aug-2026 | I31: Tharun
A32: 26 | B32: iWork | C32: Business Critical | D32: PROD Bug: Dashboard vs RO page - When login user applied the same filters in Dashboard and the same in RO then counts are NO matching - Example Milind in email | E32: DEV - WIP | F32: Milestone 6 | G32: 06-Aug-2026 | H32: 06-Aug-2026 | I32: Karan
A33: 27 | B33: IBP/iWork | C33: Country Handling {Data Source Mgmt} | D33: 23-May: Respective org. data should reside in the same country. | E33: Yet to start | F33: Milestone 4 | G33: 10-Jun-2025 | H33: 07-Aug-2026 | I33: Rama
A34: 28 | B34: iWork | C34: Teams Integration | D34: MS Teams - Meetings & Tasks integration into iWork Bi-Directional | E34: Yet to start | F34: Milestone 4 | G34: 10-Jun-2025 | H34: 07-Aug-2026 | I34: Rama
A35: 29 | B35: IBP/iWork | C35: Wellness IIRM View | D35: IIRM View of Wellness usage by Corporates/Employees (IBP Admin) | E35: Yet to start | F35: Milestone 5 | G35: 31-Jul-2025 | H35: 07-Aug-2026 | I35: Manjusha | J35: Wellness HR View
A36: 30 | B36: iWork | C36: Reconciliation Management Upload Commission Statement | D36: Upload commission statement, reconcile against issued policies; Upload invoice & reconcile against commission stmt; Upload invoice statuses and reconcile paid/unpaid Premium vs Brokerage Invoice vs Brokerage Collected; Data from Finops | E36: Yet to start | F36: Milestone 5 | G36: 31-Jul-2025 | H36: 07-Aug-2026 | J36: Need inputs from Kapil
A37: 31 | B37: iWork | C37: Insurer Integration Mgmt | D37: Can be used as a part of External API Intergration | E37: Yet to start | F37: Milestone 5 | G37: 31-Jul-2025 | H37: 07-Aug-2026
A38: 32 | B38: iWork | C38: Reconciliation Mgmt | E38: Yet to start | F38: Milestone 5 | G38: 31-Jul-2025 | H38: 07-Aug-2026
A39: 33 | B39: iWork - CR | C39: Policy Configuration | D39: Enable Parent-Child Policy Mapping for GMC and Sub-Plans (Parental, OPD, Dental, Others) - How to view config from Base to Child Policiy? - How to handle endorsement & Claims? (Entire Service Flow) | E39: Yet to start | F39: Milestone 6 | G39: 01-May-2026 | H39: 07-Aug-2026 | I39: Sunil
A40: 34 | B40: iWork - CR | C40: Opportunity - Validate uploaded documents | D40: Using AI - Extract the documents, validate, populate the data in the Opty. flow (Ex. KDM Meeting, Policy Hard Copy, & Others) | E40: Yet to start | F40: Milestone 6 | G40: 08-May-2026 | H40: 07-Aug-2026 | J40: Need some information about the document rules that defines the idenity of it
A41: 35 | B41: iWork - CR | C41: SSO - MS AD Account | D41: iWork - SSO with Microsoft AD (POC) | E41: DEV - Done | F41: Milestone 6 | G41: 05-Jun-2026 | H41: 07-Aug-2026 | I41: Rama | J41: 10-Jun-2026: POC Demo to Venu completed
A42: 36 | B42: IBP/iWork - CR | C42: IIRM-10667 | D42: iWork - Knowledge Central Re-Design | E42: Yet to start | F42: Milestone 6 | G42: 15-Jun-2026 | H42: 07-Aug-2026
...

Sheet 📅 10-Aug
A1: WEEK OF 10 Aug 2026 → 16 Aug 2026 — 14 items · 0 delivered · 14 pending · NEXT WEEK
A3: ⚠️ Static snapshot. To update: edit STATUS/ETA in the source sheet, then re-run build_iirm_summary.py
A5: # | B5: Module | C5: Feature | D5: Functionality | E5: Status | F5: Milestone | G5: Requested | H5: ETA | I5: Resource | J5: Remarks
A6: iWork (Backlog & CRs) · 13 items · 0 delivered · 13 pending
A7: 1 | B7: iWork | C7: Business Critical | D7: BizDone - Performance - Query Fine Tuning | E7: Dev - WIP | F7: Milestone 6 | G7: 01-Aug-2026 | H7: 10-Aug-2026 | I7: Karan
A8: 2 | B8: iWork | C8: Business Critical | D8: BizDone & other filters - Multi-select for Vertical & Branch | E8: Dev - WIP | F8: Milestone 6 | G8: 18-Jul-2026 | H8: 11-Aug-2026 | I8: Sunil
A9: 3 | B9: iWork | C9: Operational | D9: Demo Env. - Record the application/Infrastruction/DevOps situation when application is in Zero state | E9: Yet to start | F9: Milestone 6 | G9: 01-Aug-2026 | H9: 11-Aug-2026 | I9: Tharun / Jagadeesh
A10: 4 | B10: iWork | C10: Operational | D10: PROD & Demo Env.: Database - Partitioning | E10: Yet to start | F10: Milestone 6 | G10: 01-Aug-2026 | H10: 11-Aug-2026 | I10: Abhilash
A11: 5 | B11: iWork | C11: Orphan Records | D11: Orphan - Companies - Identifying the records, Validate & Delete | E11: Yet to start | F11: Milestone 6 | G11: 06-Aug-2026 | H11: 11-Aug-2026 | I11: Gopal / Rama
A12: 6 | B12: iWork | C12: Orphan Records | D12: Orphan - Oppotunities - Identifying the records, Validate & Delete | E12: Yet to start | F12: Milestone 6 | G12: 06-Aug-2026 | H12: 11-Aug-2026 | I12: Gopal / Rama
A13: 7 | B13: iWork | C13: Orphan Records | D13: Orphan - Policies - Identifying the records, Validate & Delete | E13: Yet to start | F13: Milestone 6 | G13: 06-Aug-2026 | H13: 11-Aug-2026 | I13: Gopal / Rama
A14: 8 | B14: iWork | C14: Business Critical | D14: Dashboard - Performance - Query Fine Tuning | E14: Yet to start | F14: Milestone 6 | G14: 01-Aug-2026 | H14: 12-Aug-2026 | I14: Sunil
A15: 9 | B15: iWork - CR | C15: Business Critical | D15: BizDone - Download - Reduce the file size (Ex. Excel binary or others) | E15: Yet to start | F15: Milestone 6 | G15: 01-Aug-2026 | H15: 12-Aug-2026 | I15: Karan
A16: 10 | B16: iWork | C16: Operational | D16: Job - Expiry Opportunity - Review, Enhance and document | E16: Yet to start | F16: Milestone 6 | G16: 01-Aug-2026 | H16: 12-Aug-2026 | I16: Karan
A17: 11 | B17: iWork | C17: Operational | D17: PROD & Demo Env.: Database - Indexing | E17: Yet to start | F17: Milestone 6 | G17: 01-Aug-2026 | H17: 13-Aug-2026 | I17: Abhilash
A18: 12 | B18: iWork | C18: Operational | D18: Job - RO Creation - Review, Enhance and document | E18: Yet to start | F18: Milestone 6 | G18: 01-Aug-2026 | H18: 13-Aug-2026 | I18: Karan | J18: 6-Aug: Surya sir want to discuss thing
A19: 13 | B19: iWork | C19: Operational | D19: PROD & Demo Env.: Database - SQL Functions for all the reports | E19: Yet to start | F19: Milestone 6 | G19: 01-Aug-2026 | H19: 14-Aug-2026 | I19: Abhilash
A20: Other / Unassigned · 1 item · 0 delivered · 1 pending
A21: 14 | B21: iWork/IBP | C21: Operational | D21: Notification Mgmt - Turn on, Turn off, History, Approval, template changes | E21: Yet to start | F21: Milestone 6 | G21: 01-Aug-2026 | H21: 11-Aug-2026 | I21: Karan

Sheet 📅 Upcoming
A1: UPCOMING (ETA beyond 10 Aug week) — 0 items · 0 delivered · 0 pending
A3: ⚠️ Static snapshot. To update: edit STATUS/ETA in the source sheet, then re-run build_iirm_summary.py
A5: # | B5: Module | C5: Feature | D5: Functionality | E5: Status | F5: Milestone | G5: Requested | H5: ETA | I5: Resource | J5: Remarks

Sheet Unplanned (no ETA)
A1: UNPLANNED — PENDING, NO ETA · 36 items
A3: Pending items with no ETA yet. Assign an ETA in the source sheet to move an item into its week. Static snapshot — re-run to refresh.
A5: # | B5: Module | C5: Feature | D5: Functionality | E5: Status | F5: Milestone | G5: Requested | H5: ETA | I5: Resource | J5: Remarks
A6: iWork (Backlog & CRs) · 28 items
A7: 1 | B7: IBP/iWork | C7: IBP Landing Page - Customization | D7: Landing Page customization in Admin side of IBP - available in iWork (per Corporate) | E7: Yet to start | F7: Milestone 5 | G7: 31-Jul-2025
A8: 2 | B8: iWork | C8: Maintenance | D8: iWork - Reports - View Dump for each download for comparision | E8: Yet to start | F8: Milestone 6 | G8: 20-Apr-2026 | I8: Gopal
A9: 3 | B9: iWork - CR | C9: Operational | D9: Policy Config - Premium Rater Table | E9: Yet to start | F9: Milestone 6 | G9: 21-Apr-2026 | I9: Jagadeesh
A10: 4 | B10: iWork | C10: Operational | D10: Export to excel - iWork all the results table; Download is on Previlage | E10: Yet to start | F10: Milestone 6 | G10: 15-Jun-2026
A11: 5 | B11: IBP/iWork | C11: Operational | D11: IBP - Raise Ticket: Edit the ticket and update the status by the Lead CRM & System Admin Same funtionality should be there in iWork for internal purpose. Should send email notification when there are changes to status | E11: Yet to start | F11: Milestone 6 | G11: 01-Jul-2026 | I11: Manjusha
A12: 6 | B12: IBP/iWork | C12: Operational | D12: IBP - Emails: Dual approval/confirmation - Before sending to Employees. 1. 2 levels in iWork 2. CRM will submit & HR will approve in Risk Watch | E12: Yet to start | F12: Milestone 6 | G12: 14-Jul-2026
A13: 7 | B13: iWork | C13: Maintenance | D13: In any of the screen, we have to provide an info icon where it will help the users how critical fields in that screen are derieved or got populated | E13: Yet to start | F13: Milestone 6 | G13: 17-Jul-2026
A14: 8 | B14: iWork | C14: Operational | D14: CMS - Policy Level - Component Notes from Strapi | E14: Yet to start | F14: Milestone 6 | G14: 31-Jul-2026 | J14: Ex. TL - Parental 2-years Lock-in; SI may vary
A15: 9 | B15: iWork | C15: Maintenance | D15: Convert Policy from Active to Generated | E15: Yet to start | F15: Milestone 6 | G15: 01-Aug-2026
A16: 10 | B16: iWork | C16: Maintenance | D16: Delete - Policy Configuration | E16: Yet to start | F16: Milestone 6 | G16: 01-Aug-2026
A17: 11 | B17: iWork | C17: Maintenance | D17: PROD: Health Check of the Application, Alert notification & Triage the situation | E17: Yet to start | F17: Milestone 6 | G17: 01-Aug-2026
A18: 12 | B18: iWork | C18: Maintenance | D18: Delete - Inception/Endorsement Data | E18: Yet to start | F18: Milestone 6 | G18: 01-Aug-2026
A19: 13 | B19: iWork | C19: Maintenance | D19: Employee Mgmt - Create, Update, Delete - Validate and document | E19: Yet to start | F19: Milestone 6 | G19: 01-Aug-2026
A20: 14 | B20: iWork | C20: Maintenance | D20: Hierarchy Mgmt - View & Update - Report & Visual Chart | E20: Yet to start | F20: Milestone 6 | G20: 01-Aug-2026
A21: 15 | B21: iWork | C21: Maintenance | D21: iWork - Reports - Use BizDone framework | E21: Yet to start | F21: Milestone 6 | G21: 01-Aug-2026
A22: 16 | B22: iWork | C22: Operational | D22: PROD Bug: SES - Notifications - Check what is the configuration. (Scenario: For the very first time Email or SMS is taking time then rest are instant) | E22: Yet to start | F22: Milestone 6 | G22: 01-Aug-2026
A23: 17 | B23: iWork | C23: Operational | D23: Infra - Season based bumping (Example: When policies are expiring, need to bump the infra/DB because load will be more). Identify the data and plan this acitivity. | E23: Yet to start | F23: Milestone 6 | G23: 01-Aug-2026
A24: 18 | B24: iWork | C24: Operational | D24: Optimal allocate the memory/infra size based on the service operational usage rather than generic size for all | E24: Yet to start | F24: Milestone 6 | G24: 01-Aug-2026
A25: 19 | B25: iWork | C25: Operational | D25: Split Service - Risk Watch because it should run on it own and NOT impact other iWork or IBP services | E25: Yet to start | F25: Milestone 6 | G25: 01-Aug-2026
A26: 20 | B26: iWork | C26: Operational | D26: Split Service - Identify service areas because either iWork or IBP utilization should not impact other services | E26: Yet to start | F26: Milestone 6 | G26: 01-Aug-2026
A27: 21 | B27: iWork | C27: Operational | D27: Reports - iWork - Validate, enhance, and document | E27: Yet to start | F27: Milestone 6 | G27: 01-Aug-2026
A28: 22 | B28: iWork | C28: Operational | D28: Automation process for Data Load (Gopal & Rama's Task) | E28: Yet to start | F28: Milestone 6 | G28: 01-Aug-2026 | I28: Rama
A29: 23 | B29: iWork | C29: Operational | D29: Export - IBP-Risk Watch - All the results/Widget must be downloadable based onn Previlage | E29: Yet to start | F29: Milestone 6 | G29: 01-Aug-2026
A30: 24 | B30: iWork | C30: Operational | D30: Email Notifications - Policy Renewals - CRM users & Insurer Contact | E30: Yet to start | F30: Milestone 6 | G30: 01-Aug-2026
A31: 25 | B31: iWork | C31: Operational | D31: Email Notifications - Opty. Lost/ Policy Renewals/ Instalments - CRM users | E31: Yet to start | F31: Milestone 6 | G31: 01-Aug-2026
A32: 26 | B32: iWork | C32: Operational | D32: Add/Update - Address & Contact - Across Application | E32: Yet to start | F32: Milestone 6 | G32: 01-Aug-2026
A33: 27 | B33: iWork | C33: Orphan Records | D33: Admin Screen - to view and delete the records | E33: Yet to start | F33: Milestone 6 | G33: 06-Aug-2026
A34: 28 | B34: iWork | C34: S3 Document Mgmt. | D34: Admin Screen to Delete or Archive files in S3 Need a process to handle it | E34: Yet to start | F34: Milestone 6 | G34: 06-Aug-2026
A35: IBP (Backlog & CRs) · 4 items
A36: 29 | B36: IBP | C36: Premium Range Calculator | D36: Calculate insurance premium range. Calculate the IDV of various assets | E36: Yet to start | F36: Milestone 5 | G36: 31-Jul-2025 | I36: Ravi | J36: Retail Business
A37: 30 | B37: IBP | C37: Multiple 3rd Party Service Mgmt | D37: Elderly Services, Dental Services etc. 3rd Party integrations. Multiple providers 3 such services are in scope at this stage {Redhealth, MyDental, AkinCare} | E37: Yet to start | F37: Milestone 5 | G37: 31-Jul-2025 | J37: Retail Business
A38: 31 | B38: IBP | C38: Claims Mgmt | D38: Part-2: Personal Policy based claim mgmt, Tracking status, Document Mgmt related to claims | E38: Yet to start | F38: Milestone 5 | G38: 31-Jul-2025 | J38: Retail Business
A39: 32 | B39: IBP | C39: IBP - Enrolment Journey | D39: When user save & exit is considered as Enrolled | E39: Yet to start | F39: Milestone 6 | G39: 21-Jul-2026 | I39: Abhilash | J39: Jayakar reported
A40: Other / Unassigned · 4 items
A41: 33 | B41: iWork/IBP | C41: Maintenance | D41: IBP - Go-Live: Check-list document & SOP | E41: Yet to start | F41: Milestone 6 | G41: 20-Apr-2026 | I41: Nithin
A42: 34 | B42: iWork/IBP | C42: Business Critical | D42: iWork/IBP - Claim Process - Intimation & Submission (Different Flows) | E42: Yet to start | F42: Milestone 6 | G42: 01-Aug-2026
...

Sheet VRK Feedbacks
A1: VRK — PROD FEEDBACK TRACKER · 80 items · 67 delivered · 13 pending
A3: All 'VRK - PROD Feedback:' items, broken up by week (status then ETA within a week). Excluded from the other views. Static snapshot.
A5: # | B5: Module | C5: Feature | D5: Functionality | E5: Status | F5: Milestone | G5: Requested | H5: ETA | I5: Resource | J5: Remarks
A6: 📅 WEEK OF 08 Jun → 14 Jun 2026 · PAST · 27 items
A7: 1 | B7: iWork | C7: VRK - PROD Feedback: 5-Jun-2026 | D7: Manage SO - Update the date filters to "SO Expiry Date" | E7: Delivered | F7: Milestone 6 | G7: 05-Jun-2026 | H7: 08-Jun-2026
A8: 2 | B8: iWork | C8: VRK - PROD Feedback: 8-Jun-2026 | D8: Critical: SO expiry logic and date validation should allow within 365 days at the time so creation. | E8: Delivered | F8: Milestone 6 | G8: 08-Jun-2026 | H8: 08-Jun-2026
A9: 3 | B9: iWork | C9: VRK - PROD Feedback: 8-Jun-2026 | D9: Dashboard - Save View button to be moved to Run button --> Move the Save View button beside Reset | E9: Delivered | F9: Milestone 6 | G9: 08-Jun-2026 | H9: 08-Jun-2026
A10: 4 | B10: iWork | C10: VRK - PROD Feedback: 8-Jun-2026 | D10: Dont display CD management in menu link - move under Admin | E10: Delivered | F10: Milestone 6 | G10: 08-Jun-2026 | H10: 08-Jun-2026
A11: 5 | B11: iWork | C11: VRK - PROD Feedback: 8-Jun-2026 | D11: filter out support services from the dashboard | E11: Delivered | F11: Milestone 6 | G11: 08-Jun-2026 | H11: 08-Jun-2026
A12: 6 | B12: iWork | C12: VRK - PROD Feedback: 8-Jun-2026 | D12: funnels - hide Overall conversion values | E12: Delivered | F12: Milestone 6 | G12: 08-Jun-2026 | H12: 08-Jun-2026
A13: 7 | B13: iWork | C13: VRK - PROD Feedback: 8-Jun-2026 | D13: In My RO, "BD planning" title should change to "Renewal Planning" for RO | E13: Delivered | F13: Milestone 6 | G13: 08-Jun-2026 | H13: 08-Jun-2026
A14: 8 | B14: iWork | C14: VRK - PROD Feedback: 8-Jun-2026 | D14: Manage TPA/BRoker/Insurer should be moved to Admin Module | E14: Delivered | F14: Milestone 6 | G14: 08-Jun-2026 | H14: 08-Jun-2026
A15: 9 | B15: iWork | C15: VRK - PROD Feedback: 8-Jun-2026 | D15: My Follow Up - hide "All" option - RO should be default | E15: Delivered | F15: Milestone 6 | G15: 08-Jun-2026 | H15: 08-Jun-2026
A16: 10 | B16: iWork | C16: VRK - PROD Feedback: 8-Jun-2026 | D16: Policy Expiry Timeline by SBU - change to "Renewal Schedule by SBU" and move under renewal funnel | E16: Delivered | F16: Milestone 6 | G16: 08-Jun-2026 | H16: 08-Jun-2026
A17: 11 | B17: iWork | C17: VRK - PROD Feedback: 8-Jun-2026 | D17: Ribbon level reports link should be hidden --> Hide "Reports" on the header menu. And also move the "Utilization report" to Admin Module. | E17: Delivered | F17: Milestone 6 | G17: 08-Jun-2026 | H17: 08-Jun-2026
A18: 12 | B18: iWork | C18: VRK - PROD Feedback: 8-Jun-2026 IIRM-10589 | D18: My client portfolio - Period (Company created) change to - Period (policies created) --- Show the same filters of Manage Policy | E18: Delivered | F18: Milestone 6 | G18: 08-Jun-2026 | H18: 09-Jun-2026 | I18: Karan
A19: 13 | B19: iWork | C19: VRK - PROD Feedback: 8-Jun-2026 | D19: isg roles: manage quotes screen should display the opportunities which are related to ISG only. | E19: Delivered | F19: Milestone 6 | G19: 08-Jun-2026 | H19: 09-Jun-2026
A20: 14 | B20: iWork | C20: VRK - PROD Feedback: 9-Jun-2026 | D20: BD/ISG planning dates should be empty and mandatory - should be mandatory to start the journey. | E20: Delivered | F20: Milestone 6 | G20: 09-Jun-2026 | H20: 09-Jun-2026
A21: 15 | B21: iWork | C21: VRK - PROD Feedback: 9-Jun-2026 | D21: In "Manage Quotes"/"Manage SO" page, a link should be provided on the activity name, it should get redirected to respective activity stage. | E21: Delivered | F21: Milestone 6 | G21: 09-Jun-2026 | H21: 09-Jun-2026 | I21: Pushyami
A22: 16 | B22: iWork | C22: VRK - PROD Feedback: 9-Jun-2026 | D22: Issue in Bizdone search results - Company name not visible | E22: Delivered | F22: Milestone 6 | G22: 09-Jun-2026 | H22: 09-Jun-2026 | I22: Pushyami
A23: 17 | B23: iWork | C23: VRK - PROD Feedback: 9-Jun-2026 IIRM-10588 | D23: Rename "My SO" to "Manage SO" in the sales portfolio. | E23: Delivered | F23: Milestone 6 | G23: 09-Jun-2026 | H23: 09-Jun-2026 | I23: Pushyami
A24: 18 | B24: iWork | C24: VRK - PROD Feedback: 9-Jun-2026 | D24: SO creation process: SO Expiry field title should be changed to "Opportunity/Existing Policy Expiry" - label to be changed. Nithin --> Also, change in SO details page as well | E24: Delivered | F24: Milestone 6 | G24: 09-Jun-2026 | H24: 09-Jun-2026 | I24: Pushyami
A25: 19 | B25: iWork | C25: VRK - PROD Feedback: 8-Jun-2026 | D25: My RO clicked should not get highlighted to My SO menu link. | E25: Delivered | F25: Milestone 6 | G25: 08-Jun-2026 | H25: 10-Jun-2026
A26: 20 | B26: iWork | C26: VRK - PROD Feedback: 9-Jun-2026 | D26: My followup section in the dashboard - should display default Activity names and show the values even there are zeros for each activity. | E26: Delivered | F26: Milestone 6 | G26: 09-Jun-2026 | H26: 10-Jun-2026 | I26: Prathiphala
A27: 21 | B27: iWork | C27: VRK - PROD Feedback: 9-Jun-2026 | D27: Opportunity lost logic:- if placement slip is not crossed, instantly mark the opportunity as "Lost" based on Opty. Expiry date | E27: Delivered | F27: Milestone 6 | G27: 09-Jun-2026 | H27: 10-Jun-2026 | I27: Jagadeesh
A28: 22 | B28: iWork | C28: VRK - PROD Feedback: 9-Jun-2026 | D28: Opportunity lost logic:- if the activity crossed "Placement Slip", premium calculation and crossed 5 days, then mark the opportunity as "Lost" based on Opty. expiry date+5 days | E28: Delivered | F28: Milestone 6 | G28: 09-Jun-2026 | H28: 10-Jun-2026 | I28: Jagadeesh
A29: 23 | B29: iWork | C29: VRK - PROD Feedback: 8-Jun-2026 IIRM-10589 | D29: My client portfolio - list of all companies for Active policies only | E29: Delivered | F29: Milestone 6 | G29: 08-Jun-2026 | H29: 12-Jun-2026 | I29: Karan
A30: 24 | B30: iWork | C30: VRK - PROD Feedback: 8-Jun-2026 | D30: Policy Expiry Timeline by SBU - when clicked, redirect to RO screen with the counts. | E30: Delivered | F30: Milestone 6 | G30: 08-Jun-2026 | H30: 12-Jun-2026
A31: 25 | B31: iWork | C31: VRK - PROD Feedback: 9-Jun-2026 | D31: BDR results list should display the link of policy ID and Opty ID. | E31: Delivered | F31: Milestone 6 | G31: 09-Jun-2026 | H31: 12-Jun-2026 | I31: Prathiphala
A32: 26 | B32: iWork | C32: VRK - PROD Feedback: 8-Jun-2026 | D32: My client portfolio: List of Companies should be displayed for which there are active RO's. The premium and brokerage should be displayed as per RO cards. --> Que: Yesterday it was asked to get the data related to Active Policies???? | E32: Not a bug | F32: Milestone 6 | G32: 08-Jun-2026 | H32: 08-Jun-2026 | J32: 10-Jun: As per Surya/Kapil Sir. It's Active Policies only
A33: 27 | B33: iWork | C33: VRK - PROD Feedback: 8-Jun-2026 | D33: my followup should be added into my actionalables with default display instead of "All" tab. | E33: Not a bug | F33: Milestone 6 | G33: 08-Jun-2026 | H33: 08-Jun-2026
A34: 📅 WEEK OF 15 Jun → 21 Jun 2026 · PAST · 8 items
A35: 28 | B35: iWork | C35: VRK - PROD Feedback: 9-Jun-2026 IIRM-10589 | D35: All SO and RO items should be displayed order by Expiry Date (ascending) in the same page once "Manage Quotes" is clicked by the user. | E35: Delivered | F35: Milestone 6 | G35: 09-Jun-2026 | H35: 15-Jun-2026 | I35: Karan
A36: 29 | B36: iWork | C36: VRK - PROD Feedback: 9-Jun-2026 IIRM-10589 | D36: ISG users should be able to view ISG activities only and BD related activities should be collapsable and hidden; accordingly manage the breadcrums. Similarly, vice versa for BD users. | E36: Delivered | F36: Milestone 6 | G36: 09-Jun-2026 | H36: 15-Jun-2026 | I36: Karan
A37: 30 | B37: iWork | C37: VRK - PROD Feedback: 9-Jun-2026 IIRM-10589 | D37: Manage Quote RO and Manager Quote SO should be clubbed to "Manage Quotes" link for ISG team only. --> 10-Jun: Surya -> Show the data only when opty. is in ISG Activity. | E37: Delivered | F37: Milestone 6 | G37: 09-Jun-2026 | H37: 15-Jun-2026 | I37: Karan
A38: 31 | B38: iWork | C38: VRK - PROD Feedback: 9-Jun-2026 IIRM-10589 | D38: My client portfolio: There must be a provision of "Past company" view in the Client Portfolio. | E38: Delivered | F38: Milestone 6 | G38: 09-Jun-2026 | H38: 15-Jun-2026
A39: 32 | B39: iWork | C39: VRK - PROD Feedback: 9-Jun-2026 IIRM-10589 | D39: Nithin -> Add the filters required to handle both SO & RO in "Manage Quotes" | E39: Delivered | F39: Milestone 6 | G39: 09-Jun-2026 | H39: 15-Jun-2026 | I39: Karan
A40: 33 | B40: iWork | C40: VRK - PROD Feedback: 9-Jun-2026 IIRM-10589 | D40: Hide "My RO" from the Sales portfolio. Add in the "My Client Portfolio" | E40: Delivered | F40: Milestone 6 | G40: 09-Jun-2026 | H40: 16-Jun-2026
