Workbook

Sheet iWork,IBP & Framework_SOW Items
A1: Area | B1: Feature | C1: Functionality | D1: Module | E1: Phase | F1: Status | G1: Remarks | H1: Need Design Approval | I1: ETA | J1: Resource
A2: FRAMEWORK: Frontend | B2: Project setup | C2: Basic project / Development environment setup | D2: Framework | E2: Milestone 1 | F2: Delivered
A3: FRAMEWORK: Frontend | B3: UI Approach Design System | C3: Building Design System | D3: Framework | E3: Milestone 1 | F3: Delivered
A4: FRAMEWORK: Frontend | B4: Core Infrastructure | C4: Core Infra | D4: Framework | E4: Milestone 1 | F4: Delivered
A5: FRAMEWORK: Frontend | B5: Build UI components | C5: This includes all the UI componnets to compose the application and module definitions: Form, Toast, Filter, Cards, Visualisation, Grid, Menu, Header, Footer, Maps Integration | D5: Framework | E5: Milestone 1 | F5: Delivered
A6: FRAMEWORK: Frontend | B6: UI Approach Style Establishment | C6: UI Style Establishment | D6: Framework | E6: Milestone 1 | F6: Delivered
A7: FRAMEWORK: Frontend | B7: Service Workers Implementation | D7: Framework | E7: Milestone 1 | F7: Delivered
A8: FRAMEWORK: Frontend | B8: Core System | D8: Framework | E8: Milestone 1 | F8: Delivered
A9: FRAMEWORK: Frontend | B9: ACL & RBAC Control Framework | D9: Framework | E9: Milestone 1 | F9: Delivered
A10: FRAMEWORK: Frontend | B10: Micro Frontend Setup | D10: Framework | E10: Milestone 1 | F10: Delivered
A11: FRAMEWORK: Frontend | B11: Landing Page | D11: Framework | E11: Milestone 1 | F11: Delivered
A12: FRAMEWORK: Services - Basic Modules | B12: Access Control Management | D12: Framework | E12: Milestone 1 | F12: Delivered
A13: FRAMEWORK: Services - Larger Modules | B13: Auth Module (Simple Auth) | D13: Framework | E13: Milestone 1 | F13: Delivered
A14: FRAMEWORK: Services - Larger Modules | B14: Micro Service Framework Setup | D14: Framework | E14: Milestone 1 | F14: Delivered
A15: iWORK: Services - Basic Modules | B15: Employee Mgmt | D15: iWork | E15: Milestone 1 | F15: Delivered | G15: User deletion need to be handled | I15: 46185
A16: iWORK: Common Components | B16: Common - Audit Trail Mgmt - Becomes critical in this phase iteself | D16: iWork | E16: Milestone 1 | F16: Delivered
A17: iWORK: Frontend | B17: Add/View/Edit Opportunity | C17: Add Medium size form with 1->N list of Claims; Multiple drop downs Large View with several widgets, Simple Edit | D17: iWork | E17: Milestone 1 | F17: Delivered
A18: iWORK: Frontend | B18: Manage TPA/Insurer | C18: Basic Add, View with edit of basic data, with lists of policies/companies | D18: iWork | E18: Milestone 1 | F18: Delivered
A19: iWORK: Frontend | B19: Core Infra | C19: Infrastructure | D19: iWork | E19: Milestone 1 | F19: Delivered
A20: iWORK: Frontend | B20: Add/View/Edit Company | C20: Large form with basic format based validations, some mandatory fields, multiple addresses, couple of Rich Text Editor fields; Some multi-line fields (e.g., GST), uploads; Duplicate detection on Company name, GST/PAN etc. Simple edit like Add; View is multiple widgets (Contacts, Opportunities, Policies, Claims, SLAs, Document list) | D20: iWork | E20: Milestone 1 | F20: Delivered
A21: iWORK: Frontend | B21: Insurer/TPA Hub | C21: List with Filter/Search | D21: iWork | E21: Milestone 1 | F21: Delivered
A22: iWORK: Frontend | B22: Add/View/Edit Contact | C22: Simple edit like Add Contacts should maintain Company history although only 1 Company active with 1 contact; Medium size form with fields, linked in connect | D22: iWork | E22: Milestone 1 | F22: Delivered
A23: iWORK: Frontend | B23: Company (Prospect) Hub | C23: Top 10/Latest companies, with search/filter, Table of basic attributes with GPS etc. | D23: iWork | E23: Milestone 1 | F23: Delivered
A24: iWORK: Frontend | B24: Contact Hub | C24: Top 10/Latest Contacts, with search/filter, list with basic attributes | D24: iWork | E24: Milestone 1 | F24: Delivered
A25: iWORK: Frontend | B25: Opportunity Hub | C25: Top Opportunities with search/filter, List of opportunities with high level summaries | D25: iWork | E25: Milestone 1 | F25: Delivered
A26: iWORK: Services - Basic Modules | B26: Contact /Company/Insurer/TPA Mgmt | D26: iWork | E26: Milestone 1 | F26: Delivered
A27: iWORK: Services - Basic Modules | B27: Task Mgmt | D27: iWork | E27: Milestone 1 | F27: Delivered
A28: iWORK: Services - Basic Modules | B28: Meeting Mgmt | D28: iWork | E28: Milestone 1 | F28: Delivered
A29: iWORK: Services - Basic Modules | B29: RBAC and ACL setup for Iwork Module | D29: iWork | E29: Milestone 1 | F29: Delivered
A30: iWORK: Services - Basic Modules | B30: Opportunity Mgmt | D30: iWork | E30: Milestone 1 | F30: Delivered
A31: FRAMEWORK: Frontend | B31: Master Data Management | D31: Framework | E31: Milestone 2 | F31: Delivered | I31: 46169
A32: FRAMEWORK: Frontend | B32: User Management | C32: 22-May: Other than iWork employee | D32: Framework | E32: Milestone 2 | F32: Delivered | G32: Pending: User deletion | I32: 46185
A33: FRAMEWORK: Services - Basic Modules | B33: User Management | C33: 22-May: Other than iWork employee | D33: Framework | E33: Milestone 2 | F33: Delivered | G33: Pending: User deletion | I33: 46185
A34: FRAMEWORK: Services - Basic Modules | B34: Notification and Communication Management | C34: 23-May: In-App, Emails, SMS, both or all. Template vs Channel | D34: Framework | E34: Milestone 2 | F34: Delivered - Deficit | G34: Pending: Configuration UI | I34: 46197
A35: FRAMEWORK: Services - Basic Modules | B35: Usage Tracking System (Reports) | C35: 23-May: Handle as a part of Reports | D35: Framework | E35: Milestone 2 | F35: Delivered - Deficit | G35: Pending: IBP usage | I35: 46198
A36: FRAMEWORK: Services - Larger Modules | B36: Data Security Considerations | D36: Framework | E36: Milestone 2 | F36: Delivered | G36: Duplicate of Covers in DPDP items | I36: 46203
A37: FRAMEWORK: Frontend | B37: Visualization framework | C37: Charts and KPIs | D37: Framework | E37: Milestone 2 | F37: Delivered
A38: FRAMEWORK: Frontend | B38: Document Management | C38: Create, Upload, Seach, Download | D38: Framework | E38: Milestone 2 | F38: Delivered
A39: FRAMEWORK: Frontend | B39: Caching of API Data | D39: Framework | E39: Milestone 2 | F39: Delivered
A40: FRAMEWORK: Services - Basic Modules | B40: Audit Data Capturing | D40: Framework | E40: Milestone 2 | F40: Delivered
...

Sheet ① Executive Summary
A1: PROJECT DELIVERY PLAN
A3: iWork · IBP · Framework (IIRM SOW) | Status Overview & Forward Roadmap · As of 21-May-2026
A5: OVERALL COMPLETION | H5: REMAINING WORK
A6: =ROUND(COUNTIF(Helper!$E:$E,"Delivered")/(COUNTIF(Helper!$E:$E,"Delivered")+COUNTIF(Helper!$E:$E,"Pending")),3) -> 0.669 | D6: =COUNTIF(Helper!$E:$E,"Delivered")&" of "&(COUNTIF(Helper!$E:$E,"Delivered")+COUNTIF(Helper!$E:$E,"Pending"))&" scope items delivered" -> 174 of 260 scope items delivered | H6: =COUNTIF(Helper!$E:$E,"Pending") -> 86 | J6: items still to deliver across all modules — broken down by milestone in the Pending Roadmap sheet
A10: STATUS BREAKDOWN (all items)
A11: =COUNTIF(Helper!$D:$D,"Delivered") -> 168 | D11: =COUNTIF(Helper!$D:$D,"Dev Complete") -> 6 | G11: =COUNTIF(Helper!$D:$D,"In Development") -> 8 | J11: =COUNTIF(Helper!$D:$D,"In QA") -> 2
A12: Delivered | D12: Dev Complete | G12: In Development | J12: In QA
A13: =COUNTIF(Helper!$D:$D,"Pre-PROD / UAT") -> 4 | D13: =COUNTIF(Helper!$D:$D,"Not Started") -> 59 | G13: =COUNTIF(Helper!$D:$D,"Partial Delivery") -> 13 | J13: =COUNTIF(Helper!$D:$D,"N/A") -> 0
A14: Pre-PROD / UAT | D14: Not Started | G14: Partial Delivery | J14: N/A
A16: PROGRESS BY MODULE
A17: Module | B17: Type | C17: Total | D17: Delivered | E17: Pending | F17: N/A | G17: % Complete | H17: Progress
A18: iWork (Backlog) | B18: Backlog | C18: =COUNTIF(Helper!$A:$A,"iWork") -> 115 | D18: =COUNTIFS(Helper!$A:$A,"iWork",Helper!$E:$E,"Delivered") -> 94 | E18: =COUNTIFS(Helper!$A:$A,"iWork",Helper!$E:$E,"Pending") -> 21 | F18: =COUNTIFS(Helper!$A:$A,"iWork",Helper!$E:$E,"N/A") -> 0 | G18: =IFERROR(D18/(D18+E18),0) -> 0.8173913 | H18: =G18 -> 0.8173913
A19: iWork (Change Requests) | B19: Change Request | C19: =COUNTIF(Helper!$A:$A,"iWork - CR") -> 8 | D19: =COUNTIFS(Helper!$A:$A,"iWork - CR",Helper!$E:$E,"Delivered") -> 3 | E19: =COUNTIFS(Helper!$A:$A,"iWork - CR",Helper!$E:$E,"Pending") -> 5 | F19: =COUNTIFS(Helper!$A:$A,"iWork - CR",Helper!$E:$E,"N/A") -> 0 | G19: =IFERROR(D19/(D19+E19),0) -> 0.375 | H19: =G19 -> 0.375
A20: IBP (Backlog) | B20: Backlog | C20: =COUNTIF(Helper!$A:$A,"IBP") -> 62 | D20: =COUNTIFS(Helper!$A:$A,"IBP",Helper!$E:$E,"Delivered") -> 32 | E20: =COUNTIFS(Helper!$A:$A,"IBP",Helper!$E:$E,"Pending") -> 30 | F20: =COUNTIFS(Helper!$A:$A,"IBP",Helper!$E:$E,"N/A") -> 0 | G20: =IFERROR(D20/(D20+E20),0) -> 0.51612903 | H20: =G20 -> 0.51612903
A21: IBP (Change Requests) | B21: Change Request | C21: =COUNTIF(Helper!$A:$A,"IBP - CR") -> 1 | D21: =COUNTIFS(Helper!$A:$A,"IBP - CR",Helper!$E:$E,"Delivered") -> 0 | E21: =COUNTIFS(Helper!$A:$A,"IBP - CR",Helper!$E:$E,"Pending") -> 1 | F21: =COUNTIFS(Helper!$A:$A,"IBP - CR",Helper!$E:$E,"N/A") -> 0 | G21: =IFERROR(D21/(D21+E21),0) -> 0 | H21: =G21 -> 0
A22: IBP / iWork (Shared) | B22: Backlog | C22: =COUNTIF(Helper!$A:$A,"IBP/iWork") -> 18 | D22: =COUNTIFS(Helper!$A:$A,"IBP/iWork",Helper!$E:$E,"Delivered") -> 10 | E22: =COUNTIFS(Helper!$A:$A,"IBP/iWork",Helper!$E:$E,"Pending") -> 8 | F22: =COUNTIFS(Helper!$A:$A,"IBP/iWork",Helper!$E:$E,"N/A") -> 0 | G22: =IFERROR(D22/(D22+E22),0) -> 0.55555556 | H22: =G22 -> 0.55555556
A23: Framework | B23: Backlog | C23: =COUNTIF(Helper!$A:$A,"Framework") -> 34 | D23: =COUNTIFS(Helper!$A:$A,"Framework",Helper!$E:$E,"Delivered") -> 28 | E23: =COUNTIFS(Helper!$A:$A,"Framework",Helper!$E:$E,"Pending") -> 6 | F23: =COUNTIFS(Helper!$A:$A,"Framework",Helper!$E:$E,"N/A") -> 0 | G23: =IFERROR(D23/(D23+E23),0) -> 0.82352941 | H23: =G23 -> 0.82352941
A24: DPDP | B24: Backlog | C24: =COUNTIF(Helper!$A:$A,"DPDP") -> 19 | D24: =COUNTIFS(Helper!$A:$A,"DPDP",Helper!$E:$E,"Delivered") -> 5 | E24: =COUNTIFS(Helper!$A:$A,"DPDP",Helper!$E:$E,"Pending") -> 14 | F24: =COUNTIFS(Helper!$A:$A,"DPDP",Helper!$E:$E,"N/A") -> 0 | G24: =IFERROR(D24/(D24+E24),0) -> 0.26315789 | H24: =G24 -> 0.26315789
A25: NFR | B25: Backlog | C25: =COUNTIF(Helper!$A:$A,"NFR") -> 3 | D25: =COUNTIFS(Helper!$A:$A,"NFR",Helper!$E:$E,"Delivered") -> 2 | E25: =COUNTIFS(Helper!$A:$A,"NFR",Helper!$E:$E,"Pending") -> 1 | F25: =COUNTIFS(Helper!$A:$A,"NFR",Helper!$E:$E,"N/A") -> 0 | G25: =IFERROR(D25/(D25+E25),0) -> 0.66666667 | H25: =G25 -> 0.66666667
A26: TOTAL | B26: All | C26: =COUNTA(Helper!$A$2:$A$5000) -> 260 | D26: =COUNTIF(Helper!$E:$E,"Delivered") -> 174 | E26: =COUNTIF(Helper!$E:$E,"Pending") -> 86 | F26: =COUNTIF(Helper!$E:$E,"N/A") -> 0 | G26: =IFERROR(D26/(D26+E26),0) -> 0.66923077 | H26: =G26 -> 0.66923077
A28: % Complete = Delivered ÷ (Delivered + Pending). N/A items (duplicates) are excluded. All figures update live from the 'iWork,IBP & Framework_SOW Items' sheet.

Sheet 📋 iWork
A1: IWORK (BACKLOG) — PENDING WEEKLY PLAN
A3: ⚠️ This sheet is a static snapshot. To update: edit STATUS in the source sheet, then re-run build_iirm_summary.py
A5: # | B5: Feature | C5: Functionality | D5: Status | E5: Milestone | F5: ETA | G5: Resource | H5: Remarks
A6: 📅 08 Jun 2026 → 14 Jun 2026 · 1 item
A7: 1 | B7: VRK - PROD Feedback: 9-Jun-2026 | C7: All Stage/Activity-wise wherever Document upload option is there, should be a mandatory | D7: Yet to start | E7: Milestone 6 | F7: 12-Jun-2026 | G7: Karan
A8: 📅 15 Jun 2026 → 21 Jun 2026 · 1 item
A9: 1 | B9: VRK - PROD Feedback: 9-Jun-2026 | C9: Dual approval mechanism - current logic and recommendation to enable as per the current CRM hierarchy | D9: Yet to start | E9: Milestone 6 | F9: 16-Jun-2026
A10: 📅 22 Jun 2026 → 28 Jun 2026 · 13 items
A11: 1 | B11: IIRM-10587 | C11: Add new fields - Business Month & Date of Business - Capture in Opty. & Flow to Policy and add filters in BizDone --> Refer to Madhav email "Business Month Requirement" | D11: Delivered - Deficit | E11: Milestone 6 | F11: 22-Jun-2026 | G11: Pushyami | H11: Pending: Additional filters
A12: 2 | B12: Dashboard - FinOps Data | C12: Premium vs Brokerage Invoice vs Brokerage Collected; Data from Finops | D12: Yet to start | E12: Milestone 4 | F12: 22-Jun-2026 | H12: Duplicate of reconcilation
A13: 3 | B13: VRK - PROD Feedback: 8-Jun-2026 | C13: funnels - alignment graph issues with grid; | D13: Yet to start | E13: Milestone 6 | F13: 22-Jun-2026
A14: 4 | B14: VRK - PROD Feedback: 8-Jun-2026 | C14: Policy Hard copy receipt stage - When User uploads the Policy copy, system should capture the policy level elements like Ins Pol No., Dates, Premium amounts, etc and validate with the policy record saved. - Need discussion for more details to use the deviation and approval process to modify the values as per deviation from Policy Hard copy. | D14: Yet to start | E14: Milestone 6 | F14: 22-Jun-2026 | G14: Karan
A15: 5 | B15: MIR Entry Mgmt | C15: Entry Form, Print to Document, List of Earlier MIRs, Search on MIRs | D15: Yet to start | E15: Milestone 3 | F15: 24-Jun-2026 | G15: Pushyami
A16: 6 | B16: MIR Entry Mgmt | C16: Module to manage MIR {Monthly Infomatiom Report} | D16: Yet to start | E16: Milestone 3 | F16: 24-Jun-2026 | G16: Pushyami
A17: 7 | B17: Reports - Biz Done | C17: BizDone - Finance Team to see the respective Org. data similar to VRK | D17: Yet to start | E17: Milestone 4 | F17: 24-Jun-2026 | G17: Karan
A18: 8 | B18: Cut Off Mgmt | D18: Yet to start | E18: Milestone 2 | F18: 26-Jun-2026 | H18: Need inputs related to the implementation
A19: 9 | B19: View Service Score | C19: Servicing Stats Dashboard - Single Table (drillable) to calculate an overall score | D19: Delivered - Deficit | E19: Milestone 4 | F19: 26-Jun-2026 | G19: Pushyami | H19: Pending: Meeting, MIR calculation
A20: 10 | B20: Integration UI Component | C20: Integration UI Component (for TPA, HRMS, Insurer) | D20: Yet to start | E20: Milestone 5 | F20: 26-Jun-2026
A21: 11 | B21: Reconciliation Management Upload Commission Statement | C21: Upload commission statement, reconcile against issued policies; Upload invoice & reconcile against commission stmt; Upload invoice statuses and reconcile paid/unpaid | D21: Yet to start | E21: Milestone 5 | F21: 26-Jun-2026
A22: 12 | B22: Reconciliation Mgmt | D22: Yet to start | E22: Milestone 5 | F22: 26-Jun-2026
A23: 13 | B23: Insurer Integration Mgmt | D23: Yet to start | E23: Milestone 5 | F23: 26-Jun-2026
A24: 📅 29 Jun 2026 → 05 Jul 2026 · 1 item
A25: 1 | B25: Teams Integration | C25: MS Teams - Meetings & Tasks integration into iWork | D25: Yet to start | E25: Milestone 4 | F25: 30-Jun-2026 | G25: Rama
A26: ⏳ Unscheduled (no ETA assigned) · 6 items
A27: 1 | B27: Reports | C27: Generic template for all the reports, Bizdone Report, Missing entries from commission statement against policies | D27: Delivered - Deficit | E27: Milestone 5
A28: 2 | B28: HRMS Integration Mgmt | C28: Base framework needs to be built and actual integration should be on need - Need to create the API's for each service flow process (Endorsement - Add/Delete) - Endorsement process - What is the process for this? | D28: Yet to start | E28: Milestone 5
A29: 3 | B29: Export to Excel | C29: Export to excel - iWork all the results table; Download is on Previlage | D29: Yet to start | E29: Milestone 6
A30: 4 | B30: VRK - PROD Feedback: 8-Jun-2026 | C30: Filter stickyness is not working for Bizdone and check with all the other screens. (Filters Persistence in all the screens) | D30: Yet to start | E30: Milestone 6
A31: 5 | B31: VRK - PROD Feedback: 8-Jun-2026 | C31: my followup should be added into my actionalables with default display instead of "All" tab. | D31: Yet to start | E31: Milestone 6
A32: 6 | B32: Rewards | C32: Rewards - Specific & Generic Rewards - Start with a form and collect data | D32: Yet to start | E32: Milestone 6

Sheet 📋 iWork CRs
A1: IWORK (CHANGE REQUESTS) — PENDING WEEKLY PLAN
A3: ⚠️ This sheet is a static snapshot. To update: edit STATUS in the source sheet, then re-run build_iirm_summary.py
A5: # | B5: Feature | C5: Functionality | D5: Status | E5: Milestone | F5: ETA | G5: Resource | H5: Remarks
A6: 📅 08 Jun 2026 → 14 Jun 2026 · 1 item
A7: 1 | B7: End-2-End: Automation of IBP Go-live Setup | C7: 1. Form based data collection 2. Default CMS details 3. Configure the sub-domain in AWS (any API) | D7: Yet to start | E7: Milestone 6 | F7: 12-Jun-2026
A8: 📅 15 Jun 2026 → 21 Jun 2026 · 1 item
A9: 1 | B9: Policy Configuration | C9: Using AI - Extract the Policy document and perform Policy Configuration (Premium, Family, Parameters, & Others) | D9: QA - WIP | E9: Milestone 6 | F9: 16-Jun-2026 | G9: Jagadeesh
A10: 📅 22 Jun 2026 → 28 Jun 2026 · 3 items
A11: 1 | B11: Policy Configuration | C11: Enable Parent-Child Policy Mapping for GMC and Sub-Plans (Parental, OPD, Dental, Others) - How to view config from Base to Child Policiy? - How to handle endorsement & Claims? (Entire Service Flow) | D11: Yet to start | E11: Milestone 6 | F11: 24-Jun-2026 | G11: Sunil
A12: 2 | B12: Opportunity - Validate uploaded documents | C12: Using AI - Extract the documents, validate, populate the data in the Opty. flow (Ex. KDM Meeting, Policy Hard Copy, & Others) | D12: Yet to start | E12: Milestone 6 | F12: 24-Jun-2026 | G12: Jagadeesh | H12: Need some information about the document rules that defines the idenity of it
A13: 3 | B13: Cover Mgmt | C13: Asset fields which are captured at Broking slip, few of the asset fields should not be printed at the time of Placement slip (example, no of members at inception, total lives, prev policy expiring year etc.) only for GMC | D13: Yet to start | E13: Milestone 6 | F13: 24-Jun-2026 | G13: Karan

Sheet 📋 IBP
A1: IBP (BACKLOG) — PENDING WEEKLY PLAN
A3: ⚠️ This sheet is a static snapshot. To update: edit STATUS in the source sheet, then re-run build_iirm_summary.py
A5: # | B5: Feature | C5: Functionality | D5: Status | E5: Milestone | F5: ETA | G5: Resource | H5: Remarks
A6: 📅 08 Jun 2026 → 14 Jun 2026 · 2 items
A7: 1 | C7: Risk Watch: Showing policy feature documents at each policy | D7: Pre-PROD | E7: Milestone 3 | F7: 09-Jun-2026 | G7: Ravi
A8: 2 | B8: IBP - Portal Setup | C8: Post policy creation, create default IBP Portal Config for all the company-policy(ies) | D8: Pre-PROD | E8: Milestone 4 | F8: 10-Jun-2026 | G8: Manjusha
A9: 📅 15 Jun 2026 → 21 Jun 2026 · 2 items
A10: 1 | B10: NFR_Usability | C10: NFR-USA-011: The system should support at least 100 concurrent users without performance degradation. | D10: Pre-PROD | E10: Milestone 4 | F10: 17-Jun-2026 | G10: Akhila
A11: 2 | B11: My Insurance | C11: Part-2: Hub of all plans I have as an employee - individually signed up. Mostly a navigational page | D11: Yet to start | E11: Milestone 5 | F11: 19-Jun-2026 | G11: Abhilash | H11: Retail insurance(facility to load user insurance policies)
A12: 📅 22 Jun 2026 → 28 Jun 2026 · 4 items
A13: 1 | B13: Claims Corner | C13: Claims Corner - Screen Re-design | D13: Dev - WIP | E13: Milestone 6 | F13: 22-Jun-2026
A14: 2 | B14: Admin Reports | C14: Services for multiple reports | D14: Yet to start | E14: Milestone 4 | F14: 23-Jun-2026 | G14: Abhilash
A15: 3 | B15: Group Policy Mgmt - Data Load | C15: End User data load {Similar to inception data load only but this time it is from the policy definition stage and confiemd by HR of the Company}. Reuse of the inception data load | D15: Pre-PROD | E15: Milestone 4 | F15: 24-Jun-2026 | G15: Tharun | H15: Pending: HR Module - Endorsement
A16: 4 | B16: NFR_Security | C16: DPDP NFR | D16: Yet to start | E16: Milestone 4 | F16: 24-Jun-2026 | G16: Tharun
A17: ⏳ Unscheduled (no ETA assigned) · 23 items
A18: 1 | B18: IBP Landing Page - Advanced | C18: Advanced Landing Page with individual plans & wellness programs introduced Quick Links, Promotional, high level dashboard, my plans, individual policies, company benefits, etc. Whitelabelling may be required (only Company Logo), but for future, theming may have to be supported | D18: Delivered - Deficit | E18: Milestone 5 | H18: Pending: Wellness Program related
A19: 2 | B19: Dynamic Info Sections - Landing | C19: Hospital network, Offers and Discounts, Benfits at Glance, Quick Links | D19: Delivered - Deficit | E19: Milestone 5 | G19: Manjusha | H19: Pending: Offers & Discuounts
A20: 3 | B20: User Profile | C20: Profile, Service Subscriptions, Feedback | D20: Delivered - Deficit | E20: Milestone 5 | G20: Abhilash | H20: Pending: Service Subscriptions, Feedback
A21: 4 | B21: Benefits Summary | C21: End User's Summary View | D21: Delivered - Deficit | E21: Milestone 5 | H21: Pending: Retail Insurance
A22: 5 | B22: End User Portal Configurator | C22: What set of features to be enabled or disabled, Offers, Benefits etc. More or less how portal should contain and visible to end user needs to be configured (per Corporate Configuration) | D22: Delivered - Deficit | E22: Milestone 5 | H22: Pending: Offer, Feature flagging (UI)
A23: 6 | B23: Basic Wellness Hub | C23: Basic wellness hub - Currently only 3 wellness programs (3rd parties) supported | D23: Yet to start | E23: Milestone 5 | G23: Manjusha
A24: 7 | B24: Book Ambulance | C24: Floater on the screen - Integrate to Ambulance Service | D24: Yet to start | E24: Milestone 5
A25: 8 | B25: Chat Interface | C25: Floater on the screen - Integrate with AI Component and IWork support channel | D25: Yet to start | E25: Milestone 5
A26: 9 | B26: Wellness HR View | C26: HR View of Wellness usage by Employees | D26: Yet to start | E26: Milestone 5
A27: 10 | B27: Wellness Partner View | C27: Partner/service provider view of the usage of their corresponding services | D27: Yet to start | E27: Milestone 5
A28: 11 | B28: Individual Plans | C28: Quotation flow of a new insurance - multple products; quotation ranges after basic data collection; cross-sells and finally an summary page that someone will get back to you. About 7 individual products - could be 4-5 screens in the flow of which 2 screens may be product-specific. | D28: Yet to start | E28: Milestone 5 | G28: Abhilash | H28: Pending: Retail insurance
A29: 12 | B29: Profile Migration | C29: Request migration of Corporate Profile to Individual | D29: Yet to start | E29: Milestone 5
A30: 13 | B30: Profile Migration | C30: Request migration of Individual Profile to Corporate | D30: Yet to start | E30: Milestone 5
A31: 14 | B31: Individual Plan Summary | C31: View of individual Plans currently owned with renewal dates, premiums etc. | D31: Yet to start | E31: Milestone 5 | G31: Manjusha | H31: Pending: Retail insurance
A32: 15 | B32: Chat for End Users | C32: Chat Module to interact with Chat Bot and Customer Support Representative | D32: Yet to start | E32: Milestone 5 | H32: External chatbot integration?
A33: 16 | B33: Landing Page Services | C33: Benefits Summary View, Upcoming welness appointment, Policy renewals, Individual Plans Summary views | D33: Yet to start | E33: Milestone 5
A34: 17 | B34: Feedback Mgmt | C34: User Feedback capture service | D34: Yet to start | E34: Milestone 5 | H34: IBP support is already in place
A35: 18 | B35: Premium Range Calculator | C35: Calculate insurance premium range. Calculate the IDV of various assets | D35: Yet to start | E35: Milestone 5
A36: 19 | B36: Multiple 3rd Party Service Mgmt | C36: Elderly Services, Dental Services etc. 3rd Party integrations. Multiple providers 3 such services are in scope at this stage {Redhealth, MyDental, AkinCare} | D36: Yet to start | E36: Milestone 5
A37: 20 | B37: Online Pharmacy Integration | C37: External Pharmacy integration(s), more than one pharmacy capability. SSO to the pharmacy. | D37: Yet to start | E37: Milestone 5
A38: 21 | B38: Evexia Club Integration | C38: Integration to Evexia | D38: Yet to start | E38: Milestone 5
A39: 22 | B39: Claims Mgmt | C39: Part-2: Personal Policy based claim mgmt, Tracking status, Document Mgmt related to claims | D39: Yet to start | E39: Milestone 5
A40: 23 | B40: Individual Insurance Plan Mgmt | C40: Support for multiple categories of plans. Configuration Mgmt for Infomration capture, Flow and Summaries. Add on configuration, Insurer configuration, Offer configuration, Post the request to Sales Channel (Iwork) 7 Policy Types to be taken care of | D40: Yet to start | E40: Milestone 5

Sheet 📋 IBP CRs
A1: IBP (CHANGE REQUESTS) — PENDING WEEKLY PLAN
A3: ⚠️ This sheet is a static snapshot. To update: edit STATUS in the source sheet, then re-run build_iirm_summary.py
A5: # | B5: Feature | C5: Functionality | D5: Status | E5: Milestone | F5: ETA | G5: Resource | H5: Remarks
A6: 📅 22 Jun 2026 → 28 Jun 2026 · 1 item
A7: 1 | B7: Claim Intimation & Submission | C7: POC - Using AI(Amazon Textract) - Extract Claim documents and populate the data | D7: Dev - WIP | E7: Milestone 6 | F7: 22-Jun-2026 | G7: Tharun

Sheet 📋 IBP-iWork
A1: IBP / IWORK (SHARED) — PENDING WEEKLY PLAN
A3: ⚠️ This sheet is a static snapshot. To update: edit STATUS in the source sheet, then re-run build_iirm_summary.py
A5: # | B5: Feature | C5: Functionality | D5: Status | E5: Milestone | F5: ETA | G5: Resource | H5: Remarks
A6: 📅 22 Jun 2026 → 28 Jun 2026 · 4 items
A7: 1 | B7: Security | C7: InfoSec - IBP Portal (Security Issue) 19-Jun: Critical - 0 High - 3 Pending Medium - 24 pending Low - 2 pending | D7: Dev - WIP | E7: Milestone 4 | F7: 22-Jun-2026
A8: 2 | B8: NFR_Usability | C8: NFR-USA-021: Guidelines for document management should be provided | D8: Delivered - Deficit | E8: Milestone 4 | F8: 24-Jun-2026 | G8: Manjusha | H8: Pending: Provide the document on how do we store and view it
A9: 3 | B9: Country Handling {Data Source Mgmt} | C9: 23-May: Respective org. data should reside in the same country. | D9: Yet to start | E9: Milestone 4 | F9: 24-Jun-2026 | G9: Tharun | H9: Check with Gopal
A10: 4 | B10: TPA Integration Mgmt [Framework] | C10: 1. Framework - KIT 2. WBS - with details -Medi Assist India Pvt. Ltd. -Family Health Plan Ltd. -Health India -MD India Healthcare Services (Pvt.) Ltd. -Vidal Health TPA Private Limited -Paramount Health Services Pvt. Ltd. | D10: Dev - WIP | E10: Milestone 5 | F10: 24-Jun-2026 | H10: 9-Jun: Shared errors to Neeraj
A11: ⏳ Unscheduled (no ETA assigned) · 4 items
A12: 1 | B12: Core Infrastructure | C12: Core Infra | D12: Delivered - Deficit | E12: Milestone 5 | H12: Pending: Mobile responsive
A13: 2 | B13: Wellness Admin Configurator | C13: Admin side of IBP (in iWork) needs to customize/configure the offerings/page per Corporate. | D13: Yet to start | E13: Milestone 5
A14: 3 | B14: Wellness IIRM View | C14: IIRM View of Wellness usage by Corporates/Employees (IBP Admin) | D14: Yet to start | E14: Milestone 5
A15: 4 | B15: VRK - PROD Feedback: 8-Jun-2026 | C15: TPA Integration for other TPA's - Approach/Prerequisites to initiate the process. | D15: Dev - WIP | E15: Milestone 6 | G15: Tharun

Sheet 📋 Framework
A1: FRAMEWORK — PENDING WEEKLY PLAN
A3: ⚠️ This sheet is a static snapshot. To update: edit STATUS in the source sheet, then re-run build_iirm_summary.py
A5: # | B5: Feature | C5: Functionality | D5: Status | E5: Milestone | F5: ETA | G5: Resource | H5: Remarks
A6: 📅 22 Jun 2026 → 28 Jun 2026 · 6 items
A7: 1 | B7: Notification and Communication Management | C7: 23-May: In-App, Emails, SMS, both or all. Template vs Channel | D7: Delivered - Deficit | E7: Milestone 2 | F7: 24-Jun-2026 | H7: Pending: Configuration UI
A8: 2 | B8: Accessibility | D8: Yet to start | E8: Milestone 4 | F8: 24-Jun-2026
A9: 3 | B9: Usage Tracking System (Reports) | C9: 23-May: Handle as a part of Reports | D9: Delivered - Deficit | E9: Milestone 2 | F9: 25-Jun-2026 | H9: Pending: IBP usage
A10: 4 | B10: Localisation | D10: Delivered - Deficit | E10: Milestone 4 | F10: 25-Jun-2026 | G10: Karan | H10: Pending: Service Flow & IBP
A11: 5 | B11: Workflow Management | C11: 23-May: Integrate the 3'rd party libraries | D11: Yet to start | E11: Milestone 4 | F11: 26-Jun-2026 | G11: Nithin
A12: 6 | B12: Rule Definition Management | C12: 23-May: Integrate the 3'rd party libraries | D12: Yet to start | E12: Milestone 4 | F12: 26-Jun-2026 | G12: Nithin

Sheet 📋 DPDP
A1: DPDP — PENDING WEEKLY PLAN
A3: ⚠️ This sheet is a static snapshot. To update: edit STATUS in the source sheet, then re-run build_iirm_summary.py
A5: # | B5: Feature | C5: Functionality | D5: Status | E5: Milestone | F5: ETA | G5: Resource | H5: Remarks
A6: 📅 22 Jun 2026 → 28 Jun 2026 · 11 items
A7: 1 | B7: Show privacy notice with purpose, retention, rights | D7: Dev - WIP | E7: Milestone 5 | F7: 24-Jun-2026 | G7: Sunil
A8: 2 | B8: App vulnerability scans | D8: Dev - WIP | E8: Milestone 5 | F8: 24-Jun-2026
A9: 3 | B9: Quarterly restore tests | D9: Pre-PROD | E9: Milestone 5 | F9: 24-Jun-2026
A10: 4 | B10: Document Flows | D10: Yet to start | E10: Milestone 5 | F10: 24-Jun-2026
A11: 5 | B11: Perform security UAT | D11: Yet to start | E11: Milestone 5 | F11: 24-Jun-2026
A12: 6 | B12: Enforce business logic to restrict purpose | D12: Yet to start | E12: Milestone 5 | F12: 24-Jun-2026
A13: 7 | B13: Map PII tables | D13: QA - WIP | E13: Milestone 5 | F13: 25-Jun-2026
A14: 8 | B14: Enable delete pipeline | D14: Yet to start | E14: Milestone 5 | F14: 26-Jun-2026
A15: 9 | B15: Allow user corrections | D15: Yet to start | E15: Milestone 5 | F15: 26-Jun-2026
A16: 10 | B16: Delete expired data | D16: Yet to start | E16: Milestone 5 | F16: 26-Jun-2026
A17: 11 | B17: Sign DPDP clauses | D17: Yet to start | E17: Milestone 5 | F17: 26-Jun-2026
A18: 📅 29 Jun 2026 → 05 Jul 2026 · 2 items
A19: 1 | B19: Define archival | D19: Yet to start | E19: Milestone 5 | F19: 30-Jun-2026
A20: 2 | B20: Archived Oppurtunity, Policy Mgmt {Archived Biz Data and Retrieval on need} - DPDP | D20: Yet to start | E20: Milestone 4 | F20: 30-Jun-2026 | H20: Duplicate of Archival from NFR & DPDP
A21: ⏳ Unscheduled (no ETA assigned) · 1 item
A22: 1 | B22: Enable SAST | D22: Dev - WIP | E22: Milestone 5

Sheet 📋 NFR
A1: NFR — PENDING WEEKLY PLAN
A3: ⚠️ This sheet is a static snapshot. To update: edit STATUS in the source sheet, then re-run build_iirm_summary.py
A5: # | B5: Feature | C5: Functionality | D5: Status | E5: Milestone | F5: ETA | G5: Resource | H5: Remarks
A6: 📅 22 Jun 2026 → 28 Jun 2026 · 1 item
A7: 1 | B7: NFR-OTH-022: A self-service report generator must be available for dynamic query/report creation. | D7: Yet to start | E7: Milestone 5 | F7: 26-Jun-2026 | H7: Need clarity

Sheet ③ Milestone Summary
A1: MILESTONE SUMMARY — Pending Items by Milestone & Module
A3: Counts show PENDING items only (Delivered & N/A excluded). Live from the SOW sheet.
A4: Milestone | B4: iWork (Backlog) | C4: iWork (Change Requests) | D4: IBP (Backlog) | E4: IBP (Change Requests) | F4: IBP / iWork (Shared) | G4: Framework | H4: DPDP | I4: NFR | J4: TOTAL PENDING
A5: Milestone 1 | B5: =COUNTIFS(Helper!$B:$B,"Milestone 1",Helper!$A:$A,"iWork",Helper!$E:$E,"Pending") -> 0 | C5: =COUNTIFS(Helper!$B:$B,"Milestone 1",Helper!$A:$A,"iWork - CR",Helper!$E:$E,"Pending") -> 0 | D5: =COUNTIFS(Helper!$B:$B,"Milestone 1",Helper!$A:$A,"IBP",Helper!$E:$E,"Pending") -> 0 | E5: =COUNTIFS(Helper!$B:$B,"Milestone 1",Helper!$A:$A,"IBP - CR",Helper!$E:$E,"Pending") -> 0 | F5: =COUNTIFS(Helper!$B:$B,"Milestone 1",Helper!$A:$A,"IBP/iWork",Helper!$E:$E,"Pending") -> 0 | G5: =COUNTIFS(Helper!$B:$B,"Milestone 1",Helper!$A:$A,"Framework",Helper!$E:$E,"Pending") -> 0 | H5: =COUNTIFS(Helper!$B:$B,"Milestone 1",Helper!$A:$A,"DPDP",Helper!$E:$E,"Pending") -> 0 | I5: =COUNTIFS(Helper!$B:$B,"Milestone 1",Helper!$A:$A,"NFR",Helper!$E:$E,"Pending") -> 0 | J5: =SUM(B5:I5) -> 0
A6: Milestone 2 | B6: =COUNTIFS(Helper!$B:$B,"Milestone 2",Helper!$A:$A,"iWork",Helper!$E:$E,"Pending") -> 1 | C6: =COUNTIFS(Helper!$B:$B,"Milestone 2",Helper!$A:$A,"iWork - CR",Helper!$E:$E,"Pending") -> 0 | D6: =COUNTIFS(Helper!$B:$B,"Milestone 2",Helper!$A:$A,"IBP",Helper!$E:$E,"Pending") -> 0 | E6: =COUNTIFS(Helper!$B:$B,"Milestone 2",Helper!$A:$A,"IBP - CR",Helper!$E:$E,"Pending") -> 0 | F6: =COUNTIFS(Helper!$B:$B,"Milestone 2",Helper!$A:$A,"IBP/iWork",Helper!$E:$E,"Pending") -> 0 | G6: =COUNTIFS(Helper!$B:$B,"Milestone 2",Helper!$A:$A,"Framework",Helper!$E:$E,"Pending") -> 2 | H6: =COUNTIFS(Helper!$B:$B,"Milestone 2",Helper!$A:$A,"DPDP",Helper!$E:$E,"Pending") -> 0 | I6: =COUNTIFS(Helper!$B:$B,"Milestone 2",Helper!$A:$A,"NFR",Helper!$E:$E,"Pending") -> 0 | J6: =SUM(B6:I6) -> 3
A7: Milestone 3 | B7: =COUNTIFS(Helper!$B:$B,"Milestone 3",Helper!$A:$A,"iWork",Helper!$E:$E,"Pending") -> 2 | C7: =COUNTIFS(Helper!$B:$B,"Milestone 3",Helper!$A:$A,"iWork - CR",Helper!$E:$E,"Pending") -> 0 | D7: =COUNTIFS(Helper!$B:$B,"Milestone 3",Helper!$A:$A,"IBP",Helper!$E:$E,"Pending") -> 0 | E7: =COUNTIFS(Helper!$B:$B,"Milestone 3",Helper!$A:$A,"IBP - CR",Helper!$E:$E,"Pending") -> 0 | F7: =COUNTIFS(Helper!$B:$B,"Milestone 3",Helper!$A:$A,"IBP/iWork",Helper!$E:$E,"Pending") -> 0 | G7: =COUNTIFS(Helper!$B:$B,"Milestone 3",Helper!$A:$A,"Framework",Helper!$E:$E,"Pending") -> 0 | H7: =COUNTIFS(Helper!$B:$B,"Milestone 3",Helper!$A:$A,"DPDP",Helper!$E:$E,"Pending") -> 0 | I7: =COUNTIFS(Helper!$B:$B,"Milestone 3",Helper!$A:$A,"NFR",Helper!$E:$E,"Pending") -> 0 | J7: =SUM(B7:I7) -> 2
A8: Milestone 4 | B8: =COUNTIFS(Helper!$B:$B,"Milestone 4",Helper!$A:$A,"iWork",Helper!$E:$E,"Pending") -> 4 | C8: =COUNTIFS(Helper!$B:$B,"Milestone 4",Helper!$A:$A,"iWork - CR",Helper!$E:$E,"Pending") -> 0 | D8: =COUNTIFS(Helper!$B:$B,"Milestone 4",Helper!$A:$A,"IBP",Helper!$E:$E,"Pending") -> 5 | E8: =COUNTIFS(Helper!$B:$B,"Milestone 4",Helper!$A:$A,"IBP - CR",Helper!$E:$E,"Pending") -> 0 | F8: =COUNTIFS(Helper!$B:$B,"Milestone 4",Helper!$A:$A,"IBP/iWork",Helper!$E:$E,"Pending") -> 3 | G8: =COUNTIFS(Helper!$B:$B,"Milestone 4",Helper!$A:$A,"Framework",Helper!$E:$E,"Pending") -> 4 | H8: =COUNTIFS(Helper!$B:$B,"Milestone 4",Helper!$A:$A,"DPDP",Helper!$E:$E,"Pending") -> 1 | I8: =COUNTIFS(Helper!$B:$B,"Milestone 4",Helper!$A:$A,"NFR",Helper!$E:$E,"Pending") -> 0 | J8: =SUM(B8:I8) -> 17
A9: Milestone 5 | B9: =COUNTIFS(Helper!$B:$B,"Milestone 5",Helper!$A:$A,"iWork",Helper!$E:$E,"Pending") -> 6 | C9: =COUNTIFS(Helper!$B:$B,"Milestone 5",Helper!$A:$A,"iWork - CR",Helper!$E:$E,"Pending") -> 0 | D9: =COUNTIFS(Helper!$B:$B,"Milestone 5",Helper!$A:$A,"IBP",Helper!$E:$E,"Pending") -> 24 | E9: =COUNTIFS(Helper!$B:$B,"Milestone 5",Helper!$A:$A,"IBP - CR",Helper!$E:$E,"Pending") -> 0 | F9: =COUNTIFS(Helper!$B:$B,"Milestone 5",Helper!$A:$A,"IBP/iWork",Helper!$E:$E,"Pending") -> 4 | G9: =COUNTIFS(Helper!$B:$B,"Milestone 5",Helper!$A:$A,"Framework",Helper!$E:$E,"Pending") -> 0 | H9: =COUNTIFS(Helper!$B:$B,"Milestone 5",Helper!$A:$A,"DPDP",Helper!$E:$E,"Pending") -> 13 | I9: =COUNTIFS(Helper!$B:$B,"Milestone 5",Helper!$A:$A,"NFR",Helper!$E:$E,"Pending") -> 1 | J9: =SUM(B9:I9) -> 48
A10: Milestone 6 | B10: =COUNTIFS(Helper!$B:$B,"Milestone 6",Helper!$A:$A,"iWork",Helper!$E:$E,"Pending") -> 8 | C10: =COUNTIFS(Helper!$B:$B,"Milestone 6",Helper!$A:$A,"iWork - CR",Helper!$E:$E,"Pending") -> 5 | D10: =COUNTIFS(Helper!$B:$B,"Milestone 6",Helper!$A:$A,"IBP",Helper!$E:$E,"Pending") -> 1 | E10: =COUNTIFS(Helper!$B:$B,"Milestone 6",Helper!$A:$A,"IBP - CR",Helper!$E:$E,"Pending") -> 1 | F10: =COUNTIFS(Helper!$B:$B,"Milestone 6",Helper!$A:$A,"IBP/iWork",Helper!$E:$E,"Pending") -> 1 | G10: =COUNTIFS(Helper!$B:$B,"Milestone 6",Helper!$A:$A,"Framework",Helper!$E:$E,"Pending") -> 0 | H10: =COUNTIFS(Helper!$B:$B,"Milestone 6",Helper!$A:$A,"DPDP",Helper!$E:$E,"Pending") -> 0 | I10: =COUNTIFS(Helper!$B:$B,"Milestone 6",Helper!$A:$A,"NFR",Helper!$E:$E,"Pending") -> 0 | J10: =SUM(B10:I10) -> 16
A11: TOTAL | B11: =SUM(B5:B10) -> 21 | C11: =SUM(C5:C10) -> 5 | D11: =SUM(D5:D10) -> 30 | E11: =SUM(E5:E10) -> 1 | F11: =SUM(F5:F10) -> 8 | G11: =SUM(G5:G10) -> 6 | H11: =SUM(H5:H10) -> 14 | I11: =SUM(I5:I10) -> 1 | J11: =SUM(J5:J10) -> 86

Sheet Helper
A1: Module | B1: Phase | C1: Status | D1: Category | E1: Bucket
A2: ='iWork,IBP & Framework_SOW Items'!D2 -> Framework | B2: ='iWork,IBP & Framework_SOW Items'!E2 -> Milestone 1 | C2: ='iWork,IBP & Framework_SOW Items'!F2 -> Delivered | D2: =IFERROR(VLOOKUP(C2,Config!$A:$B,2,0),"Unknown") -> Delivered | E2: =IFERROR(VLOOKUP(C2,Config!$A:$C,3,0),"N/A") -> Delivered
A3: ='iWork,IBP & Framework_SOW Items'!D3 -> Framework | B3: ='iWork,IBP & Framework_SOW Items'!E3 -> Milestone 1 | C3: ='iWork,IBP & Framework_SOW Items'!F3 -> Delivered | D3: =IFERROR(VLOOKUP(C3,Config!$A:$B,2,0),"Unknown") -> Delivered | E3: =IFERROR(VLOOKUP(C3,Config!$A:$C,3,0),"N/A") -> Delivered
A4: ='iWork,IBP & Framework_SOW Items'!D4 -> Framework | B4: ='iWork,IBP & Framework_SOW Items'!E4 -> Milestone 1 | C4: ='iWork,IBP & Framework_SOW Items'!F4 -> Delivered | D4: =IFERROR(VLOOKUP(C4,Config!$A:$B,2,0),"Unknown") -> Delivered | E4: =IFERROR(VLOOKUP(C4,Config!$A:$C,3,0),"N/A") -> Delivered
A5: ='iWork,IBP & Framework_SOW Items'!D5 -> Framework | B5: ='iWork,IBP & Framework_SOW Items'!E5 -> Milestone 1 | C5: ='iWork,IBP & Framework_SOW Items'!F5 -> Delivered | D5: =IFERROR(VLOOKUP(C5,Config!$A:$B,2,0),"Unknown") -> Delivered | E5: =IFERROR(VLOOKUP(C5,Config!$A:$C,3,0),"N/A") -> Delivered
A6: ='iWork,IBP & Framework_SOW Items'!D6 -> Framework | B6: ='iWork,IBP & Framework_SOW Items'!E6 -> Milestone 1 | C6: ='iWork,IBP & Framework_SOW Items'!F6 -> Delivered | D6: =IFERROR(VLOOKUP(C6,Config!$A:$B,2,0),"Unknown") -> Delivered | E6: =IFERROR(VLOOKUP(C6,Config!$A:$C,3,0),"N/A") -> Delivered
A7: ='iWork,IBP & Framework_SOW Items'!D7 -> Framework | B7: ='iWork,IBP & Framework_SOW Items'!E7 -> Milestone 1 | C7: ='iWork,IBP & Framework_SOW Items'!F7 -> Delivered | D7: =IFERROR(VLOOKUP(C7,Config!$A:$B,2,0),"Unknown") -> Delivered | E7: =IFERROR(VLOOKUP(C7,Config!$A:$C,3,0),"N/A") -> Delivered
A8: ='iWork,IBP & Framework_SOW Items'!D8 -> Framework | B8: ='iWork,IBP & Framework_SOW Items'!E8 -> Milestone 1 | C8: ='iWork,IBP & Framework_SOW Items'!F8 -> Delivered | D8: =IFERROR(VLOOKUP(C8,Config!$A:$B,2,0),"Unknown") -> Delivered | E8: =IFERROR(VLOOKUP(C8,Config!$A:$C,3,0),"N/A") -> Delivered
A9: ='iWork,IBP & Framework_SOW Items'!D9 -> Framework | B9: ='iWork,IBP & Framework_SOW Items'!E9 -> Milestone 1 | C9: ='iWork,IBP & Framework_SOW Items'!F9 -> Delivered | D9: =IFERROR(VLOOKUP(C9,Config!$A:$B,2,0),"Unknown") -> Delivered | E9: =IFERROR(VLOOKUP(C9,Config!$A:$C,3,0),"N/A") -> Delivered
A10: ='iWork,IBP & Framework_SOW Items'!D10 -> Framework | B10: ='iWork,IBP & Framework_SOW Items'!E10 -> Milestone 1 | C10: ='iWork,IBP & Framework_SOW Items'!F10 -> Delivered | D10: =IFERROR(VLOOKUP(C10,Config!$A:$B,2,0),"Unknown") -> Delivered | E10: =IFERROR(VLOOKUP(C10,Config!$A:$C,3,0),"N/A") -> Delivered
A11: ='iWork,IBP & Framework_SOW Items'!D11 -> Framework | B11: ='iWork,IBP & Framework_SOW Items'!E11 -> Milestone 1 | C11: ='iWork,IBP & Framework_SOW Items'!F11 -> Delivered | D11: =IFERROR(VLOOKUP(C11,Config!$A:$B,2,0),"Unknown") -> Delivered | E11: =IFERROR(VLOOKUP(C11,Config!$A:$C,3,0),"N/A") -> Delivered
A12: ='iWork,IBP & Framework_SOW Items'!D12 -> Framework | B12: ='iWork,IBP & Framework_SOW Items'!E12 -> Milestone 1 | C12: ='iWork,IBP & Framework_SOW Items'!F12 -> Delivered | D12: =IFERROR(VLOOKUP(C12,Config!$A:$B,2,0),"Unknown") -> Delivered | E12: =IFERROR(VLOOKUP(C12,Config!$A:$C,3,0),"N/A") -> Delivered
A13: ='iWork,IBP & Framework_SOW Items'!D13 -> Framework | B13: ='iWork,IBP & Framework_SOW Items'!E13 -> Milestone 1 | C13: ='iWork,IBP & Framework_SOW Items'!F13 -> Delivered | D13: =IFERROR(VLOOKUP(C13,Config!$A:$B,2,0),"Unknown") -> Delivered | E13: =IFERROR(VLOOKUP(C13,Config!$A:$C,3,0),"N/A") -> Delivered
... A261: ='iWork,IBP & Framework_SOW Items'!D261 -> iWork - CR | B261: ='iWork,IBP & Framework_SOW Items'!E261 -> Milestone 6 | C261: ='iWork,IBP & Framework_SOW Items'!F261 -> Yet to start | D261: =IFERROR(VLOOKUP(C261,Config!$A:$B,2,0),"Unknown") -> Not Started | E261: =IFERROR(VLOOKUP(C261,Config!$A:$C,3,0),"N/A") -> Pending

Sheet Config
A1: Status_Raw | B1: Category | C1: Bucket
A2: Delivered | B2: Delivered | C2: Delivered
A3: Dev - Done | B3: Dev Complete | C3: Delivered
A4: Dev - WIP | B4: In Development | C4: Pending
A5: QA - WIP | B5: In QA | C5: Pending
A6: Pre-PROD | B6: Pre-PROD / UAT | C6: Pending
A7: Yet to start | B7: Not Started | C7: Pending
A8: Delivered - Deficit | B8: Partial Delivery | C8: Pending
A9: Duplicate | B9: N/A | C9: N/A

Sheet ② Pending Roadmap
A1: PENDING ROADMAP — Remaining Deliverables (live from SOW sheet)
A3: 🔎 Delivered & N/A items are filtered out by default. Click the filter arrow on the 'Delivery' column (F5) → tick 'Delivered' or 'Select All' to show them.
A5: Milestone | B5: Module | C5: Feature | D5: Functionality | E5: Status | F5: Delivery | G5: ETA | H5: Resource | I5: Remarks
A6: ='iWork,IBP & Framework_SOW Items'!E2 -> Milestone 1 | B6: ='iWork,IBP & Framework_SOW Items'!D2 -> Framework | C6: ='iWork,IBP & Framework_SOW Items'!B2 -> Project setup | D6: ='iWork,IBP & Framework_SOW Items'!C2 -> Basic project / Development environment setup | E6: ='iWork,IBP & Framework_SOW Items'!F2 -> Delivered | F6: =Helper!E2 -> Delivered | G6: =IF('iWork,IBP & Framework_SOW Items'!I2="","",'iWork,IBP & Framework_SOW Items'!I2) | H6: =IF('iWork,IBP & Framework_SOW Items'!J2="","",'iWork,IBP & Framework_SOW Items'!J2) | I6: =IF('iWork,IBP & Framework_SOW Items'!G2="","",'iWork,IBP & Framework_SOW Items'!G2)
A7: ='iWork,IBP & Framework_SOW Items'!E3 -> Milestone 1 | B7: ='iWork,IBP & Framework_SOW Items'!D3 -> Framework | C7: ='iWork,IBP & Framework_SOW Items'!B3 -> UI Approach Design System | D7: ='iWork,IBP & Framework_SOW Items'!C3 -> Building Design System | E7: ='iWork,IBP & Framework_SOW Items'!F3 -> Delivered | F7: =Helper!E3 -> Delivered | G7: =IF('iWork,IBP & Framework_SOW Items'!I3="","",'iWork,IBP & Framework_SOW Items'!I3) | H7: =IF('iWork,IBP & Framework_SOW Items'!J3="","",'iWork,IBP & Framework_SOW Items'!J3) | I7: =IF('iWork,IBP & Framework_SOW Items'!G3="","",'iWork,IBP & Framework_SOW Items'!G3)
A8: ='iWork,IBP & Framework_SOW Items'!E4 -> Milestone 1 | B8: ='iWork,IBP & Framework_SOW Items'!D4 -> Framework | C8: ='iWork,IBP & Framework_SOW Items'!B4 -> Core Infrastructure | D8: ='iWork,IBP & Framework_SOW Items'!C4 -> Core Infra | E8: ='iWork,IBP & Framework_SOW Items'!F4 -> Delivered | F8: =Helper!E4 -> Delivered | G8: =IF('iWork,IBP & Framework_SOW Items'!I4="","",'iWork,IBP & Framework_SOW Items'!I4) | H8: =IF('iWork,IBP & Framework_SOW Items'!J4="","",'iWork,IBP & Framework_SOW Items'!J4) | I8: =IF('iWork,IBP & Framework_SOW Items'!G4="","",'iWork,IBP & Framework_SOW Items'!G4)
A9: ='iWork,IBP & Framework_SOW Items'!E5 -> Milestone 1 | B9: ='iWork,IBP & Framework_SOW Items'!D5 -> Framework | C9: ='iWork,IBP & Framework_SOW Items'!B5 -> Build UI components | D9: ='iWork,IBP & Framework_SOW Items'!C5 -> This includes all the UI componnets to compose the application and module definitions: Form, Toast, Filter, Cards, Visualisation, Grid, Menu, Header, Footer, Maps Integration | E9: ='iWork,IBP & Framework_SOW Items'!F5 -> Delivered | F9: =Helper!E5 -> Delivered | G9: =IF('iWork,IBP & Framework_SOW Items'!I5="","",'iWork,IBP & Framework_SOW Items'!I5) | H9: =IF('iWork,IBP & Framework_SOW Items'!J5="","",'iWork,IBP & Framework_SOW Items'!J5) | I9: =IF('iWork,IBP & Framework_SOW Items'!G5="","",'iWork,IBP & Framework_SOW Items'!G5)
A10: ='iWork,IBP & Framework_SOW Items'!E6 -> Milestone 1 | B10: ='iWork,IBP & Framework_SOW Items'!D6 -> Framework | C10: ='iWork,IBP & Framework_SOW Items'!B6 -> UI Approach Style Establishment | D10: ='iWork,IBP & Framework_SOW Items'!C6 -> UI Style Establishment | E10: ='iWork,IBP & Framework_SOW Items'!F6 -> Delivered | F10: =Helper!E6 -> Delivered | G10: =IF('iWork,IBP & Framework_SOW Items'!I6="","",'iWork,IBP & Framework_SOW Items'!I6) | H10: =IF('iWork,IBP & Framework_SOW Items'!J6="","",'iWork,IBP & Framework_SOW Items'!J6) | I10: =IF('iWork,IBP & Framework_SOW Items'!G6="","",'iWork,IBP & Framework_SOW Items'!G6)
A11: ='iWork,IBP & Framework_SOW Items'!E7 -> Milestone 1 | B11: ='iWork,IBP & Framework_SOW Items'!D7 -> Framework | C11: ='iWork,IBP & Framework_SOW Items'!B7 -> Service Workers Implementation | D11: ='iWork,IBP & Framework_SOW Items'!C7 -> 0 | E11: ='iWork,IBP & Framework_SOW Items'!F7 -> Delivered | F11: =Helper!E7 -> Delivered | G11: =IF('iWork,IBP & Framework_SOW Items'!I7="","",'iWork,IBP & Framework_SOW Items'!I7) | H11: =IF('iWork,IBP & Framework_SOW Items'!J7="","",'iWork,IBP & Framework_SOW Items'!J7) | I11: =IF('iWork,IBP & Framework_SOW Items'!G7="","",'iWork,IBP & Framework_SOW Items'!G7)
A12: ='iWork,IBP & Framework_SOW Items'!E8 -> Milestone 1 | B12: ='iWork,IBP & Framework_SOW Items'!D8 -> Framework | C12: ='iWork,IBP & Framework_SOW Items'!B8 -> Core System | D12: ='iWork,IBP & Framework_SOW Items'!C8 -> 0 | E12: ='iWork,IBP & Framework_SOW Items'!F8 -> Delivered | F12: =Helper!E8 -> Delivered | G12: =IF('iWork,IBP & Framework_SOW Items'!I8="","",'iWork,IBP & Framework_SOW Items'!I8) | H12: =IF('iWork,IBP & Framework_SOW Items'!J8="","",'iWork,IBP & Framework_SOW Items'!J8) | I12: =IF('iWork,IBP & Framework_SOW Items'!G8="","",'iWork,IBP & Framework_SOW Items'!G8)
A13: ='iWork,IBP & Framework_SOW Items'!E9 -> Milestone 1 | B13: ='iWork,IBP & Framework_SOW Items'!D9 -> Framework | C13: ='iWork,IBP & Framework_SOW Items'!B9 -> ACL & RBAC Control Framework | D13: ='iWork,IBP & Framework_SOW Items'!C9 -> 0 | E13: ='iWork,IBP & Framework_SOW Items'!F9 -> Delivered | F13: =Helper!E9 -> Delivered | G13: =IF('iWork,IBP & Framework_SOW Items'!I9="","",'iWork,IBP & Framework_SOW Items'!I9) | H13: =IF('iWork,IBP & Framework_SOW Items'!J9="","",'iWork,IBP & Framework_SOW Items'!J9) | I13: =IF('iWork,IBP & Framework_SOW Items'!G9="","",'iWork,IBP & Framework_SOW Items'!G9)
A14: ='iWork,IBP & Framework_SOW Items'!E10 -> Milestone 1 | B14: ='iWork,IBP & Framework_SOW Items'!D10 -> Framework | C14: ='iWork,IBP & Framework_SOW Items'!B10 -> Micro Frontend Setup | D14: ='iWork,IBP & Framework_SOW Items'!C10 -> 0 | E14: ='iWork,IBP & Framework_SOW Items'!F10 -> Delivered | F14: =Helper!E10 -> Delivered | G14: =IF('iWork,IBP & Framework_SOW Items'!I10="","",'iWork,IBP & Framework_SOW Items'!I10) | H14: =IF('iWork,IBP & Framework_SOW Items'!J10="","",'iWork,IBP & Framework_SOW Items'!J10) | I14: =IF('iWork,IBP & Framework_SOW Items'!G10="","",'iWork,IBP & Framework_SOW Items'!G10)
A15: ='iWork,IBP & Framework_SOW Items'!E11 -> Milestone 1 | B15: ='iWork,IBP & Framework_SOW Items'!D11 -> Framework | C15: ='iWork,IBP & Framework_SOW Items'!B11 -> Landing Page | D15: ='iWork,IBP & Framework_SOW Items'!C11 -> 0 | E15: ='iWork,IBP & Framework_SOW Items'!F11 -> Delivered | F15: =Helper!E11 -> Delivered | G15: =IF('iWork,IBP & Framework_SOW Items'!I11="","",'iWork,IBP & Framework_SOW Items'!I11) | H15: =IF('iWork,IBP & Framework_SOW Items'!J11="","",'iWork,IBP & Framework_SOW Items'!J11) | I15: =IF('iWork,IBP & Framework_SOW Items'!G11="","",'iWork,IBP & Framework_SOW Items'!G11)
A16: ='iWork,IBP & Framework_SOW Items'!E12 -> Milestone 1 | B16: ='iWork,IBP & Framework_SOW Items'!D12 -> Framework | C16: ='iWork,IBP & Framework_SOW Items'!B12 -> Access Control Management | D16: ='iWork,IBP & Framework_SOW Items'!C12 -> 0 | E16: ='iWork,IBP & Framework_SOW Items'!F12 -> Delivered | F16: =Helper!E12 -> Delivered | G16: =IF('iWork,IBP & Framework_SOW Items'!I12="","",'iWork,IBP & Framework_SOW Items'!I12) | H16: =IF('iWork,IBP & Framework_SOW Items'!J12="","",'iWork,IBP & Framework_SOW Items'!J12) | I16: =IF('iWork,IBP & Framework_SOW Items'!G12="","",'iWork,IBP & Framework_SOW Items'!G12)
A17: ='iWork,IBP & Framework_SOW Items'!E13 -> Milestone 1 | B17: ='iWork,IBP & Framework_SOW Items'!D13 -> Framework | C17: ='iWork,IBP & Framework_SOW Items'!B13 -> Auth Module (Simple Auth) | D17: ='iWork,IBP & Framework_SOW Items'!C13 -> 0 | E17: ='iWork,IBP & Framework_SOW Items'!F13 -> Delivered | F17: =Helper!E13 -> Delivered | G17: =IF('iWork,IBP & Framework_SOW Items'!I13="","",'iWork,IBP & Framework_SOW Items'!I13) | H17: =IF('iWork,IBP & Framework_SOW Items'!J13="","",'iWork,IBP & Framework_SOW Items'!J13) | I17: =IF('iWork,IBP & Framework_SOW Items'!G13="","",'iWork,IBP & Framework_SOW Items'!G13)
... A62: ='iWork,IBP & Framework_SOW Items'!E58 -> Milestone 2 | B62: ='iWork,IBP & Framework_SOW Items'!D58 -> iWork | C62: ='iWork,IBP & Framework_SOW Items'!B58 -> Organisation, Branch, Employee, & Hierarchy Mgmt | D62: ='iWork,IBP & Framework_SOW Items'!C58 -> 0 | E62: ='iWork,IBP & Framework_SOW Items'!F58 -> Delivered | F62: =Helper!E58 -> Delivered | G62: =IF('iWork,IBP & Framework_SOW Items'!I58="","",'iWork,IBP & Framework_SOW Items'!I58) | H62: =IF('iWork,IBP & Framework_SOW Items'!J58="","",'iWork,IBP & Framework_SOW Items'!J58) | I62: =IF('iWork,IBP & Framework_SOW Items'!G58="","",'iWork,IBP & Framework_SOW Items'!G58)
A63: ='iWork,IBP & Framework_SOW Items'!E59 -> Milestone 2 | B63: ='iWork,IBP & Framework_SOW Items'!D59 -> iWork | C63: ='iWork,IBP & Framework_SOW Items'!B59 -> Dashboard (Place Holder) | D63: ='iWork,IBP & Framework_SOW Items'!C59 -> 0 | E63: ='iWork,IBP & Framework_SOW Items'!F59 -> Delivered | F63: Delivered | G63: =IF('iWork,IBP & Framework_SOW Items'!I59="","",'iWork,IBP & Framework_SOW Items'!I59) | H63: =IF('iWork,IBP & Framework_SOW Items'!J59="","",'iWork,IBP & Framework_SOW Items'!J59) | I63: =IF('iWork,IBP & Framework_SOW Items'!G59="","",'iWork,IBP & Framework_SOW Items'!G59)
A64: ='iWork,IBP & Framework_SOW Items'!E69 -> Milestone 3 | B64: ='iWork,IBP & Framework_SOW Items'!D69 -> iWork | C64: ='iWork,IBP & Framework_SOW Items'!B69 -> Stage Mgmt (Activity/Transaction/Quote) | D64: ='iWork,IBP & Framework_SOW Items'!C69 -> 0 | E64: ='iWork,IBP & Framework_SOW Items'!F69 -> Delivered | F64: =Helper!E69 -> Delivered | G64: =IF('iWork,IBP & Framework_SOW Items'!I69="","",'iWork,IBP & Framework_SOW Items'!I69) | H64: =IF('iWork,IBP & Framework_SOW Items'!J69="","",'iWork,IBP & Framework_SOW Items'!J69) | I64: =IF('iWork,IBP & Framework_SOW Items'!G69="","",'iWork,IBP & Framework_SOW Items'!G69)
A65: ='iWork,IBP & Framework_SOW Items'!E114 -> Milestone 4 | B65: ='iWork,IBP & Framework_SOW Items'!D114 -> IBP/iWork | C65: ='iWork,IBP & Framework_SOW Items'!B114 -> Company Plan Configurator | D65: ='iWork,IBP & Framework_SOW Items'!C114 -> Admin side of IBP should configure (per Corporate) how to define a Policy and determine how it breaks down the Premium and Coverage rules | E65: ='iWork,IBP & Framework_SOW Items'!F114 -> Delivered | F65: =Helper!E114 -> Delivered | G65: =IF('iWork,IBP & Framework_SOW Items'!I114="","",'iWork,IBP & Framework_SOW Items'!I114) | H65: =IF('iWork,IBP & Framework_SOW Items'!J114="","",'iWork,IBP & Framework_SOW Items'!J114) | I65: =IF('iWork,IBP & Framework_SOW Items'!G114="","",'iWork,IBP & Framework_SOW Items'!G114)
A66: ='iWork,IBP & Framework_SOW Items'!E246 -> Milestone 6 | B66: ='iWork,IBP & Framework_SOW Items'!D246 -> iWork | C66: ='iWork,IBP & Framework_SOW Items'!B246 -> VRK - PROD Feedback: 8-Jun-2026 | D66: ='iWork,IBP & Framework_SOW Items'!C246 -> Policy Hard copy receipt stage - When User uploads the Policy copy, system should capture the policy level elements like Ins Pol No., Dates, Premium amounts, etc and validate with the policy record saved. - Need discussion for more details to use the deviation and approval process to modify the values as per deviation from Policy Hard copy. | E66: ='iWork,IBP & Framework_SOW Items'!F246 -> Yet to start | F66: =Helper!E246 -> Pending | G66: =IF('iWork,IBP & Framework_SOW Items'!I246="","",'iWork,IBP & Framework_SOW Items'!I246) -> 46195 | H66: =IF('iWork,IBP & Framework_SOW Items'!J246="","",'iWork,IBP & Framework_SOW Items'!J246) -> Karan | I66: =IF('iWork,IBP & Framework_SOW Items'!G246="","",'iWork,IBP & Framework_SOW Items'!G246)
A67: ='iWork,IBP & Framework_SOW Items'!E63 -> Milestone 3 | B67: ='iWork,IBP & Framework_SOW Items'!D63 -> Framework | C67: ='iWork,IBP & Framework_SOW Items'!B63 -> Document Generation | D67: ='iWork,IBP & Framework_SOW Items'!C63 -> 0 | E67: ='iWork,IBP & Framework_SOW Items'!F63 -> Delivered | F67: =Helper!E63 -> Delivered | G67: =IF('iWork,IBP & Framework_SOW Items'!I63="","",'iWork,IBP & Framework_SOW Items'!I63) | H67: =IF('iWork,IBP & Framework_SOW Items'!J63="","",'iWork,IBP & Framework_SOW Items'!J63) | I67: =IF('iWork,IBP & Framework_SOW Items'!G63="","",'iWork,IBP & Framework_SOW Items'!G63)
A68: ='iWork,IBP & Framework_SOW Items'!E64 -> Milestone 3 | B68: ='iWork,IBP & Framework_SOW Items'!D64 -> IBP | C68: ='iWork,IBP & Framework_SOW Items'!B64 -> 0 | D68: ='iWork,IBP & Framework_SOW Items'!C64 -> Risk Watch: Showing policy feature documents at each policy | E68: ='iWork,IBP & Framework_SOW Items'!F64 -> Delivered | F68: =Helper!E64 -> Delivered | G68: =IF('iWork,IBP & Framework_SOW Items'!I64="","",'iWork,IBP & Framework_SOW Items'!I64) -> 46192 | H68: =IF('iWork,IBP & Framework_SOW Items'!J64="","",'iWork,IBP & Framework_SOW Items'!J64) -> Ravi | I68: =IF('iWork,IBP & Framework_SOW Items'!G64="","",'iWork,IBP & Framework_SOW Items'!G64)
A69: ='iWork,IBP & Framework_SOW Items'!E65 -> Milestone 3 | B69: ='iWork,IBP & Framework_SOW Items'!D65 -> iWork | C69: ='iWork,IBP & Framework_SOW Items'!B65 -> Cover Mgmt | D69: ='iWork,IBP & Framework_SOW Items'!C65 -> 0 | E69: ='iWork,IBP & Framework_SOW Items'!F65 -> Delivered | F69: =Helper!E65 -> Delivered | G69: =IF('iWork,IBP & Framework_SOW Items'!I65="","",'iWork,IBP & Framework_SOW Items'!I65) -> 46183 | H69: =IF('iWork,IBP & Framework_SOW Items'!J65="","",'iWork,IBP & Framework_SOW Items'!J65) -> Karan | I69: =IF('iWork,IBP & Framework_SOW Items'!G65="","",'iWork,IBP & Framework_SOW Items'!G65)
A70: ='iWork,IBP & Framework_SOW Items'!E66 -> Milestone 3 | B70: ='iWork,IBP & Framework_SOW Items'!D66 -> iWork | C70: ='iWork,IBP & Framework_SOW Items'!B66 -> MIR Entry Mgmt | D70: ='iWork,IBP & Framework_SOW Items'!C66 -> Entry Form, Print to Document, List of Earlier MIRs, Search on MIRs | E70: ='iWork,IBP & Framework_SOW Items'!F66 -> Yet to start | F70: =Helper!E66 -> Pending | G70: =IF('iWork,IBP & Framework_SOW Items'!I66="","",'iWork,IBP & Framework_SOW Items'!I66) -> 46197 | H70: =IF('iWork,IBP & Framework_SOW Items'!J66="","",'iWork,IBP & Framework_SOW Items'!J66) -> Pushyami | I70: =IF('iWork,IBP & Framework_SOW Items'!G66="","",'iWork,IBP & Framework_SOW Items'!G66)
A71: ='iWork,IBP & Framework_SOW Items'!E67 -> Milestone 3 | B71: ='iWork,IBP & Framework_SOW Items'!D67 -> iWork | C71: ='iWork,IBP & Framework_SOW Items'!B67 -> MIR Entry Mgmt | D71: ='iWork,IBP & Framework_SOW Items'!C67 -> Module to manage MIR {Monthly Infomatiom Report} | E71: ='iWork,IBP & Framework_SOW Items'!F67 -> Yet to start | F71: =Helper!E67 -> Pending | G71: =IF('iWork,IBP & Framework_SOW Items'!I67="","",'iWork,IBP & Framework_SOW Items'!I67) -> 46197 | H71: =IF('iWork,IBP & Framework_SOW Items'!J67="","",'iWork,IBP & Framework_SOW Items'!J67) -> Pushyami | I71: =IF('iWork,IBP & Framework_SOW Items'!G67="","",'iWork,IBP & Framework_SOW Items'!G67)
A72: ='iWork,IBP & Framework_SOW Items'!E68 -> Milestone 3 | B72: ='iWork,IBP & Framework_SOW Items'!D68 -> iWork | C72: ='iWork,IBP & Framework_SOW Items'!B68 -> Manage Policy (Endorsements) | D72: ='iWork,IBP & Framework_SOW Items'!C68 -> Add Endorsement - basic form with uploads of excel/document Validations of endorsement format - Map customer fields to internal fields Map internal fields to TPA fields (occasional per TPA) View/Update Endorsement, List View, Endorsement Performance | E72: ='iWork,IBP & Framework_SOW Items'!F68 -> Delivered | F72: =Helper!E68 -> Delivered | G72: =IF('iWork,IBP & Framework_SOW Items'!I68="","",'iWork,IBP & Framework_SOW Items'!I68) | H72: =IF('iWork,IBP & Framework_SOW Items'!J68="","",'iWork,IBP & Framework_SOW Items'!J68) | I72: =IF('iWork,IBP & Framework_SOW Items'!G68="","",'iWork,IBP & Framework_SOW Items'!G68)
A73: ='iWork,IBP & Framework_SOW Items'!E250 -> Milestone 6 | B73: ='iWork,IBP & Framework_SOW Items'!D250 -> iWork | C73: ='iWork,IBP & Framework_SOW Items'!B250 -> Export to Excel | D73: ='iWork,IBP & Framework_SOW Items'!C250 -> Export to excel - iWork all the results table; Download is on Previlage | E73: ='iWork,IBP & Framework_SOW Items'!F250 -> Yet to start | F73: =Helper!E250 -> Pending | G73: =IF('iWork,IBP & Framework_SOW Items'!I250="","",'iWork,IBP & Framework_SOW Items'!I250) | H73: =IF('iWork,IBP & Framework_SOW Items'!J250="","",'iWork,IBP & Framework_SOW Items'!J250) | I73: =IF('iWork,IBP & Framework_SOW Items'!G250="","",'iWork,IBP & Framework_SOW Items'!G250)
A74: ='iWork,IBP & Framework_SOW Items'!E253 -> Milestone 6 | B74: ='iWork,IBP & Framework_SOW Items'!D253 -> iWork | C74: ='iWork,IBP & Framework_SOW Items'!B253 -> Rewards | D74: ='iWork,IBP & Framework_SOW Items'!C253 -> Rewards - Specific & Generic Rewards - Start with a form and collect data | E74: ='iWork,IBP & Framework_SOW Items'!F253 -> Yet to start | F74: =Helper!E253 -> Pending | G74: =IF('iWork,IBP & Framework_SOW Items'!I253="","",'iWork,IBP & Framework_SOW Items'!I253) | H74: =IF('iWork,IBP & Framework_SOW Items'!J253="","",'iWork,IBP & Framework_SOW Items'!J253) | I74: =IF('iWork,IBP & Framework_SOW Items'!G253="","",'iWork,IBP & Framework_SOW Items'!G253)
A75: ='iWork,IBP & Framework_SOW Items'!E254 -> Milestone 6 | B75: ='iWork,IBP & Framework_SOW Items'!D254 -> iWork - CR | C75: ='iWork,IBP & Framework_SOW Items'!B254 -> Endorsement Mgmt (Non-Group / Non-GMC / Non-EB) | D75: ='iWork,IBP & Framework_SOW Items'!C254 -> Enhance the Non-GMC Process (Based on Kishore feedback) | E75: ='iWork,IBP & Framework_SOW Items'!F254 -> Delivered | F75: =Helper!E254 -> Delivered | G75: =IF('iWork,IBP & Framework_SOW Items'!I254="","",'iWork,IBP & Framework_SOW Items'!I254) -> 46170 | H75: =IF('iWork,IBP & Framework_SOW Items'!J254="","",'iWork,IBP & Framework_SOW Items'!J254) -> Pushyami | I75: =IF('iWork,IBP & Framework_SOW Items'!G254="","",'iWork,IBP & Framework_SOW Items'!G254)
A76: ='iWork,IBP & Framework_SOW Items'!E72 -> Milestone 4 | B76: ='iWork,IBP & Framework_SOW Items'!D72 -> DPDP | C76: ='iWork,IBP & Framework_SOW Items'!B72 -> Archived Oppurtunity, Policy Mgmt {Archived Biz Data and Retrieval on need} - DPDP | D76: ='iWork,IBP & Framework_SOW Items'!C72 -> 0 | E76: ='iWork,IBP & Framework_SOW Items'!F72 -> Yet to start | F76: =Helper!E72 -> Pending | G76: =IF('iWork,IBP & Framework_SOW Items'!I72="","",'iWork,IBP & Framework_SOW Items'!I72) -> 46203 | H76: =IF('iWork,IBP & Framework_SOW Items'!J72="","",'iWork,IBP & Framework_SOW Items'!J72) | I76: =IF('iWork,IBP & Framework_SOW Items'!G72="","",'iWork,IBP & Framework_SOW Items'!G72) -> Duplicate of Archival from NFR & DPDP
A77: ='iWork,IBP & Framework_SOW Items'!E73 -> Milestone 4 | B77: ='iWork,IBP & Framework_SOW Items'!D73 -> Framework | C77: ='iWork,IBP & Framework_SOW Items'!B73 -> Accessibility | D77: ='iWork,IBP & Framework_SOW Items'!C73 -> 0 | E77: ='iWork,IBP & Framework_SOW Items'!F73 -> Yet to start | F77: =Helper!E73 -> Pending | G77: =IF('iWork,IBP & Framework_SOW Items'!I73="","",'iWork,IBP & Framework_SOW Items'!I73) -> 46197 | H77: =IF('iWork,IBP & Framework_SOW Items'!J73="","",'iWork,IBP & Framework_SOW Items'!J73) | I77: =IF('iWork,IBP & Framework_SOW Items'!G73="","",'iWork,IBP & Framework_SOW Items'!G73)
