Workbook

Sheet VRK Feedbacks
A1: VRK — PROD FEEDBACK TRACKER · 67 items · 61 delivered · 6 pending
A3: All 'VRK - PROD Feedback:' items, broken up by week (status then ETA within a week). Excluded from the other views. Static snapshot.
A5: # | B5: Module | C5: Feature | D5: Functionality | E5: Status | F5: Milestone | G5: Requested | H5: ETA | I5: Resource | J5: Remarks
A6: 📅 WEEK OF 08 Jun → 14 Jun 2026 · PAST · 27 items
A7: 1 | B7: iWork | C7: VRK - PROD Feedback: 5-Jun-2026 | D7: Manage SO - Update the date filters to "SO Expiry Date" | E7: Delivered | F7: Milestone 6 | G7: 05-Jun-2026 | H7: 08-Jun-2026
A8: 2 | B8: iWork | C8: VRK - PROD Feedback: 8-Jun-2026 | D8: Critical: SO expiry logic and date validation should allow within 365 days at the time so creation. | E8: Delivered | F8: Milestone 6 | G8: 08-Jun-2026 | H8: 08-Jun-2026
A9: 3 | B9: iWork | C9: VRK - PROD Feedback: 8-Jun-2026 | D9: Dashboard - Save View button to be moved to Run button --> Move the Save View button beside Reset | E9: Delivered | F9: Milestone 6 | G9: 08-Jun-2026 | H9: 08-Jun-2026
A10: 4 | B10: iWork | C10: VRK - PROD Feedback: 8-Jun-2026 | D10: Dont display CD management in menu link - move under Admin | E10: Delivered | F10: Milestone 6 | G10: 08-Jun-2026 | H10: 08-Jun-2026
A11: 5 | B11: iWork | C11: VRK - PROD Feedback: 8-Jun-2026 | D11: filter out support services from the dashboard | E11: Delivered | F11: Milestone 6 | G11: 08-Jun-2026 | H11: 08-Jun-2026
A12: 6 | B12: iWork | C12: VRK - PROD Feedback: 8-Jun-2026 | D12: funnels - hide Overall conversion values | E12: Delivered | F12: Milestone 6 | G12: 08-Jun-2026 | H12: 08-Jun-2026
A13: 7 | B13: iWork | C13: VRK - PROD Feedback: 8-Jun-2026 | D13: In My RO, "BD planning" title should change to "Renewal Planning" for RO | E13: Delivered | F13: Milestone 6 | G13: 08-Jun-2026 | H13: 08-Jun-2026
A14: 8 | B14: iWork | C14: VRK - PROD Feedback: 8-Jun-2026 | D14: Manage TPA/BRoker/Insurer should be moved to Admin Module | E14: Delivered | F14: Milestone 6 | G14: 08-Jun-2026 | H14: 08-Jun-2026
A15: 9 | B15: iWork | C15: VRK - PROD Feedback: 8-Jun-2026 | D15: My Follow Up - hide "All" option - RO should be default | E15: Delivered | F15: Milestone 6 | G15: 08-Jun-2026 | H15: 08-Jun-2026
A16: 10 | B16: iWork | C16: VRK - PROD Feedback: 8-Jun-2026 | D16: Policy Expiry Timeline by SBU - change to "Renewal Schedule by SBU" and move under renewal funnel | E16: Delivered | F16: Milestone 6 | G16: 08-Jun-2026 | H16: 08-Jun-2026
A17: 11 | B17: iWork | C17: VRK - PROD Feedback: 8-Jun-2026 | D17: Ribbon level reports link should be hidden --> Hide "Reports" on the header menu. And also move the "Utilization report" to Admin Module. | E17: Delivered | F17: Milestone 6 | G17: 08-Jun-2026 | H17: 08-Jun-2026
A18: 12 | B18: iWork | C18: VRK - PROD Feedback: 8-Jun-2026 IIRM-10589 | D18: My client portfolio - Period (Company created) change to - Period (policies created) --- Show the same filters of Manage Policy | E18: Delivered | F18: Milestone 6 | G18: 08-Jun-2026 | H18: 09-Jun-2026 | I18: Karan
A19: 13 | B19: iWork | C19: VRK - PROD Feedback: 8-Jun-2026 | D19: isg roles: manage quotes screen should display the opportunities which are related to ISG only. | E19: Delivered | F19: Milestone 6 | G19: 08-Jun-2026 | H19: 09-Jun-2026
A20: 14 | B20: iWork | C20: VRK - PROD Feedback: 9-Jun-2026 | D20: BD/ISG planning dates should be empty and mandatory - should be mandatory to start the journey. | E20: Delivered | F20: Milestone 6 | G20: 09-Jun-2026 | H20: 09-Jun-2026
A21: 15 | B21: iWork | C21: VRK - PROD Feedback: 9-Jun-2026 | D21: In "Manage Quotes"/"Manage SO" page, a link should be provided on the activity name, it should get redirected to respective activity stage. | E21: Delivered | F21: Milestone 6 | G21: 09-Jun-2026 | H21: 09-Jun-2026 | I21: Pushyami
A22: 16 | B22: iWork | C22: VRK - PROD Feedback: 9-Jun-2026 | D22: Issue in Bizdone search results - Company name not visible | E22: Delivered | F22: Milestone 6 | G22: 09-Jun-2026 | H22: 09-Jun-2026 | I22: Pushyami
A23: 17 | B23: iWork | C23: VRK - PROD Feedback: 9-Jun-2026 IIRM-10588 | D23: Rename "My SO" to "Manage SO" in the sales portfolio. | E23: Delivered | F23: Milestone 6 | G23: 09-Jun-2026 | H23: 09-Jun-2026 | I23: Pushyami
A24: 18 | B24: iWork | C24: VRK - PROD Feedback: 9-Jun-2026 | D24: SO creation process: SO Expiry field title should be changed to "Opportunity/Existing Policy Expiry" - label to be changed. Nithin --> Also, change in SO details page as well | E24: Delivered | F24: Milestone 6 | G24: 09-Jun-2026 | H24: 09-Jun-2026 | I24: Pushyami
A25: 19 | B25: iWork | C25: VRK - PROD Feedback: 8-Jun-2026 | D25: My RO clicked should not get highlighted to My SO menu link. | E25: Delivered | F25: Milestone 6 | G25: 08-Jun-2026 | H25: 10-Jun-2026
A26: 20 | B26: iWork | C26: VRK - PROD Feedback: 9-Jun-2026 | D26: My followup section in the dashboard - should display default Activity names and show the values even there are zeros for each activity. | E26: Delivered | F26: Milestone 6 | G26: 09-Jun-2026 | H26: 10-Jun-2026 | I26: Prathiphala
A27: 21 | B27: iWork | C27: VRK - PROD Feedback: 9-Jun-2026 | D27: Opportunity lost logic:- if placement slip is not crossed, instantly mark the opportunity as "Lost" based on Opty. Expiry date | E27: Delivered | F27: Milestone 6 | G27: 09-Jun-2026 | H27: 10-Jun-2026 | I27: Jagadeesh
A28: 22 | B28: iWork | C28: VRK - PROD Feedback: 9-Jun-2026 | D28: Opportunity lost logic:- if the activity crossed "Placement Slip", premium calculation and crossed 5 days, then mark the opportunity as "Lost" based on Opty. expiry date+5 days | E28: Delivered | F28: Milestone 6 | G28: 09-Jun-2026 | H28: 10-Jun-2026 | I28: Jagadeesh
A29: 23 | B29: iWork | C29: VRK - PROD Feedback: 8-Jun-2026 IIRM-10589 | D29: My client portfolio - list of all companies for Active policies only | E29: Delivered | F29: Milestone 6 | G29: 08-Jun-2026 | H29: 12-Jun-2026 | I29: Karan
A30: 24 | B30: iWork | C30: VRK - PROD Feedback: 8-Jun-2026 | D30: Policy Expiry Timeline by SBU - when clicked, redirect to RO screen with the counts. | E30: Delivered | F30: Milestone 6 | G30: 08-Jun-2026 | H30: 12-Jun-2026
A31: 25 | B31: iWork | C31: VRK - PROD Feedback: 9-Jun-2026 | D31: BDR results list should display the link of policy ID and Opty ID. | E31: Delivered | F31: Milestone 6 | G31: 09-Jun-2026 | H31: 12-Jun-2026 | I31: Prathiphala
A32: 26 | B32: iWork | C32: VRK - PROD Feedback: 8-Jun-2026 | D32: My client portfolio: List of Companies should be displayed for which there are active RO's. The premium and brokerage should be displayed as per RO cards. --> Que: Yesterday it was asked to get the data related to Active Policies???? | E32: Not a bug | F32: Milestone 6 | G32: 08-Jun-2026 | H32: 08-Jun-2026 | J32: 10-Jun: As per Surya/Kapil Sir. It's Active Policies only
A33: 27 | B33: iWork | C33: VRK - PROD Feedback: 8-Jun-2026 | D33: my followup should be added into my actionalables with default display instead of "All" tab. | E33: Not a bug | F33: Milestone 6 | G33: 08-Jun-2026 | H33: 08-Jun-2026
A34: 📅 WEEK OF 15 Jun → 21 Jun 2026 · PAST · 8 items
A35: 28 | B35: iWork | C35: VRK - PROD Feedback: 9-Jun-2026 IIRM-10589 | D35: All SO and RO items should be displayed order by Expiry Date (ascending) in the same page once "Manage Quotes" is clicked by the user. | E35: Delivered | F35: Milestone 6 | G35: 09-Jun-2026 | H35: 15-Jun-2026 | I35: Karan
A36: 29 | B36: iWork | C36: VRK - PROD Feedback: 9-Jun-2026 IIRM-10589 | D36: ISG users should be able to view ISG activities only and BD related activities should be collapsable and hidden; accordingly manage the breadcrums. Similarly, vice versa for BD users. | E36: Delivered | F36: Milestone 6 | G36: 09-Jun-2026 | H36: 15-Jun-2026 | I36: Karan
A37: 30 | B37: iWork | C37: VRK - PROD Feedback: 9-Jun-2026 IIRM-10589 | D37: Manage Quote RO and Manager Quote SO should be clubbed to "Manage Quotes" link for ISG team only. --> 10-Jun: Surya -> Show the data only when opty. is in ISG Activity. | E37: Delivered | F37: Milestone 6 | G37: 09-Jun-2026 | H37: 15-Jun-2026 | I37: Karan
A38: 31 | B38: iWork | C38: VRK - PROD Feedback: 9-Jun-2026 IIRM-10589 | D38: My client portfolio: There must be a provision of "Past company" view in the Client Portfolio. | E38: Delivered | F38: Milestone 6 | G38: 09-Jun-2026 | H38: 15-Jun-2026
A39: 32 | B39: iWork | C39: VRK - PROD Feedback: 9-Jun-2026 IIRM-10589 | D39: Nithin -> Add the filters required to handle both SO & RO in "Manage Quotes" | E39: Delivered | F39: Milestone 6 | G39: 09-Jun-2026 | H39: 15-Jun-2026 | I39: Karan
A40: 33 | B40: iWork | C40: VRK - PROD Feedback: 9-Jun-2026 IIRM-10589 | D40: Hide "My RO" from the Sales portfolio. Add in the "My Client Portfolio" | E40: Delivered | F40: Milestone 6 | G40: 09-Jun-2026 | H40: 16-Jun-2026
A41: 34 | B41: iWork | C41: VRK - PROD Feedback: 8-Jun-2026 | D41: Commercial lines 25-26 numbers should be rectified; it should be 24.99 | E41: Delivered | F41: Milestone 6 | G41: 08-Jun-2026 | H41: 19-Jun-2026 | I41: Rama
A42: 35 | B42: iWork | C42: VRK - PROD Feedback: 9-Jun-2026 | D42: All Stage/Activity-wise wherever Document upload option is there, should be a mandatory | E42: Delivered | F42: Milestone 6 | G42: 09-Jun-2026 | H42: 19-Jun-2026 | I42: Karan
...

Sheet Helper
A1: Module | B1: Phase | C1: Status | D1: Category | E1: Bucket | F1: ReqDate
A2: =#REF! -> #REF! | B2: =#REF! -> #REF! | C2: =#REF! -> #REF! | D2: =IFERROR(VLOOKUP(C2,Config!$A:$B,2,0),"Unknown") -> Unknown | E2: =IFERROR(VLOOKUP(C2,Config!$A:$C,3,0),"N/A") -> N/A | F2: =IF(#REF!="","",#REF!) -> #REF!
A3: =#REF! -> #REF! | B3: =#REF! -> #REF! | C3: =#REF! -> #REF! | D3: =IFERROR(VLOOKUP(C3,Config!$A:$B,2,0),"Unknown") -> Unknown | E3: =IFERROR(VLOOKUP(C3,Config!$A:$C,3,0),"N/A") -> N/A | F3: =IF(#REF!="","",#REF!) -> #REF!
A4: =#REF! -> #REF! | B4: =#REF! -> #REF! | C4: =#REF! -> #REF! | D4: =IFERROR(VLOOKUP(C4,Config!$A:$B,2,0),"Unknown") -> Unknown | E4: =IFERROR(VLOOKUP(C4,Config!$A:$C,3,0),"N/A") -> N/A | F4: =IF(#REF!="","",#REF!) -> #REF!
A5: =#REF! -> #REF! | B5: =#REF! -> #REF! | C5: =#REF! -> #REF! | D5: =IFERROR(VLOOKUP(C5,Config!$A:$B,2,0),"Unknown") -> Unknown | E5: =IFERROR(VLOOKUP(C5,Config!$A:$C,3,0),"N/A") -> N/A | F5: =IF(#REF!="","",#REF!) -> #REF!
A6: =#REF! -> #REF! | B6: =#REF! -> #REF! | C6: =#REF! -> #REF! | D6: =IFERROR(VLOOKUP(C6,Config!$A:$B,2,0),"Unknown") -> Unknown | E6: =IFERROR(VLOOKUP(C6,Config!$A:$C,3,0),"N/A") -> N/A | F6: =IF(#REF!="","",#REF!) -> #REF!
A7: =#REF! -> #REF! | B7: =#REF! -> #REF! | C7: =#REF! -> #REF! | D7: =IFERROR(VLOOKUP(C7,Config!$A:$B,2,0),"Unknown") -> Unknown | E7: =IFERROR(VLOOKUP(C7,Config!$A:$C,3,0),"N/A") -> N/A | F7: =IF(#REF!="","",#REF!) -> #REF!
A8: =#REF! -> #REF! | B8: =#REF! -> #REF! | C8: =#REF! -> #REF! | D8: =IFERROR(VLOOKUP(C8,Config!$A:$B,2,0),"Unknown") -> Unknown | E8: =IFERROR(VLOOKUP(C8,Config!$A:$C,3,0),"N/A") -> N/A | F8: =IF(#REF!="","",#REF!) -> #REF!
A9: =#REF! -> #REF! | B9: =#REF! -> #REF! | C9: =#REF! -> #REF! | D9: =IFERROR(VLOOKUP(C9,Config!$A:$B,2,0),"Unknown") -> Unknown | E9: =IFERROR(VLOOKUP(C9,Config!$A:$C,3,0),"N/A") -> N/A | F9: =IF(#REF!="","",#REF!) -> #REF!
A10: =#REF! -> #REF! | B10: =#REF! -> #REF! | C10: =#REF! -> #REF! | D10: =IFERROR(VLOOKUP(C10,Config!$A:$B,2,0),"Unknown") -> Unknown | E10: =IFERROR(VLOOKUP(C10,Config!$A:$C,3,0),"N/A") -> N/A | F10: =IF(#REF!="","",#REF!) -> #REF!
A11: =#REF! -> #REF! | B11: =#REF! -> #REF! | C11: =#REF! -> #REF! | D11: =IFERROR(VLOOKUP(C11,Config!$A:$B,2,0),"Unknown") -> Unknown | E11: =IFERROR(VLOOKUP(C11,Config!$A:$C,3,0),"N/A") -> N/A | F11: =IF(#REF!="","",#REF!) -> #REF!
A12: =#REF! -> #REF! | B12: =#REF! -> #REF! | C12: =#REF! -> #REF! | D12: =IFERROR(VLOOKUP(C12,Config!$A:$B,2,0),"Unknown") -> Unknown | E12: =IFERROR(VLOOKUP(C12,Config!$A:$C,3,0),"N/A") -> N/A | F12: =IF(#REF!="","",#REF!) -> #REF!
A13: =#REF! -> #REF! | B13: =#REF! -> #REF! | C13: =#REF! -> #REF! | D13: =IFERROR(VLOOKUP(C13,Config!$A:$B,2,0),"Unknown") -> Unknown | E13: =IFERROR(VLOOKUP(C13,Config!$A:$C,3,0),"N/A") -> N/A | F13: =IF(#REF!="","",#REF!) -> #REF!
... A327: =#REF! -> #REF! | B327: =#REF! -> #REF! | C327: =#REF! -> #REF! | D327: =IFERROR(VLOOKUP(C327,Config!$A:$B,2,0),"Unknown") -> Unknown | E327: =IFERROR(VLOOKUP(C327,Config!$A:$C,3,0),"N/A") -> N/A | F327: =IF(#REF!="","",#REF!) -> #REF!

Sheet Config
A1: Status_Raw | B1: Category | C1: Bucket
A2: Delivered | B2: Delivered | C2: Delivered
A3: Dev - Done | B3: Dev Complete | C3: Delivered
A4: Dev - WIP | B4: In Development | C4: Pending
A5: QA - WIP | B5: In QA | C5: Pending
A6: Pre-PROD | B6: Pre-PROD / UAT | C6: Pending
A7: Yet to start | B7: Not Started | C7: Pending
A8: Delivered - Deficit | B8: Partial Delivery | C8: Pending
A9: Duplicate | B9: N/A | C9: N/A
A10: Not a bug | B10: Delivered | C10: Delivered
